Workbook
Name ChqRankL: Month!$L$17:$L$516
Name ChqRankU: Unpaid!$L$17:$L$516
Name ChqNosF: OFFSET(Sync!$A$6,0,0,MAX(COUNTIF(Sync!$A$6:$A$505,"?*"),1),1)
Name AcctCodesF: Sync!$E$6:$E$565
Name AcctTblF: Sync!$E$6:$H$565
Name ETxnType: Sync!$M$6:$M$2005
Name ETxnChk: Sync!$P$6:$P$2005
Name ChqNo: Calc!$A$6:$A$505
Name ChqNorm: Calc!$E$6:$E$505
Name ChqAmt: Calc!$F$6:$F$505
Name ChqStatus: Calc!$H$6:$H$505
Name ChqClr: Calc!$I$6:$I$505
Name ChqKey: Calc!$K$6:$K$505
Name NChq: COUNTIF(Calc!$A$6:$A$505,"?*")
Name BClrChk: Calc!$M$6:$M$2005
Name BClrDate: Calc!$N$6:$N$2005

Sheet Issues
A1: =IF(Sync!$J$6="","مازندشت",Sync!$J$6)&" — "&IF(Sync!$J$9="","سورتینگ و بسته‌بندی مرکبات",Sync!$J$9)
A2: =IF(Sync!$J$7="","باغدشت، بخش مرکزی، شهرستان قائم‌شهر، استان مازندران، ایران",Sync!$J$7)&" | MAZANDASHT · CITRUS SORTING & PACKING"
A3: صدور چک پرداختی — ثبت تاریخ، مبلغ و ذی‌نفع هر چک
A4: شماره چک باید قبلاً در INFO ← شیت Cheques تعریف شده باشد (کشویی از همان‌جا). در تاریخ «پاس شدن» چیزی ننویسید — وقتی چک پاس شود، در Transactions یک ردیف با نوع «پاس چک» و همین شماره چک ثبت کنید؛ وضعیت خودکار عوض می‌شود. در گزارش‌ها فقط شماره چک، تاریخ و مبلغ استفاده می‌شود.
A5: تعداد چک صادرشده | C5: جمع مبلغ چک‌ها (ریال) | E5: جمع پاس‌شده (ریال) | G5: ظرفیت باقی‌مانده
A6: =COUNTA($B$9:$B$508) | C6: =SUM($D$9:$D$508) | E6: =SUMIF($F$9:$F$508,"پاس شده",$D$9:$D$508) | G6: =500-COUNTA($B$9:$B$508)
A7: ردیف | B7: شماره چک | C7: تاریخ چک | D7: مبلغ (ریال) | E7: ذی‌نفع | F7: وضعیت (خودکار) | G7: توضیحات
A8: No. | B8: Cheque No. | C8: Cheque Date | D8: Amount | E8: Beneficiary | F8: Status (auto) | G8: Notes
A9: =IF($B9="","",COUNTA($B$9:$B9)) | B9: 24012345 | C9: 1405/07/10 | D9: 80000000 | E9: S001 | F9: =IF($B9="","",IF(COUNTIFS(ETxnType,"پاس چک",ETxnChk,$B9)>0,"پاس شده","پاس نشده")) | G9: بابت خرید باغ — چک سررسید ۱۰ مهر (نمونه)
A10: =IF($B10="","",COUNTA($B$9:$B10)) | B10: 24012346 | C10: 1405/07/20 | D10: 45000000 | E10: X002 | F10: =IF($B10="","",IF(COUNTIFS(ETxnType,"پاس چک",ETxnChk,$B10)>0,"پاس شده","پاس نشده")) | G10: مالیات — چک سررسید ۲۰ مهر (نمونه)
A11: =IF($B11="","",COUNTA($B$9:$B11)) | B11: 24012347 | C11: 1405/08/02 | D11: 150000000 | E11: S002 | F11: =IF($B11="","",IF(COUNTIFS(ETxnType,"پاس چک",ETxnChk,$B11)>0,"پاس شده","پاس نشده")) | G11: خرید میدان بار — چک سررسید ۲ آبان (نمونه)
A12: =IF($B12="","",COUNTA($B$9:$B12)) | B12: 24012348 | C12: 1405/08/05 | D12: 60000000 | E12: F001 | F12: =IF($B12="","",IF(COUNTIFS(ETxnType,"پاس چک",ETxnChk,$B12)>0,"پاس شده","پاس نشده")) | G12: خرید زمین باغدشت با چک — دارایی ثابت (نمونه)
A13: =IF($B13="","",COUNTA($B$9:$B13)) | F13: =IF($B13="","",IF(COUNTIFS(ETxnType,"پاس چک",ETxnChk,$B13)>0,"پاس شده","پاس نشده"))
A14: =IF($B14="","",COUNTA($B$9:$B14)) | F14: =IF($B14="","",IF(COUNTIFS(ETxnType,"پاس چک",ETxnChk,$B14)>0,"پاس شده","پاس نشده"))
A15: =IF($B15="","",COUNTA($B$9:$B15)) | F15: =IF($B15="","",IF(COUNTIFS(ETxnType,"پاس چک",ETxnChk,$B15)>0,"پاس شده","پاس نشده"))
A16: =IF($B16="","",COUNTA($B$9:$B16)) | F16: =IF($B16="","",IF(COUNTIFS(ETxnType,"پاس چک",ETxnChk,$B16)>0,"پاس شده","پاس نشده"))
A17: =IF($B17="","",COUNTA($B$9:$B17)) | F17: =IF($B17="","",IF(COUNTIFS(ETxnType,"پاس چک",ETxnChk,$B17)>0,"پاس شده","پاس نشده"))
A18: =IF($B18="","",COUNTA($B$9:$B18)) | F18: =IF($B18="","",IF(COUNTIFS(ETxnType,"پاس چک",ETxnChk,$B18)>0,"پاس شده","پاس نشده"))
A19: =IF($B19="","",COUNTA($B$9:$B19)) | F19: =IF($B19="","",IF(COUNTIFS(ETxnType,"پاس چک",ETxnChk,$B19)>0,"پاس شده","پاس نشده"))
A20: =IF($B20="","",COUNTA($B$9:$B20)) | F20: =IF($B20="","",IF(COUNTIFS(ETxnType,"پاس چک",ETxnChk,$B20)>0,"پاس شده","پاس نشده"))
A21: =IF($B21="","",COUNTA($B$9:$B21)) | F21: =IF($B21="","",IF(COUNTIFS(ETxnType,"پاس چک",ETxnChk,$B21)>0,"پاس شده","پاس نشده"))
A22: =IF($B22="","",COUNTA($B$9:$B22)) | F22: =IF($B22="","",IF(COUNTIFS(ETxnType,"پاس چک",ETxnChk,$B22)>0,"پاس شده","پاس نشده"))
A23: =IF($B23="","",COUNTA($B$9:$B23)) | F23: =IF($B23="","",IF(COUNTIFS(ETxnType,"پاس چک",ETxnChk,$B23)>0,"پاس شده","پاس نشده"))
A24: =IF($B24="","",COUNTA($B$9:$B24)) | F24: =IF($B24="","",IF(COUNTIFS(ETxnType,"پاس چک",ETxnChk,$B24)>0,"پاس شده","پاس نشده"))
... A508: =IF($B508="","",COUNTA($B$9:$B508)) | F508: =IF($B508="","",IF(COUNTIFS(ETxnType,"پاس چک",ETxnChk,$B508)>0,"پاس شده","پاس نشده"))

Sheet Month
A1: =IF(Sync!$J$6="","مازندشت",Sync!$J$6)&" — "&IF(Sync!$J$9="","سورتینگ و بسته‌بندی مرکبات",Sync!$J$9)
A2: =IF(Sync!$J$7="","باغدشت، بخش مرکزی، شهرستان قائم‌شهر، استان مازندران، ایران",Sync!$J$7)&" | MAZANDASHT · CITRUS SORTING & PACKING"
A3: گردش چک‌های پرداختی در بازه — همه چک‌ها (سبز = پاس شده، قرمز = پاس نشده) | H3: =IF(OR($B$5="",LEN($B$5)<>10),"",$B$5)
H4: =IF(OR($D$5="",LEN($D$5)<>10),"",$D$5)
A5: از تاریخ: | B5: 1405/07/01 | C5: تا تاریخ: | D5: 1405/07/31 | E5: بازه را با قالب 1405/07/01 وارد کنید — برای هر ماه، همین شیت را کپی کنید و بازه را عوض کنید.
A11: جمع کل چک‌های بازه (ریال) | C11: جمع پاس‌شده (ریال) | E11: جمع پاس‌نشده (ریال)
A12: =SUM($D$17:$D$516) | C12: =SUMIF($E$17:$E$516,"پاس شده",$D$17:$D$516) | E12: =SUMIF($E$17:$E$516,"پاس نشده",$D$17:$D$516)
A13: ردیف | B13: تاریخ چک | C13: شماره چک | D13: مبلغ (ریال) | E13: وضعیت | F13: تاریخ پاس
A14: No. | B14: Cheque Date | C14: Cheque No. | D14: Amount | E14: Status | F14: Cleared On
A17: =IF(IFERROR(MATCH(1,ChqRankL,0),0)=0,"",1) | B17: =IF(IFERROR(MATCH(1,ChqRankL,0),0)=0,"",INDEX(ChqNorm,IFERROR(MATCH(1,ChqRankL,0),0))) | C17: =IF(IFERROR(MATCH(1,ChqRankL,0),0)=0,"",INDEX(ChqNo,IFERROR(MATCH(1,ChqRankL,0),0))) | D17: =IF(IFERROR(MATCH(1,ChqRankL,0),0)=0,"",IF(INDEX(ChqAmt,IFERROR(MATCH(1,ChqRankL,0),0))=0,"",INDEX(ChqAmt,IFERROR(MATCH(1,ChqRankL,0),0)))) | E17: =IF(IFERROR(MATCH(1,ChqRankL,0),0)=0,"",INDEX(ChqStatus,IFERROR(MATCH(1,ChqRankL,0),0))) | F17: =IF(IFERROR(MATCH(1,ChqRankL,0),0)=0,"",IF(INDEX(ChqStatus,IFERROR(MATCH(1,ChqRankL,0),0))="پاس نشده","—",IF(INDEX(ChqClr,IFERROR(MATCH(1,ChqRankL,0),0))="","—",INDEX(ChqClr,IFERROR(MATCH(1,ChqRankL,0),0))))) | I17: =IF(1>NChq,"",INDEX(ChqNorm,1)) | J17: =IF($I17="","",IF(AND($I17>=$H$3,$I17<=$H$4),1,0)) | K17: =IF($J17=0,"",INDEX(ChqKey,1)) | L17: =IF($K17="","",COUNTIFS($J$17:$J$516,1,$K$17:$K$516,"<"&$K17)+1)
A18: =IF(IFERROR(MATCH(2,ChqRankL,0),0)=0,"",2) | B18: =IF(IFERROR(MATCH(2,ChqRankL,0),0)=0,"",INDEX(ChqNorm,IFERROR(MATCH(2,ChqRankL,0),0))) | C18: =IF(IFERROR(MATCH(2,ChqRankL,0),0)=0,"",INDEX(ChqNo,IFERROR(MATCH(2,ChqRankL,0),0))) | D18: =IF(IFERROR(MATCH(2,ChqRankL,0),0)=0,"",IF(INDEX(ChqAmt,IFERROR(MATCH(2,ChqRankL,0),0))=0,"",INDEX(ChqAmt,IFERROR(MATCH(2,ChqRankL,0),0)))) | E18: =IF(IFERROR(MATCH(2,ChqRankL,0),0)=0,"",INDEX(ChqStatus,IFERROR(MATCH(2,ChqRankL,0),0))) | F18: =IF(IFERROR(MATCH(2,ChqRankL,0),0)=0,"",IF(INDEX(ChqStatus,IFERROR(MATCH(2,ChqRankL,0),0))="پاس نشده","—",IF(INDEX(ChqClr,IFERROR(MATCH(2,ChqRankL,0),0))="","—",INDEX(ChqClr,IFERROR(MATCH(2,ChqRankL,0),0))))) | I18: =IF(2>NChq,"",INDEX(ChqNorm,2)) | J18: =IF($I18="","",IF(AND($I18>=$H$3,$I18<=$H$4),1,0)) | K18: =IF($J18=0,"",INDEX(ChqKey,2)) | L18: =IF($K18="","",COUNTIFS($J$17:$J$516,1,$K$17:$K$516,"<"&$K18)+1)
A19: =IF(IFERROR(MATCH(3,ChqRankL,0),0)=0,"",3) | B19: =IF(IFERROR(MATCH(3,ChqRankL,0),0)=0,"",INDEX(ChqNorm,IFERROR(MATCH(3,ChqRankL,0),0))) | C19: =IF(IFERROR(MATCH(3,ChqRankL,0),0)=0,"",INDEX(ChqNo,IFERROR(MATCH(3,ChqRankL,0),0))) | D19: =IF(IFERROR(MATCH(3,ChqRankL,0),0)=0,"",IF(INDEX(ChqAmt,IFERROR(MATCH(3,ChqRankL,0),0))=0,"",INDEX(ChqAmt,IFERROR(MATCH(3,ChqRankL,0),0)))) | E19: =IF(IFERROR(MATCH(3,ChqRankL,0),0)=0,"",INDEX(ChqStatus,IFERROR(MATCH(3,ChqRankL,0),0))) | F19: =IF(IFERROR(MATCH(3,ChqRankL,0),0)=0,"",IF(INDEX(ChqStatus,IFERROR(MATCH(3,ChqRankL,0),0))="پاس نشده","—",IF(INDEX(ChqClr,IFERROR(MATCH(3,ChqRankL,0),0))="","—",INDEX(ChqClr,IFERROR(MATCH(3,ChqRankL,0),0))))) | I19: =IF(3>NChq,"",INDEX(ChqNorm,3)) | J19: =IF($I19="","",IF(AND($I19>=$H$3,$I19<=$H$4),1,0)) | K19: =IF($J19=0,"",INDEX(ChqKey,3)) | L19: =IF($K19="","",COUNTIFS($J$17:$J$516,1,$K$17:$K$516,"<"&$K19)+1)
A20: =IF(IFERROR(MATCH(4,ChqRankL,0),0)=0,"",4) | B20: =IF(IFERROR(MATCH(4,ChqRankL,0),0)=0,"",INDEX(ChqNorm,IFERROR(MATCH(4,ChqRankL,0),0))) | C20: =IF(IFERROR(MATCH(4,ChqRankL,0),0)=0,"",INDEX(ChqNo,IFERROR(MATCH(4,ChqRankL,0),0))) | D20: =IF(IFERROR(MATCH(4,ChqRankL,0),0)=0,"",IF(INDEX(ChqAmt,IFERROR(MATCH(4,ChqRankL,0),0))=0,"",INDEX(ChqAmt,IFERROR(MATCH(4,ChqRankL,0),0)))) | E20: =IF(IFERROR(MATCH(4,ChqRankL,0),0)=0,"",INDEX(ChqStatus,IFERROR(MATCH(4,ChqRankL,0),0))) | F20: =IF(IFERROR(MATCH(4,ChqRankL,0),0)=0,"",IF(INDEX(ChqStatus,IFERROR(MATCH(4,ChqRankL,0),0))="پاس نشده","—",IF(INDEX(ChqClr,IFERROR(MATCH(4,ChqRankL,0),0))="","—",INDEX(ChqClr,IFERROR(MATCH(4,ChqRankL,0),0))))) | I20: =IF(4>NChq,"",INDEX(ChqNorm,4)) | J20: =IF($I20="","",IF(AND($I20>=$H$3,$I20<=$H$4),1,0)) | K20: =IF($J20=0,"",INDEX(ChqKey,4)) | L20: =IF($K20="","",COUNTIFS($J$17:$J$516,1,$K$17:$K$516,"<"&$K20)+1)
A21: =IF(IFERROR(MATCH(5,ChqRankL,0),0)=0,"",5) | B21: =IF(IFERROR(MATCH(5,ChqRankL,0),0)=0,"",INDEX(ChqNorm,IFERROR(MATCH(5,ChqRankL,0),0))) | C21: =IF(IFERROR(MATCH(5,ChqRankL,0),0)=0,"",INDEX(ChqNo,IFERROR(MATCH(5,ChqRankL,0),0))) | D21: =IF(IFERROR(MATCH(5,ChqRankL,0),0)=0,"",IF(INDEX(ChqAmt,IFERROR(MATCH(5,ChqRankL,0),0))=0,"",INDEX(ChqAmt,IFERROR(MATCH(5,ChqRankL,0),0)))) | E21: =IF(IFERROR(MATCH(5,ChqRankL,0),0)=0,"",INDEX(ChqStatus,IFERROR(MATCH(5,ChqRankL,0),0))) | F21: =IF(IFERROR(MATCH(5,ChqRankL,0),0)=0,"",IF(INDEX(ChqStatus,IFERROR(MATCH(5,ChqRankL,0),0))="پاس نشده","—",IF(INDEX(ChqClr,IFERROR(MATCH(5,ChqRankL,0),0))="","—",INDEX(ChqClr,IFERROR(MATCH(5,ChqRankL,0),0))))) | I21: =IF(5>NChq,"",INDEX(ChqNorm,5)) | J21: =IF($I21="","",IF(AND($I21>=$H$3,$I21<=$H$4),1,0)) | K21: =IF($J21=0,"",INDEX(ChqKey,5)) | L21: =IF($K21="","",COUNTIFS($J$17:$J$516,1,$K$17:$K$516,"<"&$K21)+1)
A22: =IF(IFERROR(MATCH(6,ChqRankL,0),0)=0,"",6) | B22: =IF(IFERROR(MATCH(6,ChqRankL,0),0)=0,"",INDEX(ChqNorm,IFERROR(MATCH(6,ChqRankL,0),0))) | C22: =IF(IFERROR(MATCH(6,ChqRankL,0),0)=0,"",INDEX(ChqNo,IFERROR(MATCH(6,ChqRankL,0),0))) | D22: =IF(IFERROR(MATCH(6,ChqRankL,0),0)=0,"",IF(INDEX(ChqAmt,IFERROR(MATCH(6,ChqRankL,0),0))=0,"",INDEX(ChqAmt,IFERROR(MATCH(6,ChqRankL,0),0)))) | E22: =IF(IFERROR(MATCH(6,ChqRankL,0),0)=0,"",INDEX(ChqStatus,IFERROR(MATCH(6,ChqRankL,0),0))) | F22: =IF(IFERROR(MATCH(6,ChqRankL,0),0)=0,"",IF(INDEX(ChqStatus,IFERROR(MATCH(6,ChqRankL,0),0))="پاس نشده","—",IF(INDEX(ChqClr,IFERROR(MATCH(6,ChqRankL,0),0))="","—",INDEX(ChqClr,IFERROR(MATCH(6,ChqRankL,0),0))))) | I22: =IF(6>NChq,"",INDEX(ChqNorm,6)) | J22: =IF($I22="","",IF(AND($I22>=$H$3,$I22<=$H$4),1,0)) | K22: =IF($J22=0,"",INDEX(ChqKey,6)) | L22: =IF($K22="","",COUNTIFS($J$17:$J$516,1,$K$17:$K$516,"<"&$K22)+1)
A23: =IF(IFERROR(MATCH(7,ChqRankL,0),0)=0,"",7) | B23: =IF(IFERROR(MATCH(7,ChqRankL,0),0)=0,"",INDEX(ChqNorm,IFERROR(MATCH(7,ChqRankL,0),0))) | C23: =IF(IFERROR(MATCH(7,ChqRankL,0),0)=0,"",INDEX(ChqNo,IFERROR(MATCH(7,ChqRankL,0),0))) | D23: =IF(IFERROR(MATCH(7,ChqRankL,0),0)=0,"",IF(INDEX(ChqAmt,IFERROR(MATCH(7,ChqRankL,0),0))=0,"",INDEX(ChqAmt,IFERROR(MATCH(7,ChqRankL,0),0)))) | E23: =IF(IFERROR(MATCH(7,ChqRankL,0),0)=0,"",INDEX(ChqStatus,IFERROR(MATCH(7,ChqRankL,0),0))) | F23: =IF(IFERROR(MATCH(7,ChqRankL,0),0)=0,"",IF(INDEX(ChqStatus,IFERROR(MATCH(7,ChqRankL,0),0))="پاس نشده","—",IF(INDEX(ChqClr,IFERROR(MATCH(7,ChqRankL,0),0))="","—",INDEX(ChqClr,IFERROR(MATCH(7,ChqRankL,0),0))))) | I23: =IF(7>NChq,"",INDEX(ChqNorm,7)) | J23: =IF($I23="","",IF(AND($I23>=$H$3,$I23<=$H$4),1,0)) | K23: =IF($J23=0,"",INDEX(ChqKey,7)) | L23: =IF($K23="","",COUNTIFS($J$17:$J$516,1,$K$17:$K$516,"<"&$K23)+1)
A24: =IF(IFERROR(MATCH(8,ChqRankL,0),0)=0,"",8) | B24: =IF(IFERROR(MATCH(8,ChqRankL,0),0)=0,"",INDEX(ChqNorm,IFERROR(MATCH(8,ChqRankL,0),0))) | C24: =IF(IFERROR(MATCH(8,ChqRankL,0),0)=0,"",INDEX(ChqNo,IFERROR(MATCH(8,ChqRankL,0),0))) | D24: =IF(IFERROR(MATCH(8,ChqRankL,0),0)=0,"",IF(INDEX(ChqAmt,IFERROR(MATCH(8,ChqRankL,0),0))=0,"",INDEX(ChqAmt,IFERROR(MATCH(8,ChqRankL,0),0)))) | E24: =IF(IFERROR(MATCH(8,ChqRankL,0),0)=0,"",INDEX(ChqStatus,IFERROR(MATCH(8,ChqRankL,0),0))) | F24: =IF(IFERROR(MATCH(8,ChqRankL,0),0)=0,"",IF(INDEX(ChqStatus,IFERROR(MATCH(8,ChqRankL,0),0))="پاس نشده","—",IF(INDEX(ChqClr,IFERROR(MATCH(8,ChqRankL,0),0))="","—",INDEX(ChqClr,IFERROR(MATCH(8,ChqRankL,0),0))))) | I24: =IF(8>NChq,"",INDEX(ChqNorm,8)) | J24: =IF($I24="","",IF(AND($I24>=$H$3,$I24<=$H$4),1,0)) | K24: =IF($J24=0,"",INDEX(ChqKey,8)) | L24: =IF($K24="","",COUNTIFS($J$17:$J$516,1,$K$17:$K$516,"<"&$K24)+1)
A25: =IF(IFERROR(MATCH(9,ChqRankL,0),0)=0,"",9) | B25: =IF(IFERROR(MATCH(9,ChqRankL,0),0)=0,"",INDEX(ChqNorm,IFERROR(MATCH(9,ChqRankL,0),0))) | C25: =IF(IFERROR(MATCH(9,ChqRankL,0),0)=0,"",INDEX(ChqNo,IFERROR(MATCH(9,ChqRankL,0),0))) | D25: =IF(IFERROR(MATCH(9,ChqRankL,0),0)=0,"",IF(INDEX(ChqAmt,IFERROR(MATCH(9,ChqRankL,0),0))=0,"",INDEX(ChqAmt,IFERROR(MATCH(9,ChqRankL,0),0)))) | E25: =IF(IFERROR(MATCH(9,ChqRankL,0),0)=0,"",INDEX(ChqStatus,IFERROR(MATCH(9,ChqRankL,0),0))) | F25: =IF(IFERROR(MATCH(9,ChqRankL,0),0)=0,"",IF(INDEX(ChqStatus,IFERROR(MATCH(9,ChqRankL,0),0))="پاس نشده","—",IF(INDEX(ChqClr,IFERROR(MATCH(9,ChqRankL,0),0))="","—",INDEX(ChqClr,IFERROR(MATCH(9,ChqRankL,0),0))))) | I25: =IF(9>NChq,"",INDEX(ChqNorm,9)) | J25: =IF($I25="","",IF(AND($I25>=$H$3,$I25<=$H$4),1,0)) | K25: =IF($J25=0,"",INDEX(ChqKey,9)) | L25: =IF($K25="","",COUNTIFS($J$17:$J$516,1,$K$17:$K$516,"<"&$K25)+1)
A26: =IF(IFERROR(MATCH(10,ChqRankL,0),0)=0,"",10) | B26: =IF(IFERROR(MATCH(10,ChqRankL,0),0)=0,"",INDEX(ChqNorm,IFERROR(MATCH(10,ChqRankL,0),0))) | C26: =IF(IFERROR(MATCH(10,ChqRankL,0),0)=0,"",INDEX(ChqNo,IFERROR(MATCH(10,ChqRankL,0),0))) | D26: =IF(IFERROR(MATCH(10,ChqRankL,0),0)=0,"",IF(INDEX(ChqAmt,IFERROR(MATCH(10,ChqRankL,0),0))=0,"",INDEX(ChqAmt,IFERROR(MATCH(10,ChqRankL,0),0)))) | E26: =IF(IFERROR(MATCH(10,ChqRankL,0),0)=0,"",INDEX(ChqStatus,IFERROR(MATCH(10,ChqRankL,0),0))) | F26: =IF(IFERROR(MATCH(10,ChqRankL,0),0)=0,"",IF(INDEX(ChqStatus,IFERROR(MATCH(10,ChqRankL,0),0))="پاس نشده","—",IF(INDEX(ChqClr,IFERROR(MATCH(10,ChqRankL,0),0))="","—",INDEX(ChqClr,IFERROR(MATCH(10,ChqRankL,0),0))))) | I26: =IF(10>NChq,"",INDEX(ChqNorm,10)) | J26: =IF($I26="","",IF(AND($I26>=$H$3,$I26<=$H$4),1,0)) | K26: =IF($J26=0,"",INDEX(ChqKey,10)) | L26: =IF($K26="","",COUNTIFS($J$17:$J$516,1,$K$17:$K$516,"<"&$K26)+1)
A27: =IF(IFERROR(MATCH(11,ChqRankL,0),0)=0,"",11) | B27: =IF(IFERROR(MATCH(11,ChqRankL,0),0)=0,"",INDEX(ChqNorm,IFERROR(MATCH(11,ChqRankL,0),0))) | C27: =IF(IFERROR(MATCH(11,ChqRankL,0),0)=0,"",INDEX(ChqNo,IFERROR(MATCH(11,ChqRankL,0),0))) | D27: =IF(IFERROR(MATCH(11,ChqRankL,0),0)=0,"",IF(INDEX(ChqAmt,IFERROR(MATCH(11,ChqRankL,0),0))=0,"",INDEX(ChqAmt,IFERROR(MATCH(11,ChqRankL,0),0)))) | E27: =IF(IFERROR(MATCH(11,ChqRankL,0),0)=0,"",INDEX(ChqStatus,IFERROR(MATCH(11,ChqRankL,0),0))) | F27: =IF(IFERROR(MATCH(11,ChqRankL,0),0)=0,"",IF(INDEX(ChqStatus,IFERROR(MATCH(11,ChqRankL,0),0))="پاس نشده","—",IF(INDEX(ChqClr,IFERROR(MATCH(11,ChqRankL,0),0))="","—",INDEX(ChqClr,IFERROR(MATCH(11,ChqRankL,0),0))))) | I27: =IF(11>NChq,"",INDEX(ChqNorm,11)) | J27: =IF($I27="","",IF(AND($I27>=$H$3,$I27<=$H$4),1,0)) | K27: =IF($J27=0,"",INDEX(ChqKey,11)) | L27: =IF($K27="","",COUNTIFS($J$17:$J$516,1,$K$17:$K$516,"<"&$K27)+1)
A28: =IF(IFERROR(MATCH(12,ChqRankL,0),0)=0,"",12) | B28: =IF(IFERROR(MATCH(12,ChqRankL,0),0)=0,"",INDEX(ChqNorm,IFERROR(MATCH(12,ChqRankL,0),0))) | C28: =IF(IFERROR(MATCH(12,ChqRankL,0),0)=0,"",INDEX(ChqNo,IFERROR(MATCH(12,ChqRankL,0),0))) | D28: =IF(IFERROR(MATCH(12,ChqRankL,0),0)=0,"",IF(INDEX(ChqAmt,IFERROR(MATCH(12,ChqRankL,0),0))=0,"",INDEX(ChqAmt,IFERROR(MATCH(12,ChqRankL,0),0)))) | E28: =IF(IFERROR(MATCH(12,ChqRankL,0),0)=0,"",INDEX(ChqStatus,IFERROR(MATCH(12,ChqRankL,0),0))) | F28: =IF(IFERROR(MATCH(12,ChqRankL,0),0)=0,"",IF(INDEX(ChqStatus,IFERROR(MATCH(12,ChqRankL,0),0))="پاس نشده","—",IF(INDEX(ChqClr,IFERROR(MATCH(12,ChqRankL,0),0))="","—",INDEX(ChqClr,IFERROR(MATCH(12,ChqRankL,0),0))))) | I28: =IF(12>NChq,"",INDEX(ChqNorm,12)) | J28: =IF($I28="","",IF(AND($I28>=$H$3,$I28<=$H$4),1,0)) | K28: =IF($J28=0,"",INDEX(ChqKey,12)) | L28: =IF($K28="","",COUNTIFS($J$17:$J$516,1,$K$17:$K$516,"<"&$K28)+1)
A29: =IF(IFERROR(MATCH(13,ChqRankL,0),0)=0,"",13) | B29: =IF(IFERROR(MATCH(13,ChqRankL,0),0)=0,"",INDEX(ChqNorm,IFERROR(MATCH(13,ChqRankL,0),0))) | C29: =IF(IFERROR(MATCH(13,ChqRankL,0),0)=0,"",INDEX(ChqNo,IFERROR(MATCH(13,ChqRankL,0),0))) | D29: =IF(IFERROR(MATCH(13,ChqRankL,0),0)=0,"",IF(INDEX(ChqAmt,IFERROR(MATCH(13,ChqRankL,0),0))=0,"",INDEX(ChqAmt,IFERROR(MATCH(13,ChqRankL,0),0)))) | E29: =IF(IFERROR(MATCH(13,ChqRankL,0),0)=0,"",INDEX(ChqStatus,IFERROR(MATCH(13,ChqRankL,0),0))) | F29: =IF(IFERROR(MATCH(13,ChqRankL,0),0)=0,"",IF(INDEX(ChqStatus,IFERROR(MATCH(13,ChqRankL,0),0))="پاس نشده","—",IF(INDEX(ChqClr,IFERROR(MATCH(13,ChqRankL,0),0))="","—",INDEX(ChqClr,IFERROR(MATCH(13,ChqRankL,0),0))))) | I29: =IF(13>NChq,"",INDEX(ChqNorm,13)) | J29: =IF($I29="","",IF(AND($I29>=$H$3,$I29<=$H$4),1,0)) | K29: =IF($J29=0,"",INDEX(ChqKey,13)) | L29: =IF($K29="","",COUNTIFS($J$17:$J$516,1,$K$17:$K$516,"<"&$K29)+1)
A30: =IF(IFERROR(MATCH(14,ChqRankL,0),0)=0,"",14) | B30: =IF(IFERROR(MATCH(14,ChqRankL,0),0)=0,"",INDEX(ChqNorm,IFERROR(MATCH(14,ChqRankL,0),0))) | C30: =IF(IFERROR(MATCH(14,ChqRankL,0),0)=0,"",INDEX(ChqNo,IFERROR(MATCH(14,ChqRankL,0),0))) | D30: =IF(IFERROR(MATCH(14,ChqRankL,0),0)=0,"",IF(INDEX(ChqAmt,IFERROR(MATCH(14,ChqRankL,0),0))=0,"",INDEX(ChqAmt,IFERROR(MATCH(14,ChqRankL,0),0)))) | E30: =IF(IFERROR(MATCH(14,ChqRankL,0),0)=0,"",INDEX(ChqStatus,IFERROR(MATCH(14,ChqRankL,0),0))) | F30: =IF(IFERROR(MATCH(14,ChqRankL,0),0)=0,"",IF(INDEX(ChqStatus,IFERROR(MATCH(14,ChqRankL,0),0))="پاس نشده","—",IF(INDEX(ChqClr,IFERROR(MATCH(14,ChqRankL,0),0))="","—",INDEX(ChqClr,IFERROR(MATCH(14,ChqRankL,0),0))))) | I30: =IF(14>NChq,"",INDEX(ChqNorm,14)) | J30: =IF($I30="","",IF(AND($I30>=$H$3,$I30<=$H$4),1,0)) | K30: =IF($J30=0,"",INDEX(ChqKey,14)) | L30: =IF($K30="","",COUNTIFS($J$17:$J$516,1,$K$17:$K$516,"<"&$K30)+1)
A31: =IF(IFERROR(MATCH(15,ChqRankL,0),0)=0,"",15) | B31: =IF(IFERROR(MATCH(15,ChqRankL,0),0)=0,"",INDEX(ChqNorm,IFERROR(MATCH(15,ChqRankL,0),0))) | C31: =IF(IFERROR(MATCH(15,ChqRankL,0),0)=0,"",INDEX(ChqNo,IFERROR(MATCH(15,ChqRankL,0),0))) | D31: =IF(IFERROR(MATCH(15,ChqRankL,0),0)=0,"",IF(INDEX(ChqAmt,IFERROR(MATCH(15,ChqRankL,0),0))=0,"",INDEX(ChqAmt,IFERROR(MATCH(15,ChqRankL,0),0)))) | E31: =IF(IFERROR(MATCH(15,ChqRankL,0),0)=0,"",INDEX(ChqStatus,IFERROR(MATCH(15,ChqRankL,0),0))) | F31: =IF(IFERROR(MATCH(15,ChqRankL,0),0)=0,"",IF(INDEX(ChqStatus,IFERROR(MATCH(15,ChqRankL,0),0))="پاس نشده","—",IF(INDEX(ChqClr,IFERROR(MATCH(15,ChqRankL,0),0))="","—",INDEX(ChqClr,IFERROR(MATCH(15,ChqRankL,0),0))))) | I31: =IF(15>NChq,"",INDEX(ChqNorm,15)) | J31: =IF($I31="","",IF(AND($I31>=$H$3,$I31<=$H$4),1,0)) | K31: =IF($J31=0,"",INDEX(ChqKey,15)) | L31: =IF($K31="","",COUNTIFS($J$17:$J$516,1,$K$17:$K$516,"<"&$K31)+1)
A32: =IF(IFERROR(MATCH(16,ChqRankL,0),0)=0,"",16) | B32: =IF(IFERROR(MATCH(16,ChqRankL,0),0)=0,"",INDEX(ChqNorm,IFERROR(MATCH(16,ChqRankL,0),0))) | C32: =IF(IFERROR(MATCH(16,ChqRankL,0),0)=0,"",INDEX(ChqNo,IFERROR(MATCH(16,ChqRankL,0),0))) | D32: =IF(IFERROR(MATCH(16,ChqRankL,0),0)=0,"",IF(INDEX(ChqAmt,IFERROR(MATCH(16,ChqRankL,0),0))=0,"",INDEX(ChqAmt,IFERROR(MATCH(16,ChqRankL,0),0)))) | E32: =IF(IFERROR(MATCH(16,ChqRankL,0),0)=0,"",INDEX(ChqStatus,IFERROR(MATCH(16,ChqRankL,0),0))) | F32: =IF(IFERROR(MATCH(16,ChqRankL,0),0)=0,"",IF(INDEX(ChqStatus,IFERROR(MATCH(16,ChqRankL,0),0))="پاس نشده","—",IF(INDEX(ChqClr,IFERROR(MATCH(16,ChqRankL,0),0))="","—",INDEX(ChqClr,IFERROR(MATCH(16,ChqRankL,0),0))))) | I32: =IF(16>NChq,"",INDEX(ChqNorm,16)) | J32: =IF($I32="","",IF(AND($I32>=$H$3,$I32<=$H$4),1,0)) | K32: =IF($J32=0,"",INDEX(ChqKey,16)) | L32: =IF($K32="","",COUNTIFS($J$17:$J$516,1,$K$17:$K$516,"<"&$K32)+1)
A33: =IF(IFERROR(MATCH(17,ChqRankL,0),0)=0,"",17) | B33: =IF(IFERROR(MATCH(17,ChqRankL,0),0)=0,"",INDEX(ChqNorm,IFERROR(MATCH(17,ChqRankL,0),0))) | C33: =IF(IFERROR(MATCH(17,ChqRankL,0),0)=0,"",INDEX(ChqNo,IFERROR(MATCH(17,ChqRankL,0),0))) | D33: =IF(IFERROR(MATCH(17,ChqRankL,0),0)=0,"",IF(INDEX(ChqAmt,IFERROR(MATCH(17,ChqRankL,0),0))=0,"",INDEX(ChqAmt,IFERROR(MATCH(17,ChqRankL,0),0)))) | E33: =IF(IFERROR(MATCH(17,ChqRankL,0),0)=0,"",INDEX(ChqStatus,IFERROR(MATCH(17,ChqRankL,0),0))) | F33: =IF(IFERROR(MATCH(17,ChqRankL,0),0)=0,"",IF(INDEX(ChqStatus,IFERROR(MATCH(17,ChqRankL,0),0))="پاس نشده","—",IF(INDEX(ChqClr,IFERROR(MATCH(17,ChqRankL,0),0))="","—",INDEX(ChqClr,IFERROR(MATCH(17,ChqRankL,0),0))))) | I33: =IF(17>NChq,"",INDEX(ChqNorm,17)) | J33: =IF($I33="","",IF(AND($I33>=$H$3,$I33<=$H$4),1,0)) | K33: =IF($J33=0,"",INDEX(ChqKey,17)) | L33: =IF($K33="","",COUNTIFS($J$17:$J$516,1,$K$17:$K$516,"<"&$K33)+1)
A34: =IF(IFERROR(MATCH(18,ChqRankL,0),0)=0,"",18) | B34: =IF(IFERROR(MATCH(18,ChqRankL,0),0)=0,"",INDEX(ChqNorm,IFERROR(MATCH(18,ChqRankL,0),0))) | C34: =IF(IFERROR(MATCH(18,ChqRankL,0),0)=0,"",INDEX(ChqNo,IFERROR(MATCH(18,ChqRankL,0),0))) | D34: =IF(IFERROR(MATCH(18,ChqRankL,0),0)=0,"",IF(INDEX(ChqAmt,IFERROR(MATCH(18,ChqRankL,0),0))=0,"",INDEX(ChqAmt,IFERROR(MATCH(18,ChqRankL,0),0)))) | E34: =IF(IFERROR(MATCH(18,ChqRankL,0),0)=0,"",INDEX(ChqStatus,IFERROR(MATCH(18,ChqRankL,0),0))) | F34: =IF(IFERROR(MATCH(18,ChqRankL,0),0)=0,"",IF(INDEX(ChqStatus,IFERROR(MATCH(18,ChqRankL,0),0))="پاس نشده","—",IF(INDEX(ChqClr,IFERROR(MATCH(18,ChqRankL,0),0))="","—",INDEX(ChqClr,IFERROR(MATCH(18,ChqRankL,0),0))))) | I34: =IF(18>NChq,"",INDEX(ChqNorm,18)) | J34: =IF($I34="","",IF(AND($I34>=$H$3,$I34<=$H$4),1,0)) | K34: =IF($J34=0,"",INDEX(ChqKey,18)) | L34: =IF($K34="","",COUNTIFS($J$17:$J$516,1,$K$17:$K$516,"<"&$K34)+1)
A35: =IF(IFERROR(MATCH(19,ChqRankL,0),0)=0,"",19) | B35: =IF(IFERROR(MATCH(19,ChqRankL,0),0)=0,"",INDEX(ChqNorm,IFERROR(MATCH(19,ChqRankL,0),0))) | C35: =IF(IFERROR(MATCH(19,ChqRankL,0),0)=0,"",INDEX(ChqNo,IFERROR(MATCH(19,ChqRankL,0),0))) | D35: =IF(IFERROR(MATCH(19,ChqRankL,0),0)=0,"",IF(INDEX(ChqAmt,IFERROR(MATCH(19,ChqRankL,0),0))=0,"",INDEX(ChqAmt,IFERROR(MATCH(19,ChqRankL,0),0)))) | E35: =IF(IFERROR(MATCH(19,ChqRankL,0),0)=0,"",INDEX(ChqStatus,IFERROR(MATCH(19,ChqRankL,0),0))) | F35: =IF(IFERROR(MATCH(19,ChqRankL,0),0)=0,"",IF(INDEX(ChqStatus,IFERROR(MATCH(19,ChqRankL,0),0))="پاس نشده","—",IF(INDEX(ChqClr,IFERROR(MATCH(19,ChqRankL,0),0))="","—",INDEX(ChqClr,IFERROR(MATCH(19,ChqRankL,0),0))))) | I35: =IF(19>NChq,"",INDEX(ChqNorm,19)) | J35: =IF($I35="","",IF(AND($I35>=$H$3,$I35<=$H$4),1,0)) | K35: =IF($J35=0,"",INDEX(ChqKey,19)) | L35: =IF($K35="","",COUNTIFS($J$17:$J$516,1,$K$17:$K$516,"<"&$K35)+1)
A36: =IF(IFERROR(MATCH(20,ChqRankL,0),0)=0,"",20) | B36: =IF(IFERROR(MATCH(20,ChqRankL,0),0)=0,"",INDEX(ChqNorm,IFERROR(MATCH(20,ChqRankL,0),0))) | C36: =IF(IFERROR(MATCH(20,ChqRankL,0),0)=0,"",INDEX(ChqNo,IFERROR(MATCH(20,ChqRankL,0),0))) | D36: =IF(IFERROR(MATCH(20,ChqRankL,0),0)=0,"",IF(INDEX(ChqAmt,IFERROR(MATCH(20,ChqRankL,0),0))=0,"",INDEX(ChqAmt,IFERROR(MATCH(20,ChqRankL,0),0)))) | E36: =IF(IFERROR(MATCH(20,ChqRankL,0),0)=0,"",INDEX(ChqStatus,IFERROR(MATCH(20,ChqRankL,0),0))) | F36: =IF(IFERROR(MATCH(20,ChqRankL,0),0)=0,"",IF(INDEX(ChqStatus,IFERROR(MATCH(20,ChqRankL,0),0))="پاس نشده","—",IF(INDEX(ChqClr,IFERROR(MATCH(20,ChqRankL,0),0))="","—",INDEX(ChqClr,IFERROR(MATCH(20,ChqRankL,0),0))))) | I36: =IF(20>NChq,"",INDEX(ChqNorm,20)) | J36: =IF($I36="","",IF(AND($I36>=$H$3,$I36<=$H$4),1,0)) | K36: =IF($J36=0,"",INDEX(ChqKey,20)) | L36: =IF($K36="","",COUNTIFS($J$17:$J$516,1,$K$17:$K$516,"<"&$K36)+1)
A37: =IF(IFERROR(MATCH(21,ChqRankL,0),0)=0,"",21) | B37: =IF(IFERROR(MATCH(21,ChqRankL,0),0)=0,"",INDEX(ChqNorm,IFERROR(MATCH(21,ChqRankL,0),0))) | C37: =IF(IFERROR(MATCH(21,ChqRankL,0),0)=0,"",INDEX(ChqNo,IFERROR(MATCH(21,ChqRankL,0),0))) | D37: =IF(IFERROR(MATCH(21,ChqRankL,0),0)=0,"",IF(INDEX(ChqAmt,IFERROR(MATCH(21,ChqRankL,0),0))=0,"",INDEX(ChqAmt,IFERROR(MATCH(21,ChqRankL,0),0)))) | E37: =IF(IFERROR(MATCH(21,ChqRankL,0),0)=0,"",INDEX(ChqStatus,IFERROR(MATCH(21,ChqRankL,0),0))) | F37: =IF(IFERROR(MATCH(21,ChqRankL,0),0)=0,"",IF(INDEX(ChqStatus,IFERROR(MATCH(21,ChqRankL,0),0))="پاس نشده","—",IF(INDEX(ChqClr,IFERROR(MATCH(21,ChqRankL,0),0))="","—",INDEX(ChqClr,IFERROR(MATCH(21,ChqRankL,0),0))))) | I37: =IF(21>NChq,"",INDEX(ChqNorm,21)) | J37: =IF($I37="","",IF(AND($I37>=$H$3,$I37<=$H$4),1,0)) | K37: =IF($J37=0,"",INDEX(ChqKey,21)) | L37: =IF($K37="","",COUNTIFS($J$17:$J$516,1,$K$17:$K$516,"<"&$K37)+1)
A38: =IF(IFERROR(MATCH(22,ChqRankL,0),0)=0,"",22) | B38: =IF(IFERROR(MATCH(22,ChqRankL,0),0)=0,"",INDEX(ChqNorm,IFERROR(MATCH(22,ChqRankL,0),0))) | C38: =IF(IFERROR(MATCH(22,ChqRankL,0),0)=0,"",INDEX(ChqNo,IFERROR(MATCH(22,ChqRankL,0),0))) | D38: =IF(IFERROR(MATCH(22,ChqRankL,0),0)=0,"",IF(INDEX(ChqAmt,IFERROR(MATCH(22,ChqRankL,0),0))=0,"",INDEX(ChqAmt,IFERROR(MATCH(22,ChqRankL,0),0)))) | E38: =IF(IFERROR(MATCH(22,ChqRankL,0),0)=0,"",INDEX(ChqStatus,IFERROR(MATCH(22,ChqRankL,0),0))) | F38: =IF(IFERROR(MATCH(22,ChqRankL,0),0)=0,"",IF(INDEX(ChqStatus,IFERROR(MATCH(22,ChqRankL,0),0))="پاس نشده","—",IF(INDEX(ChqClr,IFERROR(MATCH(22,ChqRankL,0),0))="","—",INDEX(ChqClr,IFERROR(MATCH(22,ChqRankL,0),0))))) | I38: =IF(22>NChq,"",INDEX(ChqNorm,22)) | J38: =IF($I38="","",IF(AND($I38>=$H$3,$I38<=$H$4),1,0)) | K38: =IF($J38=0,"",INDEX(ChqKey,22)) | L38: =IF($K38="","",COUNTIFS($J$17:$J$516,1,$K$17:$K$516,"<"&$K38)+1)
A39: =IF(IFERROR(MATCH(23,ChqRankL,0),0)=0,"",23) | B39: =IF(IFERROR(MATCH(23,ChqRankL,0),0)=0,"",INDEX(ChqNorm,IFERROR(MATCH(23,ChqRankL,0),0))) | C39: =IF(IFERROR(MATCH(23,ChqRankL,0),0)=0,"",INDEX(ChqNo,IFERROR(MATCH(23,ChqRankL,0),0))) | D39: =IF(IFERROR(MATCH(23,ChqRankL,0),0)=0,"",IF(INDEX(ChqAmt,IFERROR(MATCH(23,ChqRankL,0),0))=0,"",INDEX(ChqAmt,IFERROR(MATCH(23,ChqRankL,0),0)))) | E39: =IF(IFERROR(MATCH(23,ChqRankL,0),0)=0,"",INDEX(ChqStatus,IFERROR(MATCH(23,ChqRankL,0),0))) | F39: =IF(IFERROR(MATCH(23,ChqRankL,0),0)=0,"",IF(INDEX(ChqStatus,IFERROR(MATCH(23,ChqRankL,0),0))="پاس نشده","—",IF(INDEX(ChqClr,IFERROR(MATCH(23,ChqRankL,0),0))="","—",INDEX(ChqClr,IFERROR(MATCH(23,ChqRankL,0),0))))) | I39: =IF(23>NChq,"",INDEX(ChqNorm,23)) | J39: =IF($I39="","",IF(AND($I39>=$H$3,$I39<=$H$4),1,0)) | K39: =IF($J39=0,"",INDEX(ChqKey,23)) | L39: =IF($K39="","",COUNTIFS($J$17:$J$516,1,$K$17:$K$516,"<"&$K39)+1)
A40: =IF(IFERROR(MATCH(24,ChqRankL,0),0)=0,"",24) | B40: =IF(IFERROR(MATCH(24,ChqRankL,0),0)=0,"",INDEX(ChqNorm,IFERROR(MATCH(24,ChqRankL,0),0))) | C40: =IF(IFERROR(MATCH(24,ChqRankL,0),0)=0,"",INDEX(ChqNo,IFERROR(MATCH(24,ChqRankL,0),0))) | D40: =IF(IFERROR(MATCH(24,ChqRankL,0),0)=0,"",IF(INDEX(ChqAmt,IFERROR(MATCH(24,ChqRankL,0),0))=0,"",INDEX(ChqAmt,IFERROR(MATCH(24,ChqRankL,0),0)))) | E40: =IF(IFERROR(MATCH(24,ChqRankL,0),0)=0,"",INDEX(ChqStatus,IFERROR(MATCH(24,ChqRankL,0),0))) | F40: =IF(IFERROR(MATCH(24,ChqRankL,0),0)=0,"",IF(INDEX(ChqStatus,IFERROR(MATCH(24,ChqRankL,0),0))="پاس نشده","—",IF(INDEX(ChqClr,IFERROR(MATCH(24,ChqRankL,0),0))="","—",INDEX(ChqClr,IFERROR(MATCH(24,ChqRankL,0),0))))) | I40: =IF(24>NChq,"",INDEX(ChqNorm,24)) | J40: =IF($I40="","",IF(AND($I40>=$H$3,$I40<=$H$4),1,0)) | K40: =IF($J40=0,"",INDEX(ChqKey,24)) | L40: =IF($K40="","",COUNTIFS($J$17:$J$516,1,$K$17:$K$516,"<"&$K40)+1)
A41: =IF(IFERROR(MATCH(25,ChqRankL,0),0)=0,"",25) | B41: =IF(IFERROR(MATCH(25,ChqRankL,0),0)=0,"",INDEX(ChqNorm,IFERROR(MATCH(25,ChqRankL,0),0))) | C41: =IF(IFERROR(MATCH(25,ChqRankL,0),0)=0,"",INDEX(ChqNo,IFERROR(MATCH(25,ChqRankL,0),0))) | D41: =IF(IFERROR(MATCH(25,ChqRankL,0),0)=0,"",IF(INDEX(ChqAmt,IFERROR(MATCH(25,ChqRankL,0),0))=0,"",INDEX(ChqAmt,IFERROR(MATCH(25,ChqRankL,0),0)))) | E41: =IF(IFERROR(MATCH(25,ChqRankL,0),0)=0,"",INDEX(ChqStatus,IFERROR(MATCH(25,ChqRankL,0),0))) | F41: =IF(IFERROR(MATCH(25,ChqRankL,0),0)=0,"",IF(INDEX(ChqStatus,IFERROR(MATCH(25,ChqRankL,0),0))="پاس نشده","—",IF(INDEX(ChqClr,IFERROR(MATCH(25,ChqRankL,0),0))="","—",INDEX(ChqClr,IFERROR(MATCH(25,ChqRankL,0),0))))) | I41: =IF(25>NChq,"",INDEX(ChqNorm,25)) | J41: =IF($I41="","",IF(AND($I41>=$H$3,$I41<=$H$4),1,0)) | K41: =IF($J41=0,"",INDEX(ChqKey,25)) | L41: =IF($K41="","",COUNTIFS($J$17:$J$516,1,$K$17:$K$516,"<"&$K41)+1)
A42: =IF(IFERROR(MATCH(26,ChqRankL,0),0)=0,"",26) | B42: =IF(IFERROR(MATCH(26,ChqRankL,0),0)=0,"",INDEX(ChqNorm,IFERROR(MATCH(26,ChqRankL,0),0))) | C42: =IF(IFERROR(MATCH(26,ChqRankL,0),0)=0,"",INDEX(ChqNo,IFERROR(MATCH(26,ChqRankL,0),0))) | D42: =IF(IFERROR(MATCH(26,ChqRankL,0),0)=0,"",IF(INDEX(ChqAmt,IFERROR(MATCH(26,ChqRankL,0),0))=0,"",INDEX(ChqAmt,IFERROR(MATCH(26,ChqRankL,0),0)))) | E42: =IF(IFERROR(MATCH(26,ChqRankL,0),0)=0,"",INDEX(ChqStatus,IFERROR(MATCH(26,ChqRankL,0),0))) | F42: =IF(IFERROR(MATCH(26,ChqRankL,0),0)=0,"",IF(INDEX(ChqStatus,IFERROR(MATCH(26,ChqRankL,0),0))="پاس نشده","—",IF(INDEX(ChqClr,IFERROR(MATCH(26,ChqRankL,0),0))="","—",INDEX(ChqClr,IFERROR(MATCH(26,ChqRankL,0),0))))) | I42: =IF(26>NChq,"",INDEX(ChqNorm,26)) | J42: =IF($I42="","",IF(AND($I42>=$H$3,$I42<=$H$4),1,0)) | K42: =IF($J42=0,"",INDEX(ChqKey,26)) | L42: =IF($K42="","",COUNTIFS($J$17:$J$516,1,$K$17:$K$516,"<"&$K42)+1)
A43: =IF(IFERROR(MATCH(27,ChqRankL,0),0)=0,"",27) | B43: =IF(IFERROR(MATCH(27,ChqRankL,0),0)=0,"",INDEX(ChqNorm,IFERROR(MATCH(27,ChqRankL,0),0))) | C43: =IF(IFERROR(MATCH(27,ChqRankL,0),0)=0,"",INDEX(ChqNo,IFERROR(MATCH(27,ChqRankL,0),0))) | D43: =IF(IFERROR(MATCH(27,ChqRankL,0),0)=0,"",IF(INDEX(ChqAmt,IFERROR(MATCH(27,ChqRankL,0),0))=0,"",INDEX(ChqAmt,IFERROR(MATCH(27,ChqRankL,0),0)))) | E43: =IF(IFERROR(MATCH(27,ChqRankL,0),0)=0,"",INDEX(ChqStatus,IFERROR(MATCH(27,ChqRankL,0),0))) | F43: =IF(IFERROR(MATCH(27,ChqRankL,0),0)=0,"",IF(INDEX(ChqStatus,IFERROR(MATCH(27,ChqRankL,0),0))="پاس نشده","—",IF(INDEX(ChqClr,IFERROR(MATCH(27,ChqRankL,0),0))="","—",INDEX(ChqClr,IFERROR(MATCH(27,ChqRankL,0),0))))) | I43: =IF(27>NChq,"",INDEX(ChqNorm,27)) | J43: =IF($I43="","",IF(AND($I43>=$H$3,$I43<=$H$4),1,0)) | K43: =IF($J43=0,"",INDEX(ChqKey,27)) | L43: =IF($K43="","",COUNTIFS($J$17:$J$516,1,$K$17:$K$516,"<"&$K43)+1)
A44: =IF(IFERROR(MATCH(28,ChqRankL,0),0)=0,"",28) | B44: =IF(IFERROR(MATCH(28,ChqRankL,0),0)=0,"",INDEX(ChqNorm,IFERROR(MATCH(28,ChqRankL,0),0))) | C44: =IF(IFERROR(MATCH(28,ChqRankL,0),0)=0,"",INDEX(ChqNo,IFERROR(MATCH(28,ChqRankL,0),0))) | D44: =IF(IFERROR(MATCH(28,ChqRankL,0),0)=0,"",IF(INDEX(ChqAmt,IFERROR(MATCH(28,ChqRankL,0),0))=0,"",INDEX(ChqAmt,IFERROR(MATCH(28,ChqRankL,0),0)))) | E44: =IF(IFERROR(MATCH(28,ChqRankL,0),0)=0,"",INDEX(ChqStatus,IFERROR(MATCH(28,ChqRankL,0),0))) | F44: =IF(IFERROR(MATCH(28,ChqRankL,0),0)=0,"",IF(INDEX(ChqStatus,IFERROR(MATCH(28,ChqRankL,0),0))="پاس نشده","—",IF(INDEX(ChqClr,IFERROR(MATCH(28,ChqRankL,0),0))="","—",INDEX(ChqClr,IFERROR(MATCH(28,ChqRankL,0),0))))) | I44: =IF(28>NChq,"",INDEX(ChqNorm,28)) | J44: =IF($I44="","",IF(AND($I44>=$H$3,$I44<=$H$4),1,0)) | K44: =IF($J44=0,"",INDEX(ChqKey,28)) | L44: =IF($K44="","",COUNTIFS($J$17:$J$516,1,$K$17:$K$516,"<"&$K44)+1)
A45: =IF(IFERROR(MATCH(29,ChqRankL,0),0)=0,"",29) | B45: =IF(IFERROR(MATCH(29,ChqRankL,0),0)=0,"",INDEX(ChqNorm,IFERROR(MATCH(29,ChqRankL,0),0))) | C45: =IF(IFERROR(MATCH(29,ChqRankL,0),0)=0,"",INDEX(ChqNo,IFERROR(MATCH(29,ChqRankL,0),0))) | D45: =IF(IFERROR(MATCH(29,ChqRankL,0),0)=0,"",IF(INDEX(ChqAmt,IFERROR(MATCH(29,ChqRankL,0),0))=0,"",INDEX(ChqAmt,IFERROR(MATCH(29,ChqRankL,0),0)))) | E45: =IF(IFERROR(MATCH(29,ChqRankL,0),0)=0,"",INDEX(ChqStatus,IFERROR(MATCH(29,ChqRankL,0),0))) | F45: =IF(IFERROR(MATCH(29,ChqRankL,0),0)=0,"",IF(INDEX(ChqStatus,IFERROR(MATCH(29,ChqRankL,0),0))="پاس نشده","—",IF(INDEX(ChqClr,IFERROR(MATCH(29,ChqRankL,0),0))="","—",INDEX(ChqClr,IFERROR(MATCH(29,ChqRankL,0),0))))) | I45: =IF(29>NChq,"",INDEX(ChqNorm,29)) | J45: =IF($I45="","",IF(AND($I45>=$H$3,$I45<=$H$4),1,0)) | K45: =IF($J45=0,"",INDEX(ChqKey,29)) | L45: =IF($K45="","",COUNTIFS($J$17:$J$516,1,$K$17:$K$516,"<"&$K45)+1)
A46: =IF(IFERROR(MATCH(30,ChqRankL,0),0)=0,"",30) | B46: =IF(IFERROR(MATCH(30,ChqRankL,0),0)=0,"",INDEX(ChqNorm,IFERROR(MATCH(30,ChqRankL,0),0))) | C46: =IF(IFERROR(MATCH(30,ChqRankL,0),0)=0,"",INDEX(ChqNo,IFERROR(MATCH(30,ChqRankL,0),0))) | D46: =IF(IFERROR(MATCH(30,ChqRankL,0),0)=0,"",IF(INDEX(ChqAmt,IFERROR(MATCH(30,ChqRankL,0),0))=0,"",INDEX(ChqAmt,IFERROR(MATCH(30,ChqRankL,0),0)))) | E46: =IF(IFERROR(MATCH(30,ChqRankL,0),0)=0,"",INDEX(ChqStatus,IFERROR(MATCH(30,ChqRankL,0),0))) | F46: =IF(IFERROR(MATCH(30,ChqRankL,0),0)=0,"",IF(INDEX(ChqStatus,IFERROR(MATCH(30,ChqRankL,0),0))="پاس نشده","—",IF(INDEX(ChqClr,IFERROR(MATCH(30,ChqRankL,0),0))="","—",INDEX(ChqClr,IFERROR(MATCH(30,ChqRankL,0),0))))) | I46: =IF(30>NChq,"",INDEX(ChqNorm,30)) | J46: =IF($I46="","",IF(AND($I46>=$H$3,$I46<=$H$4),1,0)) | K46: =IF($J46=0,"",INDEX(ChqKey,30)) | L46: =IF($K46="","",COUNTIFS($J$17:$J$516,1,$K$17:$K$516,"<"&$K46)+1)
A47: =IF(IFERROR(MATCH(31,ChqRankL,0),0)=0,"",31) | B47: =IF(IFERROR(MATCH(31,ChqRankL,0),0)=0,"",INDEX(ChqNorm,IFERROR(MATCH(31,ChqRankL,0),0))) | C47: =IF(IFERROR(MATCH(31,ChqRankL,0),0)=0,"",INDEX(ChqNo,IFERROR(MATCH(31,ChqRankL,0),0))) | D47: =IF(IFERROR(MATCH(31,ChqRankL,0),0)=0,"",IF(INDEX(ChqAmt,IFERROR(MATCH(31,ChqRankL,0),0))=0,"",INDEX(ChqAmt,IFERROR(MATCH(31,ChqRankL,0),0)))) | E47: =IF(IFERROR(MATCH(31,ChqRankL,0),0)=0,"",INDEX(ChqStatus,IFERROR(MATCH(31,ChqRankL,0),0))) | F47: =IF(IFERROR(MATCH(31,ChqRankL,0),0)=0,"",IF(INDEX(ChqStatus,IFERROR(MATCH(31,ChqRankL,0),0))="پاس نشده","—",IF(INDEX(ChqClr,IFERROR(MATCH(31,ChqRankL,0),0))="","—",INDEX(ChqClr,IFERROR(MATCH(31,ChqRankL,0),0))))) | I47: =IF(31>NChq,"",INDEX(ChqNorm,31)) | J47: =IF($I47="","",IF(AND($I47>=$H$3,$I47<=$H$4),1,0)) | K47: =IF($J47=0,"",INDEX(ChqKey,31)) | L47: =IF($K47="","",COUNTIFS($J$17:$J$516,1,$K$17:$K$516,"<"&$K47)+1)
...

Sheet Unpaid
A1: =IF(Sync!$J$6="","مازندشت",Sync!$J$6)&" — "&IF(Sync!$J$9="","سورتینگ و بسته‌بندی مرکبات",Sync!$J$9)
A2: =IF(Sync!$J$7="","باغدشت، بخش مرکزی، شهرستان قائم‌شهر، استان مازندران، ایران",Sync!$J$7)&" | MAZANDASHT · CITRUS SORTING & PACKING"
A3: چک‌های پاس‌نشده در بازه — به ترتیب تاریخ | H3: =IF(OR($B$5="",LEN($B$5)<>10),"",$B$5)
H4: =IF(OR($D$5="",LEN($D$5)<>10),"",$D$5)
A5: از تاریخ: | B5: 1405/07/01 | C5: تا تاریخ: | D5: 1405/07/31 | E5: بازه را با قالب 1405/07/01 وارد کنید — برای هر ماه، همین شیت را کپی کنید و بازه را عوض کنید.
A11: جمع چک‌های پاس‌نشده (ریال) | C11: تعداد | E11: نزدیک‌ترین سررسید
A12: =SUM($D$17:$D$516) | C12: =COUNT($D$17:$D$516) | E12: =IF(COUNT($D$17:$D$516)=0,"—",INDEX($B$17:$B$516,1))
A13: ردیف | B13: تاریخ چک | C13: شماره چک | D13: مبلغ (ریال) | E13: وضعیت | F13: تاریخ پاس
A14: No. | B14: Cheque Date | C14: Cheque No. | D14: Amount | E14: Status | F14: Cleared On
A17: =IF(IFERROR(MATCH(1,ChqRankU,0),0)=0,"",1) | B17: =IF(IFERROR(MATCH(1,ChqRankU,0),0)=0,"",INDEX(ChqNorm,IFERROR(MATCH(1,ChqRankU,0),0))) | C17: =IF(IFERROR(MATCH(1,ChqRankU,0),0)=0,"",INDEX(ChqNo,IFERROR(MATCH(1,ChqRankU,0),0))) | D17: =IF(IFERROR(MATCH(1,ChqRankU,0),0)=0,"",IF(INDEX(ChqAmt,IFERROR(MATCH(1,ChqRankU,0),0))=0,"",INDEX(ChqAmt,IFERROR(MATCH(1,ChqRankU,0),0)))) | E17: =IF(IFERROR(MATCH(1,ChqRankU,0),0)=0,"",INDEX(ChqStatus,IFERROR(MATCH(1,ChqRankU,0),0))) | F17: =IF(IFERROR(MATCH(1,ChqRankU,0),0)=0,"",IF(INDEX(ChqStatus,IFERROR(MATCH(1,ChqRankU,0),0))="پاس نشده","—",IF(INDEX(ChqClr,IFERROR(MATCH(1,ChqRankU,0),0))="","—",INDEX(ChqClr,IFERROR(MATCH(1,ChqRankU,0),0))))) | I17: =IF(1>NChq,"",INDEX(ChqNorm,1)) | J17: =IF($I17="","",IF(AND($I17>=$H$3,$I17<=$H$4,INDEX(ChqStatus,1)="پاس نشده"),1,0)) | K17: =IF($J17=0,"",INDEX(ChqKey,1)) | L17: =IF($K17="","",COUNTIFS($J$17:$J$516,1,$K$17:$K$516,"<"&$K17)+1)
A18: =IF(IFERROR(MATCH(2,ChqRankU,0),0)=0,"",2) | B18: =IF(IFERROR(MATCH(2,ChqRankU,0),0)=0,"",INDEX(ChqNorm,IFERROR(MATCH(2,ChqRankU,0),0))) | C18: =IF(IFERROR(MATCH(2,ChqRankU,0),0)=0,"",INDEX(ChqNo,IFERROR(MATCH(2,ChqRankU,0),0))) | D18: =IF(IFERROR(MATCH(2,ChqRankU,0),0)=0,"",IF(INDEX(ChqAmt,IFERROR(MATCH(2,ChqRankU,0),0))=0,"",INDEX(ChqAmt,IFERROR(MATCH(2,ChqRankU,0),0)))) | E18: =IF(IFERROR(MATCH(2,ChqRankU,0),0)=0,"",INDEX(ChqStatus,IFERROR(MATCH(2,ChqRankU,0),0))) | F18: =IF(IFERROR(MATCH(2,ChqRankU,0),0)=0,"",IF(INDEX(ChqStatus,IFERROR(MATCH(2,ChqRankU,0),0))="پاس نشده","—",IF(INDEX(ChqClr,IFERROR(MATCH(2,ChqRankU,0),0))="","—",INDEX(ChqClr,IFERROR(MATCH(2,ChqRankU,0),0))))) | I18: =IF(2>NChq,"",INDEX(ChqNorm,2)) | J18: =IF($I18="","",IF(AND($I18>=$H$3,$I18<=$H$4,INDEX(ChqStatus,2)="پاس نشده"),1,0)) | K18: =IF($J18=0,"",INDEX(ChqKey,2)) | L18: =IF($K18="","",COUNTIFS($J$17:$J$516,1,$K$17:$K$516,"<"&$K18)+1)
A19: =IF(IFERROR(MATCH(3,ChqRankU,0),0)=0,"",3) | B19: =IF(IFERROR(MATCH(3,ChqRankU,0),0)=0,"",INDEX(ChqNorm,IFERROR(MATCH(3,ChqRankU,0),0))) | C19: =IF(IFERROR(MATCH(3,ChqRankU,0),0)=0,"",INDEX(ChqNo,IFERROR(MATCH(3,ChqRankU,0),0))) | D19: =IF(IFERROR(MATCH(3,ChqRankU,0),0)=0,"",IF(INDEX(ChqAmt,IFERROR(MATCH(3,ChqRankU,0),0))=0,"",INDEX(ChqAmt,IFERROR(MATCH(3,ChqRankU,0),0)))) | E19: =IF(IFERROR(MATCH(3,ChqRankU,0),0)=0,"",INDEX(ChqStatus,IFERROR(MATCH(3,ChqRankU,0),0))) | F19: =IF(IFERROR(MATCH(3,ChqRankU,0),0)=0,"",IF(INDEX(ChqStatus,IFERROR(MATCH(3,ChqRankU,0),0))="پاس نشده","—",IF(INDEX(ChqClr,IFERROR(MATCH(3,ChqRankU,0),0))="","—",INDEX(ChqClr,IFERROR(MATCH(3,ChqRankU,0),0))))) | I19: =IF(3>NChq,"",INDEX(ChqNorm,3)) | J19: =IF($I19="","",IF(AND($I19>=$H$3,$I19<=$H$4,INDEX(ChqStatus,3)="پاس نشده"),1,0)) | K19: =IF($J19=0,"",INDEX(ChqKey,3)) | L19: =IF($K19="","",COUNTIFS($J$17:$J$516,1,$K$17:$K$516,"<"&$K19)+1)
A20: =IF(IFERROR(MATCH(4,ChqRankU,0),0)=0,"",4) | B20: =IF(IFERROR(MATCH(4,ChqRankU,0),0)=0,"",INDEX(ChqNorm,IFERROR(MATCH(4,ChqRankU,0),0))) | C20: =IF(IFERROR(MATCH(4,ChqRankU,0),0)=0,"",INDEX(ChqNo,IFERROR(MATCH(4,ChqRankU,0),0))) | D20: =IF(IFERROR(MATCH(4,ChqRankU,0),0)=0,"",IF(INDEX(ChqAmt,IFERROR(MATCH(4,ChqRankU,0),0))=0,"",INDEX(ChqAmt,IFERROR(MATCH(4,ChqRankU,0),0)))) | E20: =IF(IFERROR(MATCH(4,ChqRankU,0),0)=0,"",INDEX(ChqStatus,IFERROR(MATCH(4,ChqRankU,0),0))) | F20: =IF(IFERROR(MATCH(4,ChqRankU,0),0)=0,"",IF(INDEX(ChqStatus,IFERROR(MATCH(4,ChqRankU,0),0))="پاس نشده","—",IF(INDEX(ChqClr,IFERROR(MATCH(4,ChqRankU,0),0))="","—",INDEX(ChqClr,IFERROR(MATCH(4,ChqRankU,0),0))))) | I20: =IF(4>NChq,"",INDEX(ChqNorm,4)) | J20: =IF($I20="","",IF(AND($I20>=$H$3,$I20<=$H$4,INDEX(ChqStatus,4)="پاس نشده"),1,0)) | K20: =IF($J20=0,"",INDEX(ChqKey,4)) | L20: =IF($K20="","",COUNTIFS($J$17:$J$516,1,$K$17:$K$516,"<"&$K20)+1)
A21: =IF(IFERROR(MATCH(5,ChqRankU,0),0)=0,"",5) | B21: =IF(IFERROR(MATCH(5,ChqRankU,0),0)=0,"",INDEX(ChqNorm,IFERROR(MATCH(5,ChqRankU,0),0))) | C21: =IF(IFERROR(MATCH(5,ChqRankU,0),0)=0,"",INDEX(ChqNo,IFERROR(MATCH(5,ChqRankU,0),0))) | D21: =IF(IFERROR(MATCH(5,ChqRankU,0),0)=0,"",IF(INDEX(ChqAmt,IFERROR(MATCH(5,ChqRankU,0),0))=0,"",INDEX(ChqAmt,IFERROR(MATCH(5,ChqRankU,0),0)))) | E21: =IF(IFERROR(MATCH(5,ChqRankU,0),0)=0,"",INDEX(ChqStatus,IFERROR(MATCH(5,ChqRankU,0),0))) | F21: =IF(IFERROR(MATCH(5,ChqRankU,0),0)=0,"",IF(INDEX(ChqStatus,IFERROR(MATCH(5,ChqRankU,0),0))="پاس نشده","—",IF(INDEX(ChqClr,IFERROR(MATCH(5,ChqRankU,0),0))="","—",INDEX(ChqClr,IFERROR(MATCH(5,ChqRankU,0),0))))) | I21: =IF(5>NChq,"",INDEX(ChqNorm,5)) | J21: =IF($I21="","",IF(AND($I21>=$H$3,$I21<=$H$4,INDEX(ChqStatus,5)="پاس نشده"),1,0)) | K21: =IF($J21=0,"",INDEX(ChqKey,5)) | L21: =IF($K21="","",COUNTIFS($J$17:$J$516,1,$K$17:$K$516,"<"&$K21)+1)
A22: =IF(IFERROR(MATCH(6,ChqRankU,0),0)=0,"",6) | B22: =IF(IFERROR(MATCH(6,ChqRankU,0),0)=0,"",INDEX(ChqNorm,IFERROR(MATCH(6,ChqRankU,0),0))) | C22: =IF(IFERROR(MATCH(6,ChqRankU,0),0)=0,"",INDEX(ChqNo,IFERROR(MATCH(6,ChqRankU,0),0))) | D22: =IF(IFERROR(MATCH(6,ChqRankU,0),0)=0,"",IF(INDEX(ChqAmt,IFERROR(MATCH(6,ChqRankU,0),0))=0,"",INDEX(ChqAmt,IFERROR(MATCH(6,ChqRankU,0),0)))) | E22: =IF(IFERROR(MATCH(6,ChqRankU,0),0)=0,"",INDEX(ChqStatus,IFERROR(MATCH(6,ChqRankU,0),0))) | F22: =IF(IFERROR(MATCH(6,ChqRankU,0),0)=0,"",IF(INDEX(ChqStatus,IFERROR(MATCH(6,ChqRankU,0),0))="پاس نشده","—",IF(INDEX(ChqClr,IFERROR(MATCH(6,ChqRankU,0),0))="","—",INDEX(ChqClr,IFERROR(MATCH(6,ChqRankU,0),0))))) | I22: =IF(6>NChq,"",INDEX(ChqNorm,6)) | J22: =IF($I22="","",IF(AND($I22>=$H$3,$I22<=$H$4,INDEX(ChqStatus,6)="پاس نشده"),1,0)) | K22: =IF($J22=0,"",INDEX(ChqKey,6)) | L22: =IF($K22="","",COUNTIFS($J$17:$J$516,1,$K$17:$K$516,"<"&$K22)+1)
A23: =IF(IFERROR(MATCH(7,ChqRankU,0),0)=0,"",7) | B23: =IF(IFERROR(MATCH(7,ChqRankU,0),0)=0,"",INDEX(ChqNorm,IFERROR(MATCH(7,ChqRankU,0),0))) | C23: =IF(IFERROR(MATCH(7,ChqRankU,0),0)=0,"",INDEX(ChqNo,IFERROR(MATCH(7,ChqRankU,0),0))) | D23: =IF(IFERROR(MATCH(7,ChqRankU,0),0)=0,"",IF(INDEX(ChqAmt,IFERROR(MATCH(7,ChqRankU,0),0))=0,"",INDEX(ChqAmt,IFERROR(MATCH(7,ChqRankU,0),0)))) | E23: =IF(IFERROR(MATCH(7,ChqRankU,0),0)=0,"",INDEX(ChqStatus,IFERROR(MATCH(7,ChqRankU,0),0))) | F23: =IF(IFERROR(MATCH(7,ChqRankU,0),0)=0,"",IF(INDEX(ChqStatus,IFERROR(MATCH(7,ChqRankU,0),0))="پاس نشده","—",IF(INDEX(ChqClr,IFERROR(MATCH(7,ChqRankU,0),0))="","—",INDEX(ChqClr,IFERROR(MATCH(7,ChqRankU,0),0))))) | I23: =IF(7>NChq,"",INDEX(ChqNorm,7)) | J23: =IF($I23="","",IF(AND($I23>=$H$3,$I23<=$H$4,INDEX(ChqStatus,7)="پاس نشده"),1,0)) | K23: =IF($J23=0,"",INDEX(ChqKey,7)) | L23: =IF($K23="","",COUNTIFS($J$17:$J$516,1,$K$17:$K$516,"<"&$K23)+1)
A24: =IF(IFERROR(MATCH(8,ChqRankU,0),0)=0,"",8) | B24: =IF(IFERROR(MATCH(8,ChqRankU,0),0)=0,"",INDEX(ChqNorm,IFERROR(MATCH(8,ChqRankU,0),0))) | C24: =IF(IFERROR(MATCH(8,ChqRankU,0),0)=0,"",INDEX(ChqNo,IFERROR(MATCH(8,ChqRankU,0),0))) | D24: =IF(IFERROR(MATCH(8,ChqRankU,0),0)=0,"",IF(INDEX(ChqAmt,IFERROR(MATCH(8,ChqRankU,0),0))=0,"",INDEX(ChqAmt,IFERROR(MATCH(8,ChqRankU,0),0)))) | E24: =IF(IFERROR(MATCH(8,ChqRankU,0),0)=0,"",INDEX(ChqStatus,IFERROR(MATCH(8,ChqRankU,0),0))) | F24: =IF(IFERROR(MATCH(8,ChqRankU,0),0)=0,"",IF(INDEX(ChqStatus,IFERROR(MATCH(8,ChqRankU,0),0))="پاس نشده","—",IF(INDEX(ChqClr,IFERROR(MATCH(8,ChqRankU,0),0))="","—",INDEX(ChqClr,IFERROR(MATCH(8,ChqRankU,0),0))))) | I24: =IF(8>NChq,"",INDEX(ChqNorm,8)) | J24: =IF($I24="","",IF(AND($I24>=$H$3,$I24<=$H$4,INDEX(ChqStatus,8)="پاس نشده"),1,0)) | K24: =IF($J24=0,"",INDEX(ChqKey,8)) | L24: =IF($K24="","",COUNTIFS($J$17:$J$516,1,$K$17:$K$516,"<"&$K24)+1)
A25: =IF(IFERROR(MATCH(9,ChqRankU,0),0)=0,"",9) | B25: =IF(IFERROR(MATCH(9,ChqRankU,0),0)=0,"",INDEX(ChqNorm,IFERROR(MATCH(9,ChqRankU,0),0))) | C25: =IF(IFERROR(MATCH(9,ChqRankU,0),0)=0,"",INDEX(ChqNo,IFERROR(MATCH(9,ChqRankU,0),0))) | D25: =IF(IFERROR(MATCH(9,ChqRankU,0),0)=0,"",IF(INDEX(ChqAmt,IFERROR(MATCH(9,ChqRankU,0),0))=0,"",INDEX(ChqAmt,IFERROR(MATCH(9,ChqRankU,0),0)))) | E25: =IF(IFERROR(MATCH(9,ChqRankU,0),0)=0,"",INDEX(ChqStatus,IFERROR(MATCH(9,ChqRankU,0),0))) | F25: =IF(IFERROR(MATCH(9,ChqRankU,0),0)=0,"",IF(INDEX(ChqStatus,IFERROR(MATCH(9,ChqRankU,0),0))="پاس نشده","—",IF(INDEX(ChqClr,IFERROR(MATCH(9,ChqRankU,0),0))="","—",INDEX(ChqClr,IFERROR(MATCH(9,ChqRankU,0),0))))) | I25: =IF(9>NChq,"",INDEX(ChqNorm,9)) | J25: =IF($I25="","",IF(AND($I25>=$H$3,$I25<=$H$4,INDEX(ChqStatus,9)="پاس نشده"),1,0)) | K25: =IF($J25=0,"",INDEX(ChqKey,9)) | L25: =IF($K25="","",COUNTIFS($J$17:$J$516,1,$K$17:$K$516,"<"&$K25)+1)
A26: =IF(IFERROR(MATCH(10,ChqRankU,0),0)=0,"",10) | B26: =IF(IFERROR(MATCH(10,ChqRankU,0),0)=0,"",INDEX(ChqNorm,IFERROR(MATCH(10,ChqRankU,0),0))) | C26: =IF(IFERROR(MATCH(10,ChqRankU,0),0)=0,"",INDEX(ChqNo,IFERROR(MATCH(10,ChqRankU,0),0))) | D26: =IF(IFERROR(MATCH(10,ChqRankU,0),0)=0,"",IF(INDEX(ChqAmt,IFERROR(MATCH(10,ChqRankU,0),0))=0,"",INDEX(ChqAmt,IFERROR(MATCH(10,ChqRankU,0),0)))) | E26: =IF(IFERROR(MATCH(10,ChqRankU,0),0)=0,"",INDEX(ChqStatus,IFERROR(MATCH(10,ChqRankU,0),0))) | F26: =IF(IFERROR(MATCH(10,ChqRankU,0),0)=0,"",IF(INDEX(ChqStatus,IFERROR(MATCH(10,ChqRankU,0),0))="پاس نشده","—",IF(INDEX(ChqClr,IFERROR(MATCH(10,ChqRankU,0),0))="","—",INDEX(ChqClr,IFERROR(MATCH(10,ChqRankU,0),0))))) | I26: =IF(10>NChq,"",INDEX(ChqNorm,10)) | J26: =IF($I26="","",IF(AND($I26>=$H$3,$I26<=$H$4,INDEX(ChqStatus,10)="پاس نشده"),1,0)) | K26: =IF($J26=0,"",INDEX(ChqKey,10)) | L26: =IF($K26="","",COUNTIFS($J$17:$J$516,1,$K$17:$K$516,"<"&$K26)+1)
A27: =IF(IFERROR(MATCH(11,ChqRankU,0),0)=0,"",11) | B27: =IF(IFERROR(MATCH(11,ChqRankU,0),0)=0,"",INDEX(ChqNorm,IFERROR(MATCH(11,ChqRankU,0),0))) | C27: =IF(IFERROR(MATCH(11,ChqRankU,0),0)=0,"",INDEX(ChqNo,IFERROR(MATCH(11,ChqRankU,0),0))) | D27: =IF(IFERROR(MATCH(11,ChqRankU,0),0)=0,"",IF(INDEX(ChqAmt,IFERROR(MATCH(11,ChqRankU,0),0))=0,"",INDEX(ChqAmt,IFERROR(MATCH(11,ChqRankU,0),0)))) | E27: =IF(IFERROR(MATCH(11,ChqRankU,0),0)=0,"",INDEX(ChqStatus,IFERROR(MATCH(11,ChqRankU,0),0))) | F27: =IF(IFERROR(MATCH(11,ChqRankU,0),0)=0,"",IF(INDEX(ChqStatus,IFERROR(MATCH(11,ChqRankU,0),0))="پاس نشده","—",IF(INDEX(ChqClr,IFERROR(MATCH(11,ChqRankU,0),0))="","—",INDEX(ChqClr,IFERROR(MATCH(11,ChqRankU,0),0))))) | I27: =IF(11>NChq,"",INDEX(ChqNorm,11)) | J27: =IF($I27="","",IF(AND($I27>=$H$3,$I27<=$H$4,INDEX(ChqStatus,11)="پاس نشده"),1,0)) | K27: =IF($J27=0,"",INDEX(ChqKey,11)) | L27: =IF($K27="","",COUNTIFS($J$17:$J$516,1,$K$17:$K$516,"<"&$K27)+1)
A28: =IF(IFERROR(MATCH(12,ChqRankU,0),0)=0,"",12) | B28: =IF(IFERROR(MATCH(12,ChqRankU,0),0)=0,"",INDEX(ChqNorm,IFERROR(MATCH(12,ChqRankU,0),0))) | C28: =IF(IFERROR(MATCH(12,ChqRankU,0),0)=0,"",INDEX(ChqNo,IFERROR(MATCH(12,ChqRankU,0),0))) | D28: =IF(IFERROR(MATCH(12,ChqRankU,0),0)=0,"",IF(INDEX(ChqAmt,IFERROR(MATCH(12,ChqRankU,0),0))=0,"",INDEX(ChqAmt,IFERROR(MATCH(12,ChqRankU,0),0)))) | E28: =IF(IFERROR(MATCH(12,ChqRankU,0),0)=0,"",INDEX(ChqStatus,IFERROR(MATCH(12,ChqRankU,0),0))) | F28: =IF(IFERROR(MATCH(12,ChqRankU,0),0)=0,"",IF(INDEX(ChqStatus,IFERROR(MATCH(12,ChqRankU,0),0))="پاس نشده","—",IF(INDEX(ChqClr,IFERROR(MATCH(12,ChqRankU,0),0))="","—",INDEX(ChqClr,IFERROR(MATCH(12,ChqRankU,0),0))))) | I28: =IF(12>NChq,"",INDEX(ChqNorm,12)) | J28: =IF($I28="","",IF(AND($I28>=$H$3,$I28<=$H$4,INDEX(ChqStatus,12)="پاس نشده"),1,0)) | K28: =IF($J28=0,"",INDEX(ChqKey,12)) | L28: =IF($K28="","",COUNTIFS($J$17:$J$516,1,$K$17:$K$516,"<"&$K28)+1)
A29: =IF(IFERROR(MATCH(13,ChqRankU,0),0)=0,"",13) | B29: =IF(IFERROR(MATCH(13,ChqRankU,0),0)=0,"",INDEX(ChqNorm,IFERROR(MATCH(13,ChqRankU,0),0))) | C29: =IF(IFERROR(MATCH(13,ChqRankU,0),0)=0,"",INDEX(ChqNo,IFERROR(MATCH(13,ChqRankU,0),0))) | D29: =IF(IFERROR(MATCH(13,ChqRankU,0),0)=0,"",IF(INDEX(ChqAmt,IFERROR(MATCH(13,ChqRankU,0),0))=0,"",INDEX(ChqAmt,IFERROR(MATCH(13,ChqRankU,0),0)))) | E29: =IF(IFERROR(MATCH(13,ChqRankU,0),0)=0,"",INDEX(ChqStatus,IFERROR(MATCH(13,ChqRankU,0),0))) | F29: =IF(IFERROR(MATCH(13,ChqRankU,0),0)=0,"",IF(INDEX(ChqStatus,IFERROR(MATCH(13,ChqRankU,0),0))="پاس نشده","—",IF(INDEX(ChqClr,IFERROR(MATCH(13,ChqRankU,0),0))="","—",INDEX(ChqClr,IFERROR(MATCH(13,ChqRankU,0),0))))) | I29: =IF(13>NChq,"",INDEX(ChqNorm,13)) | J29: =IF($I29="","",IF(AND($I29>=$H$3,$I29<=$H$4,INDEX(ChqStatus,13)="پاس نشده"),1,0)) | K29: =IF($J29=0,"",INDEX(ChqKey,13)) | L29: =IF($K29="","",COUNTIFS($J$17:$J$516,1,$K$17:$K$516,"<"&$K29)+1)
A30: =IF(IFERROR(MATCH(14,ChqRankU,0),0)=0,"",14) | B30: =IF(IFERROR(MATCH(14,ChqRankU,0),0)=0,"",INDEX(ChqNorm,IFERROR(MATCH(14,ChqRankU,0),0))) | C30: =IF(IFERROR(MATCH(14,ChqRankU,0),0)=0,"",INDEX(ChqNo,IFERROR(MATCH(14,ChqRankU,0),0))) | D30: =IF(IFERROR(MATCH(14,ChqRankU,0),0)=0,"",IF(INDEX(ChqAmt,IFERROR(MATCH(14,ChqRankU,0),0))=0,"",INDEX(ChqAmt,IFERROR(MATCH(14,ChqRankU,0),0)))) | E30: =IF(IFERROR(MATCH(14,ChqRankU,0),0)=0,"",INDEX(ChqStatus,IFERROR(MATCH(14,ChqRankU,0),0))) | F30: =IF(IFERROR(MATCH(14,ChqRankU,0),0)=0,"",IF(INDEX(ChqStatus,IFERROR(MATCH(14,ChqRankU,0),0))="پاس نشده","—",IF(INDEX(ChqClr,IFERROR(MATCH(14,ChqRankU,0),0))="","—",INDEX(ChqClr,IFERROR(MATCH(14,ChqRankU,0),0))))) | I30: =IF(14>NChq,"",INDEX(ChqNorm,14)) | J30: =IF($I30="","",IF(AND($I30>=$H$3,$I30<=$H$4,INDEX(ChqStatus,14)="پاس نشده"),1,0)) | K30: =IF($J30=0,"",INDEX(ChqKey,14)) | L30: =IF($K30="","",COUNTIFS($J$17:$J$516,1,$K$17:$K$516,"<"&$K30)+1)
A31: =IF(IFERROR(MATCH(15,ChqRankU,0),0)=0,"",15) | B31: =IF(IFERROR(MATCH(15,ChqRankU,0),0)=0,"",INDEX(ChqNorm,IFERROR(MATCH(15,ChqRankU,0),0))) | C31: =IF(IFERROR(MATCH(15,ChqRankU,0),0)=0,"",INDEX(ChqNo,IFERROR(MATCH(15,ChqRankU,0),0))) | D31: =IF(IFERROR(MATCH(15,ChqRankU,0),0)=0,"",IF(INDEX(ChqAmt,IFERROR(MATCH(15,ChqRankU,0),0))=0,"",INDEX(ChqAmt,IFERROR(MATCH(15,ChqRankU,0),0)))) | E31: =IF(IFERROR(MATCH(15,ChqRankU,0),0)=0,"",INDEX(ChqStatus,IFERROR(MATCH(15,ChqRankU,0),0))) | F31: =IF(IFERROR(MATCH(15,ChqRankU,0),0)=0,"",IF(INDEX(ChqStatus,IFERROR(MATCH(15,ChqRankU,0),0))="پاس نشده","—",IF(INDEX(ChqClr,IFERROR(MATCH(15,ChqRankU,0),0))="","—",INDEX(ChqClr,IFERROR(MATCH(15,ChqRankU,0),0))))) | I31: =IF(15>NChq,"",INDEX(ChqNorm,15)) | J31: =IF($I31="","",IF(AND($I31>=$H$3,$I31<=$H$4,INDEX(ChqStatus,15)="پاس نشده"),1,0)) | K31: =IF($J31=0,"",INDEX(ChqKey,15)) | L31: =IF($K31="","",COUNTIFS($J$17:$J$516,1,$K$17:$K$516,"<"&$K31)+1)
A32: =IF(IFERROR(MATCH(16,ChqRankU,0),0)=0,"",16) | B32: =IF(IFERROR(MATCH(16,ChqRankU,0),0)=0,"",INDEX(ChqNorm,IFERROR(MATCH(16,ChqRankU,0),0))) | C32: =IF(IFERROR(MATCH(16,ChqRankU,0),0)=0,"",INDEX(ChqNo,IFERROR(MATCH(16,ChqRankU,0),0))) | D32: =IF(IFERROR(MATCH(16,ChqRankU,0),0)=0,"",IF(INDEX(ChqAmt,IFERROR(MATCH(16,ChqRankU,0),0))=0,"",INDEX(ChqAmt,IFERROR(MATCH(16,ChqRankU,0),0)))) | E32: =IF(IFERROR(MATCH(16,ChqRankU,0),0)=0,"",INDEX(ChqStatus,IFERROR(MATCH(16,ChqRankU,0),0))) | F32: =IF(IFERROR(MATCH(16,ChqRankU,0),0)=0,"",IF(INDEX(ChqStatus,IFERROR(MATCH(16,ChqRankU,0),0))="پاس نشده","—",IF(INDEX(ChqClr,IFERROR(MATCH(16,ChqRankU,0),0))="","—",INDEX(ChqClr,IFERROR(MATCH(16,ChqRankU,0),0))))) | I32: =IF(16>NChq,"",INDEX(ChqNorm,16)) | J32: =IF($I32="","",IF(AND($I32>=$H$3,$I32<=$H$4,INDEX(ChqStatus,16)="پاس نشده"),1,0)) | K32: =IF($J32=0,"",INDEX(ChqKey,16)) | L32: =IF($K32="","",COUNTIFS($J$17:$J$516,1,$K$17:$K$516,"<"&$K32)+1)
A33: =IF(IFERROR(MATCH(17,ChqRankU,0),0)=0,"",17) | B33: =IF(IFERROR(MATCH(17,ChqRankU,0),0)=0,"",INDEX(ChqNorm,IFERROR(MATCH(17,ChqRankU,0),0))) | C33: =IF(IFERROR(MATCH(17,ChqRankU,0),0)=0,"",INDEX(ChqNo,IFERROR(MATCH(17,ChqRankU,0),0))) | D33: =IF(IFERROR(MATCH(17,ChqRankU,0),0)=0,"",IF(INDEX(ChqAmt,IFERROR(MATCH(17,ChqRankU,0),0))=0,"",INDEX(ChqAmt,IFERROR(MATCH(17,ChqRankU,0),0)))) | E33: =IF(IFERROR(MATCH(17,ChqRankU,0),0)=0,"",INDEX(ChqStatus,IFERROR(MATCH(17,ChqRankU,0),0))) | F33: =IF(IFERROR(MATCH(17,ChqRankU,0),0)=0,"",IF(INDEX(ChqStatus,IFERROR(MATCH(17,ChqRankU,0),0))="پاس نشده","—",IF(INDEX(ChqClr,IFERROR(MATCH(17,ChqRankU,0),0))="","—",INDEX(ChqClr,IFERROR(MATCH(17,ChqRankU,0),0))))) | I33: =IF(17>NChq,"",INDEX(ChqNorm,17)) | J33: =IF($I33="","",IF(AND($I33>=$H$3,$I33<=$H$4,INDEX(ChqStatus,17)="پاس نشده"),1,0)) | K33: =IF($J33=0,"",INDEX(ChqKey,17)) | L33: =IF($K33="","",COUNTIFS($J$17:$J$516,1,$K$17:$K$516,"<"&$K33)+1)
A34: =IF(IFERROR(MATCH(18,ChqRankU,0),0)=0,"",18) | B34: =IF(IFERROR(MATCH(18,ChqRankU,0),0)=0,"",INDEX(ChqNorm,IFERROR(MATCH(18,ChqRankU,0),0))) | C34: =IF(IFERROR(MATCH(18,ChqRankU,0),0)=0,"",INDEX(ChqNo,IFERROR(MATCH(18,ChqRankU,0),0))) | D34: =IF(IFERROR(MATCH(18,ChqRankU,0),0)=0,"",IF(INDEX(ChqAmt,IFERROR(MATCH(18,ChqRankU,0),0))=0,"",INDEX(ChqAmt,IFERROR(MATCH(18,ChqRankU,0),0)))) | E34: =IF(IFERROR(MATCH(18,ChqRankU,0),0)=0,"",INDEX(ChqStatus,IFERROR(MATCH(18,ChqRankU,0),0))) | F34: =IF(IFERROR(MATCH(18,ChqRankU,0),0)=0,"",IF(INDEX(ChqStatus,IFERROR(MATCH(18,ChqRankU,0),0))="پاس نشده","—",IF(INDEX(ChqClr,IFERROR(MATCH(18,ChqRankU,0),0))="","—",INDEX(ChqClr,IFERROR(MATCH(18,ChqRankU,0),0))))) | I34: =IF(18>NChq,"",INDEX(ChqNorm,18)) | J34: =IF($I34="","",IF(AND($I34>=$H$3,$I34<=$H$4,INDEX(ChqStatus,18)="پاس نشده"),1,0)) | K34: =IF($J34=0,"",INDEX(ChqKey,18)) | L34: =IF($K34="","",COUNTIFS($J$17:$J$516,1,$K$17:$K$516,"<"&$K34)+1)
A35: =IF(IFERROR(MATCH(19,ChqRankU,0),0)=0,"",19) | B35: =IF(IFERROR(MATCH(19,ChqRankU,0),0)=0,"",INDEX(ChqNorm,IFERROR(MATCH(19,ChqRankU,0),0))) | C35: =IF(IFERROR(MATCH(19,ChqRankU,0),0)=0,"",INDEX(ChqNo,IFERROR(MATCH(19,ChqRankU,0),0))) | D35: =IF(IFERROR(MATCH(19,ChqRankU,0),0)=0,"",IF(INDEX(ChqAmt,IFERROR(MATCH(19,ChqRankU,0),0))=0,"",INDEX(ChqAmt,IFERROR(MATCH(19,ChqRankU,0),0)))) | E35: =IF(IFERROR(MATCH(19,ChqRankU,0),0)=0,"",INDEX(ChqStatus,IFERROR(MATCH(19,ChqRankU,0),0))) | F35: =IF(IFERROR(MATCH(19,ChqRankU,0),0)=0,"",IF(INDEX(ChqStatus,IFERROR(MATCH(19,ChqRankU,0),0))="پاس نشده","—",IF(INDEX(ChqClr,IFERROR(MATCH(19,ChqRankU,0),0))="","—",INDEX(ChqClr,IFERROR(MATCH(19,ChqRankU,0),0))))) | I35: =IF(19>NChq,"",INDEX(ChqNorm,19)) | J35: =IF($I35="","",IF(AND($I35>=$H$3,$I35<=$H$4,INDEX(ChqStatus,19)="پاس نشده"),1,0)) | K35: =IF($J35=0,"",INDEX(ChqKey,19)) | L35: =IF($K35="","",COUNTIFS($J$17:$J$516,1,$K$17:$K$516,"<"&$K35)+1)
A36: =IF(IFERROR(MATCH(20,ChqRankU,0),0)=0,"",20) | B36: =IF(IFERROR(MATCH(20,ChqRankU,0),0)=0,"",INDEX(ChqNorm,IFERROR(MATCH(20,ChqRankU,0),0))) | C36: =IF(IFERROR(MATCH(20,ChqRankU,0),0)=0,"",INDEX(ChqNo,IFERROR(MATCH(20,ChqRankU,0),0))) | D36: =IF(IFERROR(MATCH(20,ChqRankU,0),0)=0,"",IF(INDEX(ChqAmt,IFERROR(MATCH(20,ChqRankU,0),0))=0,"",INDEX(ChqAmt,IFERROR(MATCH(20,ChqRankU,0),0)))) | E36: =IF(IFERROR(MATCH(20,ChqRankU,0),0)=0,"",INDEX(ChqStatus,IFERROR(MATCH(20,ChqRankU,0),0))) | F36: =IF(IFERROR(MATCH(20,ChqRankU,0),0)=0,"",IF(INDEX(ChqStatus,IFERROR(MATCH(20,ChqRankU,0),0))="پاس نشده","—",IF(INDEX(ChqClr,IFERROR(MATCH(20,ChqRankU,0),0))="","—",INDEX(ChqClr,IFERROR(MATCH(20,ChqRankU,0),0))))) | I36: =IF(20>NChq,"",INDEX(ChqNorm,20)) | J36: =IF($I36="","",IF(AND($I36>=$H$3,$I36<=$H$4,INDEX(ChqStatus,20)="پاس نشده"),1,0)) | K36: =IF($J36=0,"",INDEX(ChqKey,20)) | L36: =IF($K36="","",COUNTIFS($J$17:$J$516,1,$K$17:$K$516,"<"&$K36)+1)
A37: =IF(IFERROR(MATCH(21,ChqRankU,0),0)=0,"",21) | B37: =IF(IFERROR(MATCH(21,ChqRankU,0),0)=0,"",INDEX(ChqNorm,IFERROR(MATCH(21,ChqRankU,0),0))) | C37: =IF(IFERROR(MATCH(21,ChqRankU,0),0)=0,"",INDEX(ChqNo,IFERROR(MATCH(21,ChqRankU,0),0))) | D37: =IF(IFERROR(MATCH(21,ChqRankU,0),0)=0,"",IF(INDEX(ChqAmt,IFERROR(MATCH(21,ChqRankU,0),0))=0,"",INDEX(ChqAmt,IFERROR(MATCH(21,ChqRankU,0),0)))) | E37: =IF(IFERROR(MATCH(21,ChqRankU,0),0)=0,"",INDEX(ChqStatus,IFERROR(MATCH(21,ChqRankU,0),0))) | F37: =IF(IFERROR(MATCH(21,ChqRankU,0),0)=0,"",IF(INDEX(ChqStatus,IFERROR(MATCH(21,ChqRankU,0),0))="پاس نشده","—",IF(INDEX(ChqClr,IFERROR(MATCH(21,ChqRankU,0),0))="","—",INDEX(ChqClr,IFERROR(MATCH(21,ChqRankU,0),0))))) | I37: =IF(21>NChq,"",INDEX(ChqNorm,21)) | J37: =IF($I37="","",IF(AND($I37>=$H$3,$I37<=$H$4,INDEX(ChqStatus,21)="پاس نشده"),1,0)) | K37: =IF($J37=0,"",INDEX(ChqKey,21)) | L37: =IF($K37="","",COUNTIFS($J$17:$J$516,1,$K$17:$K$516,"<"&$K37)+1)
A38: =IF(IFERROR(MATCH(22,ChqRankU,0),0)=0,"",22) | B38: =IF(IFERROR(MATCH(22,ChqRankU,0),0)=0,"",INDEX(ChqNorm,IFERROR(MATCH(22,ChqRankU,0),0))) | C38: =IF(IFERROR(MATCH(22,ChqRankU,0),0)=0,"",INDEX(ChqNo,IFERROR(MATCH(22,ChqRankU,0),0))) | D38: =IF(IFERROR(MATCH(22,ChqRankU,0),0)=0,"",IF(INDEX(ChqAmt,IFERROR(MATCH(22,ChqRankU,0),0))=0,"",INDEX(ChqAmt,IFERROR(MATCH(22,ChqRankU,0),0)))) | E38: =IF(IFERROR(MATCH(22,ChqRankU,0),0)=0,"",INDEX(ChqStatus,IFERROR(MATCH(22,ChqRankU,0),0))) | F38: =IF(IFERROR(MATCH(22,ChqRankU,0),0)=0,"",IF(INDEX(ChqStatus,IFERROR(MATCH(22,ChqRankU,0),0))="پاس نشده","—",IF(INDEX(ChqClr,IFERROR(MATCH(22,ChqRankU,0),0))="","—",INDEX(ChqClr,IFERROR(MATCH(22,ChqRankU,0),0))))) | I38: =IF(22>NChq,"",INDEX(ChqNorm,22)) | J38: =IF($I38="","",IF(AND($I38>=$H$3,$I38<=$H$4,INDEX(ChqStatus,22)="پاس نشده"),1,0)) | K38: =IF($J38=0,"",INDEX(ChqKey,22)) | L38: =IF($K38="","",COUNTIFS($J$17:$J$516,1,$K$17:$K$516,"<"&$K38)+1)
A39: =IF(IFERROR(MATCH(23,ChqRankU,0),0)=0,"",23) | B39: =IF(IFERROR(MATCH(23,ChqRankU,0),0)=0,"",INDEX(ChqNorm,IFERROR(MATCH(23,ChqRankU,0),0))) | C39: =IF(IFERROR(MATCH(23,ChqRankU,0),0)=0,"",INDEX(ChqNo,IFERROR(MATCH(23,ChqRankU,0),0))) | D39: =IF(IFERROR(MATCH(23,ChqRankU,0),0)=0,"",IF(INDEX(ChqAmt,IFERROR(MATCH(23,ChqRankU,0),0))=0,"",INDEX(ChqAmt,IFERROR(MATCH(23,ChqRankU,0),0)))) | E39: =IF(IFERROR(MATCH(23,ChqRankU,0),0)=0,"",INDEX(ChqStatus,IFERROR(MATCH(23,ChqRankU,0),0))) | F39: =IF(IFERROR(MATCH(23,ChqRankU,0),0)=0,"",IF(INDEX(ChqStatus,IFERROR(MATCH(23,ChqRankU,0),0))="پاس نشده","—",IF(INDEX(ChqClr,IFERROR(MATCH(23,ChqRankU,0),0))="","—",INDEX(ChqClr,IFERROR(MATCH(23,ChqRankU,0),0))))) | I39: =IF(23>NChq,"",INDEX(ChqNorm,23)) | J39: =IF($I39="","",IF(AND($I39>=$H$3,$I39<=$H$4,INDEX(ChqStatus,23)="پاس نشده"),1,0)) | K39: =IF($J39=0,"",INDEX(ChqKey,23)) | L39: =IF($K39="","",COUNTIFS($J$17:$J$516,1,$K$17:$K$516,"<"&$K39)+1)
A40: =IF(IFERROR(MATCH(24,ChqRankU,0),0)=0,"",24) | B40: =IF(IFERROR(MATCH(24,ChqRankU,0),0)=0,"",INDEX(ChqNorm,IFERROR(MATCH(24,ChqRankU,0),0))) | C40: =IF(IFERROR(MATCH(24,ChqRankU,0),0)=0,"",INDEX(ChqNo,IFERROR(MATCH(24,ChqRankU,0),0))) | D40: =IF(IFERROR(MATCH(24,ChqRankU,0),0)=0,"",IF(INDEX(ChqAmt,IFERROR(MATCH(24,ChqRankU,0),0))=0,"",INDEX(ChqAmt,IFERROR(MATCH(24,ChqRankU,0),0)))) | E40: =IF(IFERROR(MATCH(24,ChqRankU,0),0)=0,"",INDEX(ChqStatus,IFERROR(MATCH(24,ChqRankU,0),0))) | F40: =IF(IFERROR(MATCH(24,ChqRankU,0),0)=0,"",IF(INDEX(ChqStatus,IFERROR(MATCH(24,ChqRankU,0),0))="پاس نشده","—",IF(INDEX(ChqClr,IFERROR(MATCH(24,ChqRankU,0),0))="","—",INDEX(ChqClr,IFERROR(MATCH(24,ChqRankU,0),0))))) | I40: =IF(24>NChq,"",INDEX(ChqNorm,24)) | J40: =IF($I40="","",IF(AND($I40>=$H$3,$I40<=$H$4,INDEX(ChqStatus,24)="پاس نشده"),1,0)) | K40: =IF($J40=0,"",INDEX(ChqKey,24)) | L40: =IF($K40="","",COUNTIFS($J$17:$J$516,1,$K$17:$K$516,"<"&$K40)+1)
A41: =IF(IFERROR(MATCH(25,ChqRankU,0),0)=0,"",25) | B41: =IF(IFERROR(MATCH(25,ChqRankU,0),0)=0,"",INDEX(ChqNorm,IFERROR(MATCH(25,ChqRankU,0),0))) | C41: =IF(IFERROR(MATCH(25,ChqRankU,0),0)=0,"",INDEX(ChqNo,IFERROR(MATCH(25,ChqRankU,0),0))) | D41: =IF(IFERROR(MATCH(25,ChqRankU,0),0)=0,"",IF(INDEX(ChqAmt,IFERROR(MATCH(25,ChqRankU,0),0))=0,"",INDEX(ChqAmt,IFERROR(MATCH(25,ChqRankU,0),0)))) | E41: =IF(IFERROR(MATCH(25,ChqRankU,0),0)=0,"",INDEX(ChqStatus,IFERROR(MATCH(25,ChqRankU,0),0))) | F41: =IF(IFERROR(MATCH(25,ChqRankU,0),0)=0,"",IF(INDEX(ChqStatus,IFERROR(MATCH(25,ChqRankU,0),0))="پاس نشده","—",IF(INDEX(ChqClr,IFERROR(MATCH(25,ChqRankU,0),0))="","—",INDEX(ChqClr,IFERROR(MATCH(25,ChqRankU,0),0))))) | I41: =IF(25>NChq,"",INDEX(ChqNorm,25)) | J41: =IF($I41="","",IF(AND($I41>=$H$3,$I41<=$H$4,INDEX(ChqStatus,25)="پاس نشده"),1,0)) | K41: =IF($J41=0,"",INDEX(ChqKey,25)) | L41: =IF($K41="","",COUNTIFS($J$17:$J$516,1,$K$17:$K$516,"<"&$K41)+1)
A42: =IF(IFERROR(MATCH(26,ChqRankU,0),0)=0,"",26) | B42: =IF(IFERROR(MATCH(26,ChqRankU,0),0)=0,"",INDEX(ChqNorm,IFERROR(MATCH(26,ChqRankU,0),0))) | C42: =IF(IFERROR(MATCH(26,ChqRankU,0),0)=0,"",INDEX(ChqNo,IFERROR(MATCH(26,ChqRankU,0),0))) | D42: =IF(IFERROR(MATCH(26,ChqRankU,0),0)=0,"",IF(INDEX(ChqAmt,IFERROR(MATCH(26,ChqRankU,0),0))=0,"",INDEX(ChqAmt,IFERROR(MATCH(26,ChqRankU,0),0)))) | E42: =IF(IFERROR(MATCH(26,ChqRankU,0),0)=0,"",INDEX(ChqStatus,IFERROR(MATCH(26,ChqRankU,0),0))) | F42: =IF(IFERROR(MATCH(26,ChqRankU,0),0)=0,"",IF(INDEX(ChqStatus,IFERROR(MATCH(26,ChqRankU,0),0))="پاس نشده","—",IF(INDEX(ChqClr,IFERROR(MATCH(26,ChqRankU,0),0))="","—",INDEX(ChqClr,IFERROR(MATCH(26,ChqRankU,0),0))))) | I42: =IF(26>NChq,"",INDEX(ChqNorm,26)) | J42: =IF($I42="","",IF(AND($I42>=$H$3,$I42<=$H$4,INDEX(ChqStatus,26)="پاس نشده"),1,0)) | K42: =IF($J42=0,"",INDEX(ChqKey,26)) | L42: =IF($K42="","",COUNTIFS($J$17:$J$516,1,$K$17:$K$516,"<"&$K42)+1)
A43: =IF(IFERROR(MATCH(27,ChqRankU,0),0)=0,"",27) | B43: =IF(IFERROR(MATCH(27,ChqRankU,0),0)=0,"",INDEX(ChqNorm,IFERROR(MATCH(27,ChqRankU,0),0))) | C43: =IF(IFERROR(MATCH(27,ChqRankU,0),0)=0,"",INDEX(ChqNo,IFERROR(MATCH(27,ChqRankU,0),0))) | D43: =IF(IFERROR(MATCH(27,ChqRankU,0),0)=0,"",IF(INDEX(ChqAmt,IFERROR(MATCH(27,ChqRankU,0),0))=0,"",INDEX(ChqAmt,IFERROR(MATCH(27,ChqRankU,0),0)))) | E43: =IF(IFERROR(MATCH(27,ChqRankU,0),0)=0,"",INDEX(ChqStatus,IFERROR(MATCH(27,ChqRankU,0),0))) | F43: =IF(IFERROR(MATCH(27,ChqRankU,0),0)=0,"",IF(INDEX(ChqStatus,IFERROR(MATCH(27,ChqRankU,0),0))="پاس نشده","—",IF(INDEX(ChqClr,IFERROR(MATCH(27,ChqRankU,0),0))="","—",INDEX(ChqClr,IFERROR(MATCH(27,ChqRankU,0),0))))) | I43: =IF(27>NChq,"",INDEX(ChqNorm,27)) | J43: =IF($I43="","",IF(AND($I43>=$H$3,$I43<=$H$4,INDEX(ChqStatus,27)="پاس نشده"),1,0)) | K43: =IF($J43=0,"",INDEX(ChqKey,27)) | L43: =IF($K43="","",COUNTIFS($J$17:$J$516,1,$K$17:$K$516,"<"&$K43)+1)
