Workbook
Name AcctTbl: Sync!$A$6:$F$565
Name AcctCodes: Sync!$A$6:$A$565
Name OpTbl: Sync!$I$6:$K$25
Name ParamTbl: Sync!$O$6:$Q$17
Name PkAcctAll: Sync!$AS$6:$AS$565
Name NAcctAll: Sync!$AR$565
Name CalcNormDate: Calc!$E$9:$E$2008
Name CalcYM: Calc!$F$9:$F$2008
Name CalcParty: Calc!$G$9:$G$2008
Name CalcOp: Calc!$H$9:$H$2008
Name CalcGroup: Calc!$I$9:$I$2008
Name CalcSub: Calc!$J$9:$J$2008
Name CalcCitrus: Calc!$K$9:$K$2008
Name CalcScale: Calc!$L$9:$L$2008
Name CalcBaskets: Calc!$M$9:$M$2008
Name CalcNet: Calc!$N$9:$N$2008
Name CalcAmount: Calc!$O$9:$O$2008
Name PCNormDate: Calc!$E$9:$E$2008
Name PCOp: Calc!$H$9:$H$2008
Name PCCitrus: Calc!$K$9:$K$2008
Name PCScale: Calc!$L$9:$L$2008
Name PCBaskets: Calc!$M$9:$M$2008
Name PCNet: Calc!$N$9:$N$2008
Name PCAmount: Calc!$O$9:$O$2008
Name PCDoc: Calc!$P$9:$P$2008
Name PCNotes: Calc!$Q$9:$Q$2008
Name LdgPartyA: Ledger!$A$6:$A$2005
Name LdgKeyA: Ledger!$B$6:$B$2005
Name LdgRankKeyA: Ledger!$D$6:$D$2005
Name LdgPartyB: Ledger!$F$6:$F$2005
Name LdgKeyB: Ledger!$K$6:$K$2005
Name LdgRankKeyB: Ledger!$M$6:$M$2005
Name LdgDateB: Ledger!$J$6:$J$2005
Name TxnDepB: Sync!$AM$6:$AM$2005
Name TxnWitB: Sync!$AN$6:$AN$2005
Name LdgBankB: Sync!$AI$6:$AI$2005
Name LdgNoteB: Sync!$AO$6:$AO$2005

Sheet Report
A1: =IF(Sync!$N$6="","مازندشت",Sync!$N$6)&" — "&IF(Sync!$N$9="","سورتینگ و بسته‌بندی مرکبات",Sync!$N$9)
A2: =IF(Sync!$N$7="","باغدشت، بخش مرکزی، شهرستان قائم‌شهر، استان مازندران، ایران",Sync!$N$7)&" | MAZANDASHT · CITRUS SORTING & PACKING"
A3: ="گزارش خرید — "&IFERROR(IF(VLOOKUP($C$5,AcctTbl,4,0)="","(بدون عنوان)",VLOOKUP($C$5,AcctTbl,4,0)),"کد را وارد کنید")
A5: کد حساب (ورود دستی): | C5: S001 | E5: کد را از فایل INFO (شیت Accounts) وارد کنید — همه‌چیز این شیت خودکار به‌روز می‌شود. برای حساب دیگر، همین شیت را کپی و کد را عوض کنید.
A6: نام صاحب حساب: | C6: =IFERROR(IF(VLOOKUP($C$5,AcctTbl,4,0)="","(بدون عنوان)",VLOOKUP($C$5,AcctTbl,4,0)),"—")
A7: نوع حساب: | C7: =IFERROR(IF(VLOOKUP($C$5,AcctTbl,3,0)="",IF(VLOOKUP($C$5,AcctTbl,2,0)="","—",VLOOKUP($C$5,AcctTbl,2,0)),VLOOKUP($C$5,AcctTbl,3,0)),"—")
A8: گروه حسابداری: | C8: =IFERROR(IF(VLOOKUP($C$5,AcctTbl,5,0)="","—",VLOOKUP($C$5,AcctTbl,5,0)),"—")
A9: گروه حسابرسی: | C9: =IFERROR(IF(VLOOKUP($C$5,AcctTbl,6,0)="","—",VLOOKUP($C$5,AcctTbl,6,0)),"—")
A10: مانده اولیه بدهی (دستی): | C10: 0 | E10: اگر از قبل بدهی دارید (مثبت = بدهکار ما) اینجا بنویسید — در مانده‌ها اثر می‌گذارد.
A11: جمع وزن خالص خرید (kg) | C11: جمع وزن باسکول (kg) | E11: جمع مبلغ خرید (ریال) | G11: مانده نهایی بدهی | J11: وضعیت
A12: =SUM($H$17:$H$2016) | C12: =SUM($F$17:$F$2016) | E12: =SUM($I$17:$I$2016) | G12: =IFERROR(LOOKUP(9.99E+307,$K$17:$K$2016),$C$10) | J12: =IF($G$12>0,"● بدهکار — به او بدهکاریم",IF($G$12<0,"● بستانکار — به ما بدهکار است","= تسویه شده"))
A13: تعداد توزین خرید | C13: تعداد پرداخت/دریافت | E13: جمع پرداخت‌ها (ریال) | G13: جمع تعداد سبد | J13: آخرین تراکنش
A14: =COUNTIF($C$17:$C$2016,"خرید مرکبات")+COUNTIF($C$17:$C$2016,"مرجوعی خرید") | C14: =COUNTIF($C$17:$C$2016,"پرداخت بانکی")+COUNTIF($C$17:$C$2016,"دریافت بانکی") | E14: =SUM($J$17:$J$2016) | G14: =SUM($G$17:$G$2016) | J14: =IF(COUNT($K$17:$K$2016)=0,"—",INDEX($B$17:$B$2016,COUNT($K$17:$K$2016)))
A15: ردیف | B15: تاریخ | C15: نوع عملیات | D15: سند | E15: نوع مرکبات | F15: باسکول (kg) | G15: سبد | H15: خالص (kg) | I15: بدهکار (ریال) | J15: بستانکار (ریال) | K15: مانده (ریال) | L15: توضیحات
A16: No. | B16: Date | C16: Type | D16: Doc | E16: Citrus | F16: Scale | G16: Baskets | H16: Net | I16: Debit | J16: Credit | K16: Balance | L16: Notes
A17: 1 | B17: =IF(AND($N17="",$O17=""),"",IF($N17<>"",INDEX(PCNormDate,$N17),INDEX(LdgDateB,$O17))) | C17: =IF($N17<>"",INDEX(PCOp,$N17),IF($O17<>"",IF(N(INDEX(TxnDepB,$O17))>0,"دریافت بانکی","پرداخت بانکی"),"")) | D17: =IF($N17<>"",IF(INDEX(PCDoc,$N17)="","—",INDEX(PCDoc,$N17)),IF($O17<>"",INDEX(LdgBankB,$O17),"")) | E17: =IF($N17<>"",IF(INDEX(PCCitrus,$N17)="","—",INDEX(PCCitrus,$N17)),"") | F17: =IF($N17<>"",IF(INDEX(PCScale,$N17)=0,"",INDEX(PCScale,$N17)),"") | G17: =IF($N17<>"",IF(INDEX(PCBaskets,$N17)=0,"",INDEX(PCBaskets,$N17)),"") | H17: =IF($N17<>"",IF(INDEX(PCNet,$N17)=0,"",INDEX(PCNet,$N17)),"") | I17: =IF($N17<>"",IF(INDEX(PCOp,$N17)="مرجوعی خرید","",IF(INDEX(PCAmount,$N17)<=0,"",INDEX(PCAmount,$N17))),IF($O17<>"",IF(INDEX(TxnDepB,$O17)=0,"",INDEX(TxnDepB,$O17)),"")) | J17: =IF($N17<>"",IF(INDEX(PCOp,$N17)="مرجوعی خرید",IF(INDEX(PCAmount,$N17)=0,"",-INDEX(PCAmount,$N17)),""),IF($O17<>"",IF(INDEX(TxnWitB,$O17)=0,"",INDEX(TxnWitB,$O17)),"")) | K17: =IF($B17="","",$C$10+IF($I17="",0,$I17)-IF($J17="",0,$J17)) | L17: =IF($N17<>"",IF(INDEX(PCNotes,$N17)="","—",INDEX(PCNotes,$N17)),IF($O17<>"",IF(INDEX(LdgNoteB,$O17)="","—",INDEX(LdgNoteB,$O17)),"")) | N17: =IFERROR(MATCH($C$5&"|"&RIGHT("000000"&1,6),LdgRankKeyA,0),"") | O17: =IFERROR(MATCH($C$5&"|"&RIGHT("000000"&1,6),LdgRankKeyB,0),"")
A18: 2 | B18: =IF(AND($N18="",$O18=""),"",IF($N18<>"",INDEX(PCNormDate,$N18),INDEX(LdgDateB,$O18))) | C18: =IF($N18<>"",INDEX(PCOp,$N18),IF($O18<>"",IF(N(INDEX(TxnDepB,$O18))>0,"دریافت بانکی","پرداخت بانکی"),"")) | D18: =IF($N18<>"",IF(INDEX(PCDoc,$N18)="","—",INDEX(PCDoc,$N18)),IF($O18<>"",INDEX(LdgBankB,$O18),"")) | E18: =IF($N18<>"",IF(INDEX(PCCitrus,$N18)="","—",INDEX(PCCitrus,$N18)),"") | F18: =IF($N18<>"",IF(INDEX(PCScale,$N18)=0,"",INDEX(PCScale,$N18)),"") | G18: =IF($N18<>"",IF(INDEX(PCBaskets,$N18)=0,"",INDEX(PCBaskets,$N18)),"") | H18: =IF($N18<>"",IF(INDEX(PCNet,$N18)=0,"",INDEX(PCNet,$N18)),"") | I18: =IF($N18<>"",IF(INDEX(PCOp,$N18)="مرجوعی خرید","",IF(INDEX(PCAmount,$N18)<=0,"",INDEX(PCAmount,$N18))),IF($O18<>"",IF(INDEX(TxnDepB,$O18)=0,"",INDEX(TxnDepB,$O18)),"")) | J18: =IF($N18<>"",IF(INDEX(PCOp,$N18)="مرجوعی خرید",IF(INDEX(PCAmount,$N18)=0,"",-INDEX(PCAmount,$N18)),""),IF($O18<>"",IF(INDEX(TxnWitB,$O18)=0,"",INDEX(TxnWitB,$O18)),"")) | K18: =IF($B18="","",IF($K17="",$C$10,$K17)+IF($I18="",0,$I18)-IF($J18="",0,$J18)) | L18: =IF($N18<>"",IF(INDEX(PCNotes,$N18)="","—",INDEX(PCNotes,$N18)),IF($O18<>"",IF(INDEX(LdgNoteB,$O18)="","—",INDEX(LdgNoteB,$O18)),"")) | N18: =IFERROR(MATCH($C$5&"|"&RIGHT("000000"&2,6),LdgRankKeyA,0),"") | O18: =IFERROR(MATCH($C$5&"|"&RIGHT("000000"&2,6),LdgRankKeyB,0),"")
A19: 3 | B19: =IF(AND($N19="",$O19=""),"",IF($N19<>"",INDEX(PCNormDate,$N19),INDEX(LdgDateB,$O19))) | C19: =IF($N19<>"",INDEX(PCOp,$N19),IF($O19<>"",IF(N(INDEX(TxnDepB,$O19))>0,"دریافت بانکی","پرداخت بانکی"),"")) | D19: =IF($N19<>"",IF(INDEX(PCDoc,$N19)="","—",INDEX(PCDoc,$N19)),IF($O19<>"",INDEX(LdgBankB,$O19),"")) | E19: =IF($N19<>"",IF(INDEX(PCCitrus,$N19)="","—",INDEX(PCCitrus,$N19)),"") | F19: =IF($N19<>"",IF(INDEX(PCScale,$N19)=0,"",INDEX(PCScale,$N19)),"") | G19: =IF($N19<>"",IF(INDEX(PCBaskets,$N19)=0,"",INDEX(PCBaskets,$N19)),"") | H19: =IF($N19<>"",IF(INDEX(PCNet,$N19)=0,"",INDEX(PCNet,$N19)),"") | I19: =IF($N19<>"",IF(INDEX(PCOp,$N19)="مرجوعی خرید","",IF(INDEX(PCAmount,$N19)<=0,"",INDEX(PCAmount,$N19))),IF($O19<>"",IF(INDEX(TxnDepB,$O19)=0,"",INDEX(TxnDepB,$O19)),"")) | J19: =IF($N19<>"",IF(INDEX(PCOp,$N19)="مرجوعی خرید",IF(INDEX(PCAmount,$N19)=0,"",-INDEX(PCAmount,$N19)),""),IF($O19<>"",IF(INDEX(TxnWitB,$O19)=0,"",INDEX(TxnWitB,$O19)),"")) | K19: =IF($B19="","",IF($K18="",$C$10,$K18)+IF($I19="",0,$I19)-IF($J19="",0,$J19)) | L19: =IF($N19<>"",IF(INDEX(PCNotes,$N19)="","—",INDEX(PCNotes,$N19)),IF($O19<>"",IF(INDEX(LdgNoteB,$O19)="","—",INDEX(LdgNoteB,$O19)),"")) | N19: =IFERROR(MATCH($C$5&"|"&RIGHT("000000"&3,6),LdgRankKeyA,0),"") | O19: =IFERROR(MATCH($C$5&"|"&RIGHT("000000"&3,6),LdgRankKeyB,0),"")
A20: 4 | B20: =IF(AND($N20="",$O20=""),"",IF($N20<>"",INDEX(PCNormDate,$N20),INDEX(LdgDateB,$O20))) | C20: =IF($N20<>"",INDEX(PCOp,$N20),IF($O20<>"",IF(N(INDEX(TxnDepB,$O20))>0,"دریافت بانکی","پرداخت بانکی"),"")) | D20: =IF($N20<>"",IF(INDEX(PCDoc,$N20)="","—",INDEX(PCDoc,$N20)),IF($O20<>"",INDEX(LdgBankB,$O20),"")) | E20: =IF($N20<>"",IF(INDEX(PCCitrus,$N20)="","—",INDEX(PCCitrus,$N20)),"") | F20: =IF($N20<>"",IF(INDEX(PCScale,$N20)=0,"",INDEX(PCScale,$N20)),"") | G20: =IF($N20<>"",IF(INDEX(PCBaskets,$N20)=0,"",INDEX(PCBaskets,$N20)),"") | H20: =IF($N20<>"",IF(INDEX(PCNet,$N20)=0,"",INDEX(PCNet,$N20)),"") | I20: =IF($N20<>"",IF(INDEX(PCOp,$N20)="مرجوعی خرید","",IF(INDEX(PCAmount,$N20)<=0,"",INDEX(PCAmount,$N20))),IF($O20<>"",IF(INDEX(TxnDepB,$O20)=0,"",INDEX(TxnDepB,$O20)),"")) | J20: =IF($N20<>"",IF(INDEX(PCOp,$N20)="مرجوعی خرید",IF(INDEX(PCAmount,$N20)=0,"",-INDEX(PCAmount,$N20)),""),IF($O20<>"",IF(INDEX(TxnWitB,$O20)=0,"",INDEX(TxnWitB,$O20)),"")) | K20: =IF($B20="","",IF($K19="",$C$10,$K19)+IF($I20="",0,$I20)-IF($J20="",0,$J20)) | L20: =IF($N20<>"",IF(INDEX(PCNotes,$N20)="","—",INDEX(PCNotes,$N20)),IF($O20<>"",IF(INDEX(LdgNoteB,$O20)="","—",INDEX(LdgNoteB,$O20)),"")) | N20: =IFERROR(MATCH($C$5&"|"&RIGHT("000000"&4,6),LdgRankKeyA,0),"") | O20: =IFERROR(MATCH($C$5&"|"&RIGHT("000000"&4,6),LdgRankKeyB,0),"")
A21: 5 | B21: =IF(AND($N21="",$O21=""),"",IF($N21<>"",INDEX(PCNormDate,$N21),INDEX(LdgDateB,$O21))) | C21: =IF($N21<>"",INDEX(PCOp,$N21),IF($O21<>"",IF(N(INDEX(TxnDepB,$O21))>0,"دریافت بانکی","پرداخت بانکی"),"")) | D21: =IF($N21<>"",IF(INDEX(PCDoc,$N21)="","—",INDEX(PCDoc,$N21)),IF($O21<>"",INDEX(LdgBankB,$O21),"")) | E21: =IF($N21<>"",IF(INDEX(PCCitrus,$N21)="","—",INDEX(PCCitrus,$N21)),"") | F21: =IF($N21<>"",IF(INDEX(PCScale,$N21)=0,"",INDEX(PCScale,$N21)),"") | G21: =IF($N21<>"",IF(INDEX(PCBaskets,$N21)=0,"",INDEX(PCBaskets,$N21)),"") | H21: =IF($N21<>"",IF(INDEX(PCNet,$N21)=0,"",INDEX(PCNet,$N21)),"") | I21: =IF($N21<>"",IF(INDEX(PCOp,$N21)="مرجوعی خرید","",IF(INDEX(PCAmount,$N21)<=0,"",INDEX(PCAmount,$N21))),IF($O21<>"",IF(INDEX(TxnDepB,$O21)=0,"",INDEX(TxnDepB,$O21)),"")) | J21: =IF($N21<>"",IF(INDEX(PCOp,$N21)="مرجوعی خرید",IF(INDEX(PCAmount,$N21)=0,"",-INDEX(PCAmount,$N21)),""),IF($O21<>"",IF(INDEX(TxnWitB,$O21)=0,"",INDEX(TxnWitB,$O21)),"")) | K21: =IF($B21="","",IF($K20="",$C$10,$K20)+IF($I21="",0,$I21)-IF($J21="",0,$J21)) | L21: =IF($N21<>"",IF(INDEX(PCNotes,$N21)="","—",INDEX(PCNotes,$N21)),IF($O21<>"",IF(INDEX(LdgNoteB,$O21)="","—",INDEX(LdgNoteB,$O21)),"")) | N21: =IFERROR(MATCH($C$5&"|"&RIGHT("000000"&5,6),LdgRankKeyA,0),"") | O21: =IFERROR(MATCH($C$5&"|"&RIGHT("000000"&5,6),LdgRankKeyB,0),"")
A22: 6 | B22: =IF(AND($N22="",$O22=""),"",IF($N22<>"",INDEX(PCNormDate,$N22),INDEX(LdgDateB,$O22))) | C22: =IF($N22<>"",INDEX(PCOp,$N22),IF($O22<>"",IF(N(INDEX(TxnDepB,$O22))>0,"دریافت بانکی","پرداخت بانکی"),"")) | D22: =IF($N22<>"",IF(INDEX(PCDoc,$N22)="","—",INDEX(PCDoc,$N22)),IF($O22<>"",INDEX(LdgBankB,$O22),"")) | E22: =IF($N22<>"",IF(INDEX(PCCitrus,$N22)="","—",INDEX(PCCitrus,$N22)),"") | F22: =IF($N22<>"",IF(INDEX(PCScale,$N22)=0,"",INDEX(PCScale,$N22)),"") | G22: =IF($N22<>"",IF(INDEX(PCBaskets,$N22)=0,"",INDEX(PCBaskets,$N22)),"") | H22: =IF($N22<>"",IF(INDEX(PCNet,$N22)=0,"",INDEX(PCNet,$N22)),"") | I22: =IF($N22<>"",IF(INDEX(PCOp,$N22)="مرجوعی خرید","",IF(INDEX(PCAmount,$N22)<=0,"",INDEX(PCAmount,$N22))),IF($O22<>"",IF(INDEX(TxnDepB,$O22)=0,"",INDEX(TxnDepB,$O22)),"")) | J22: =IF($N22<>"",IF(INDEX(PCOp,$N22)="مرجوعی خرید",IF(INDEX(PCAmount,$N22)=0,"",-INDEX(PCAmount,$N22)),""),IF($O22<>"",IF(INDEX(TxnWitB,$O22)=0,"",INDEX(TxnWitB,$O22)),"")) | K22: =IF($B22="","",IF($K21="",$C$10,$K21)+IF($I22="",0,$I22)-IF($J22="",0,$J22)) | L22: =IF($N22<>"",IF(INDEX(PCNotes,$N22)="","—",INDEX(PCNotes,$N22)),IF($O22<>"",IF(INDEX(LdgNoteB,$O22)="","—",INDEX(LdgNoteB,$O22)),"")) | N22: =IFERROR(MATCH($C$5&"|"&RIGHT("000000"&6,6),LdgRankKeyA,0),"") | O22: =IFERROR(MATCH($C$5&"|"&RIGHT("000000"&6,6),LdgRankKeyB,0),"")
A23: 7 | B23: =IF(AND($N23="",$O23=""),"",IF($N23<>"",INDEX(PCNormDate,$N23),INDEX(LdgDateB,$O23))) | C23: =IF($N23<>"",INDEX(PCOp,$N23),IF($O23<>"",IF(N(INDEX(TxnDepB,$O23))>0,"دریافت بانکی","پرداخت بانکی"),"")) | D23: =IF($N23<>"",IF(INDEX(PCDoc,$N23)="","—",INDEX(PCDoc,$N23)),IF($O23<>"",INDEX(LdgBankB,$O23),"")) | E23: =IF($N23<>"",IF(INDEX(PCCitrus,$N23)="","—",INDEX(PCCitrus,$N23)),"") | F23: =IF($N23<>"",IF(INDEX(PCScale,$N23)=0,"",INDEX(PCScale,$N23)),"") | G23: =IF($N23<>"",IF(INDEX(PCBaskets,$N23)=0,"",INDEX(PCBaskets,$N23)),"") | H23: =IF($N23<>"",IF(INDEX(PCNet,$N23)=0,"",INDEX(PCNet,$N23)),"") | I23: =IF($N23<>"",IF(INDEX(PCOp,$N23)="مرجوعی خرید","",IF(INDEX(PCAmount,$N23)<=0,"",INDEX(PCAmount,$N23))),IF($O23<>"",IF(INDEX(TxnDepB,$O23)=0,"",INDEX(TxnDepB,$O23)),"")) | J23: =IF($N23<>"",IF(INDEX(PCOp,$N23)="مرجوعی خرید",IF(INDEX(PCAmount,$N23)=0,"",-INDEX(PCAmount,$N23)),""),IF($O23<>"",IF(INDEX(TxnWitB,$O23)=0,"",INDEX(TxnWitB,$O23)),"")) | K23: =IF($B23="","",IF($K22="",$C$10,$K22)+IF($I23="",0,$I23)-IF($J23="",0,$J23)) | L23: =IF($N23<>"",IF(INDEX(PCNotes,$N23)="","—",INDEX(PCNotes,$N23)),IF($O23<>"",IF(INDEX(LdgNoteB,$O23)="","—",INDEX(LdgNoteB,$O23)),"")) | N23: =IFERROR(MATCH($C$5&"|"&RIGHT("000000"&7,6),LdgRankKeyA,0),"") | O23: =IFERROR(MATCH($C$5&"|"&RIGHT("000000"&7,6),LdgRankKeyB,0),"")
A24: 8 | B24: =IF(AND($N24="",$O24=""),"",IF($N24<>"",INDEX(PCNormDate,$N24),INDEX(LdgDateB,$O24))) | C24: =IF($N24<>"",INDEX(PCOp,$N24),IF($O24<>"",IF(N(INDEX(TxnDepB,$O24))>0,"دریافت بانکی","پرداخت بانکی"),"")) | D24: =IF($N24<>"",IF(INDEX(PCDoc,$N24)="","—",INDEX(PCDoc,$N24)),IF($O24<>"",INDEX(LdgBankB,$O24),"")) | E24: =IF($N24<>"",IF(INDEX(PCCitrus,$N24)="","—",INDEX(PCCitrus,$N24)),"") | F24: =IF($N24<>"",IF(INDEX(PCScale,$N24)=0,"",INDEX(PCScale,$N24)),"") | G24: =IF($N24<>"",IF(INDEX(PCBaskets,$N24)=0,"",INDEX(PCBaskets,$N24)),"") | H24: =IF($N24<>"",IF(INDEX(PCNet,$N24)=0,"",INDEX(PCNet,$N24)),"") | I24: =IF($N24<>"",IF(INDEX(PCOp,$N24)="مرجوعی خرید","",IF(INDEX(PCAmount,$N24)<=0,"",INDEX(PCAmount,$N24))),IF($O24<>"",IF(INDEX(TxnDepB,$O24)=0,"",INDEX(TxnDepB,$O24)),"")) | J24: =IF($N24<>"",IF(INDEX(PCOp,$N24)="مرجوعی خرید",IF(INDEX(PCAmount,$N24)=0,"",-INDEX(PCAmount,$N24)),""),IF($O24<>"",IF(INDEX(TxnWitB,$O24)=0,"",INDEX(TxnWitB,$O24)),"")) | K24: =IF($B24="","",IF($K23="",$C$10,$K23)+IF($I24="",0,$I24)-IF($J24="",0,$J24)) | L24: =IF($N24<>"",IF(INDEX(PCNotes,$N24)="","—",INDEX(PCNotes,$N24)),IF($O24<>"",IF(INDEX(LdgNoteB,$O24)="","—",INDEX(LdgNoteB,$O24)),"")) | N24: =IFERROR(MATCH($C$5&"|"&RIGHT("000000"&8,6),LdgRankKeyA,0),"") | O24: =IFERROR(MATCH($C$5&"|"&RIGHT("000000"&8,6),LdgRankKeyB,0),"")
A25: 9 | B25: =IF(AND($N25="",$O25=""),"",IF($N25<>"",INDEX(PCNormDate,$N25),INDEX(LdgDateB,$O25))) | C25: =IF($N25<>"",INDEX(PCOp,$N25),IF($O25<>"",IF(N(INDEX(TxnDepB,$O25))>0,"دریافت بانکی","پرداخت بانکی"),"")) | D25: =IF($N25<>"",IF(INDEX(PCDoc,$N25)="","—",INDEX(PCDoc,$N25)),IF($O25<>"",INDEX(LdgBankB,$O25),"")) | E25: =IF($N25<>"",IF(INDEX(PCCitrus,$N25)="","—",INDEX(PCCitrus,$N25)),"") | F25: =IF($N25<>"",IF(INDEX(PCScale,$N25)=0,"",INDEX(PCScale,$N25)),"") | G25: =IF($N25<>"",IF(INDEX(PCBaskets,$N25)=0,"",INDEX(PCBaskets,$N25)),"") | H25: =IF($N25<>"",IF(INDEX(PCNet,$N25)=0,"",INDEX(PCNet,$N25)),"") | I25: =IF($N25<>"",IF(INDEX(PCOp,$N25)="مرجوعی خرید","",IF(INDEX(PCAmount,$N25)<=0,"",INDEX(PCAmount,$N25))),IF($O25<>"",IF(INDEX(TxnDepB,$O25)=0,"",INDEX(TxnDepB,$O25)),"")) | J25: =IF($N25<>"",IF(INDEX(PCOp,$N25)="مرجوعی خرید",IF(INDEX(PCAmount,$N25)=0,"",-INDEX(PCAmount,$N25)),""),IF($O25<>"",IF(INDEX(TxnWitB,$O25)=0,"",INDEX(TxnWitB,$O25)),"")) | K25: =IF($B25="","",IF($K24="",$C$10,$K24)+IF($I25="",0,$I25)-IF($J25="",0,$J25)) | L25: =IF($N25<>"",IF(INDEX(PCNotes,$N25)="","—",INDEX(PCNotes,$N25)),IF($O25<>"",IF(INDEX(LdgNoteB,$O25)="","—",INDEX(LdgNoteB,$O25)),"")) | N25: =IFERROR(MATCH($C$5&"|"&RIGHT("000000"&9,6),LdgRankKeyA,0),"") | O25: =IFERROR(MATCH($C$5&"|"&RIGHT("000000"&9,6),LdgRankKeyB,0),"")
A26: 10 | B26: =IF(AND($N26="",$O26=""),"",IF($N26<>"",INDEX(PCNormDate,$N26),INDEX(LdgDateB,$O26))) | C26: =IF($N26<>"",INDEX(PCOp,$N26),IF($O26<>"",IF(N(INDEX(TxnDepB,$O26))>0,"دریافت بانکی","پرداخت بانکی"),"")) | D26: =IF($N26<>"",IF(INDEX(PCDoc,$N26)="","—",INDEX(PCDoc,$N26)),IF($O26<>"",INDEX(LdgBankB,$O26),"")) | E26: =IF($N26<>"",IF(INDEX(PCCitrus,$N26)="","—",INDEX(PCCitrus,$N26)),"") | F26: =IF($N26<>"",IF(INDEX(PCScale,$N26)=0,"",INDEX(PCScale,$N26)),"") | G26: =IF($N26<>"",IF(INDEX(PCBaskets,$N26)=0,"",INDEX(PCBaskets,$N26)),"") | H26: =IF($N26<>"",IF(INDEX(PCNet,$N26)=0,"",INDEX(PCNet,$N26)),"") | I26: =IF($N26<>"",IF(INDEX(PCOp,$N26)="مرجوعی خرید","",IF(INDEX(PCAmount,$N26)<=0,"",INDEX(PCAmount,$N26))),IF($O26<>"",IF(INDEX(TxnDepB,$O26)=0,"",INDEX(TxnDepB,$O26)),"")) | J26: =IF($N26<>"",IF(INDEX(PCOp,$N26)="مرجوعی خرید",IF(INDEX(PCAmount,$N26)=0,"",-INDEX(PCAmount,$N26)),""),IF($O26<>"",IF(INDEX(TxnWitB,$O26)=0,"",INDEX(TxnWitB,$O26)),"")) | K26: =IF($B26="","",IF($K25="",$C$10,$K25)+IF($I26="",0,$I26)-IF($J26="",0,$J26)) | L26: =IF($N26<>"",IF(INDEX(PCNotes,$N26)="","—",INDEX(PCNotes,$N26)),IF($O26<>"",IF(INDEX(LdgNoteB,$O26)="","—",INDEX(LdgNoteB,$O26)),"")) | N26: =IFERROR(MATCH($C$5&"|"&RIGHT("000000"&10,6),LdgRankKeyA,0),"") | O26: =IFERROR(MATCH($C$5&"|"&RIGHT("000000"&10,6),LdgRankKeyB,0),"")
A27: 11 | B27: =IF(AND($N27="",$O27=""),"",IF($N27<>"",INDEX(PCNormDate,$N27),INDEX(LdgDateB,$O27))) | C27: =IF($N27<>"",INDEX(PCOp,$N27),IF($O27<>"",IF(N(INDEX(TxnDepB,$O27))>0,"دریافت بانکی","پرداخت بانکی"),"")) | D27: =IF($N27<>"",IF(INDEX(PCDoc,$N27)="","—",INDEX(PCDoc,$N27)),IF($O27<>"",INDEX(LdgBankB,$O27),"")) | E27: =IF($N27<>"",IF(INDEX(PCCitrus,$N27)="","—",INDEX(PCCitrus,$N27)),"") | F27: =IF($N27<>"",IF(INDEX(PCScale,$N27)=0,"",INDEX(PCScale,$N27)),"") | G27: =IF($N27<>"",IF(INDEX(PCBaskets,$N27)=0,"",INDEX(PCBaskets,$N27)),"") | H27: =IF($N27<>"",IF(INDEX(PCNet,$N27)=0,"",INDEX(PCNet,$N27)),"") | I27: =IF($N27<>"",IF(INDEX(PCOp,$N27)="مرجوعی خرید","",IF(INDEX(PCAmount,$N27)<=0,"",INDEX(PCAmount,$N27))),IF($O27<>"",IF(INDEX(TxnDepB,$O27)=0,"",INDEX(TxnDepB,$O27)),"")) | J27: =IF($N27<>"",IF(INDEX(PCOp,$N27)="مرجوعی خرید",IF(INDEX(PCAmount,$N27)=0,"",-INDEX(PCAmount,$N27)),""),IF($O27<>"",IF(INDEX(TxnWitB,$O27)=0,"",INDEX(TxnWitB,$O27)),"")) | K27: =IF($B27="","",IF($K26="",$C$10,$K26)+IF($I27="",0,$I27)-IF($J27="",0,$J27)) | L27: =IF($N27<>"",IF(INDEX(PCNotes,$N27)="","—",INDEX(PCNotes,$N27)),IF($O27<>"",IF(INDEX(LdgNoteB,$O27)="","—",INDEX(LdgNoteB,$O27)),"")) | N27: =IFERROR(MATCH($C$5&"|"&RIGHT("000000"&11,6),LdgRankKeyA,0),"") | O27: =IFERROR(MATCH($C$5&"|"&RIGHT("000000"&11,6),LdgRankKeyB,0),"")
A28: 12 | B28: =IF(AND($N28="",$O28=""),"",IF($N28<>"",INDEX(PCNormDate,$N28),INDEX(LdgDateB,$O28))) | C28: =IF($N28<>"",INDEX(PCOp,$N28),IF($O28<>"",IF(N(INDEX(TxnDepB,$O28))>0,"دریافت بانکی","پرداخت بانکی"),"")) | D28: =IF($N28<>"",IF(INDEX(PCDoc,$N28)="","—",INDEX(PCDoc,$N28)),IF($O28<>"",INDEX(LdgBankB,$O28),"")) | E28: =IF($N28<>"",IF(INDEX(PCCitrus,$N28)="","—",INDEX(PCCitrus,$N28)),"") | F28: =IF($N28<>"",IF(INDEX(PCScale,$N28)=0,"",INDEX(PCScale,$N28)),"") | G28: =IF($N28<>"",IF(INDEX(PCBaskets,$N28)=0,"",INDEX(PCBaskets,$N28)),"") | H28: =IF($N28<>"",IF(INDEX(PCNet,$N28)=0,"",INDEX(PCNet,$N28)),"") | I28: =IF($N28<>"",IF(INDEX(PCOp,$N28)="مرجوعی خرید","",IF(INDEX(PCAmount,$N28)<=0,"",INDEX(PCAmount,$N28))),IF($O28<>"",IF(INDEX(TxnDepB,$O28)=0,"",INDEX(TxnDepB,$O28)),"")) | J28: =IF($N28<>"",IF(INDEX(PCOp,$N28)="مرجوعی خرید",IF(INDEX(PCAmount,$N28)=0,"",-INDEX(PCAmount,$N28)),""),IF($O28<>"",IF(INDEX(TxnWitB,$O28)=0,"",INDEX(TxnWitB,$O28)),"")) | K28: =IF($B28="","",IF($K27="",$C$10,$K27)+IF($I28="",0,$I28)-IF($J28="",0,$J28)) | L28: =IF($N28<>"",IF(INDEX(PCNotes,$N28)="","—",INDEX(PCNotes,$N28)),IF($O28<>"",IF(INDEX(LdgNoteB,$O28)="","—",INDEX(LdgNoteB,$O28)),"")) | N28: =IFERROR(MATCH($C$5&"|"&RIGHT("000000"&12,6),LdgRankKeyA,0),"") | O28: =IFERROR(MATCH($C$5&"|"&RIGHT("000000"&12,6),LdgRankKeyB,0),"")
A29: 13 | B29: =IF(AND($N29="",$O29=""),"",IF($N29<>"",INDEX(PCNormDate,$N29),INDEX(LdgDateB,$O29))) | C29: =IF($N29<>"",INDEX(PCOp,$N29),IF($O29<>"",IF(N(INDEX(TxnDepB,$O29))>0,"دریافت بانکی","پرداخت بانکی"),"")) | D29: =IF($N29<>"",IF(INDEX(PCDoc,$N29)="","—",INDEX(PCDoc,$N29)),IF($O29<>"",INDEX(LdgBankB,$O29),"")) | E29: =IF($N29<>"",IF(INDEX(PCCitrus,$N29)="","—",INDEX(PCCitrus,$N29)),"") | F29: =IF($N29<>"",IF(INDEX(PCScale,$N29)=0,"",INDEX(PCScale,$N29)),"") | G29: =IF($N29<>"",IF(INDEX(PCBaskets,$N29)=0,"",INDEX(PCBaskets,$N29)),"") | H29: =IF($N29<>"",IF(INDEX(PCNet,$N29)=0,"",INDEX(PCNet,$N29)),"") | I29: =IF($N29<>"",IF(INDEX(PCOp,$N29)="مرجوعی خرید","",IF(INDEX(PCAmount,$N29)<=0,"",INDEX(PCAmount,$N29))),IF($O29<>"",IF(INDEX(TxnDepB,$O29)=0,"",INDEX(TxnDepB,$O29)),"")) | J29: =IF($N29<>"",IF(INDEX(PCOp,$N29)="مرجوعی خرید",IF(INDEX(PCAmount,$N29)=0,"",-INDEX(PCAmount,$N29)),""),IF($O29<>"",IF(INDEX(TxnWitB,$O29)=0,"",INDEX(TxnWitB,$O29)),"")) | K29: =IF($B29="","",IF($K28="",$C$10,$K28)+IF($I29="",0,$I29)-IF($J29="",0,$J29)) | L29: =IF($N29<>"",IF(INDEX(PCNotes,$N29)="","—",INDEX(PCNotes,$N29)),IF($O29<>"",IF(INDEX(LdgNoteB,$O29)="","—",INDEX(LdgNoteB,$O29)),"")) | N29: =IFERROR(MATCH($C$5&"|"&RIGHT("000000"&13,6),LdgRankKeyA,0),"") | O29: =IFERROR(MATCH($C$5&"|"&RIGHT("000000"&13,6),LdgRankKeyB,0),"")
A30: 14 | B30: =IF(AND($N30="",$O30=""),"",IF($N30<>"",INDEX(PCNormDate,$N30),INDEX(LdgDateB,$O30))) | C30: =IF($N30<>"",INDEX(PCOp,$N30),IF($O30<>"",IF(N(INDEX(TxnDepB,$O30))>0,"دریافت بانکی","پرداخت بانکی"),"")) | D30: =IF($N30<>"",IF(INDEX(PCDoc,$N30)="","—",INDEX(PCDoc,$N30)),IF($O30<>"",INDEX(LdgBankB,$O30),"")) | E30: =IF($N30<>"",IF(INDEX(PCCitrus,$N30)="","—",INDEX(PCCitrus,$N30)),"") | F30: =IF($N30<>"",IF(INDEX(PCScale,$N30)=0,"",INDEX(PCScale,$N30)),"") | G30: =IF($N30<>"",IF(INDEX(PCBaskets,$N30)=0,"",INDEX(PCBaskets,$N30)),"") | H30: =IF($N30<>"",IF(INDEX(PCNet,$N30)=0,"",INDEX(PCNet,$N30)),"") | I30: =IF($N30<>"",IF(INDEX(PCOp,$N30)="مرجوعی خرید","",IF(INDEX(PCAmount,$N30)<=0,"",INDEX(PCAmount,$N30))),IF($O30<>"",IF(INDEX(TxnDepB,$O30)=0,"",INDEX(TxnDepB,$O30)),"")) | J30: =IF($N30<>"",IF(INDEX(PCOp,$N30)="مرجوعی خرید",IF(INDEX(PCAmount,$N30)=0,"",-INDEX(PCAmount,$N30)),""),IF($O30<>"",IF(INDEX(TxnWitB,$O30)=0,"",INDEX(TxnWitB,$O30)),"")) | K30: =IF($B30="","",IF($K29="",$C$10,$K29)+IF($I30="",0,$I30)-IF($J30="",0,$J30)) | L30: =IF($N30<>"",IF(INDEX(PCNotes,$N30)="","—",INDEX(PCNotes,$N30)),IF($O30<>"",IF(INDEX(LdgNoteB,$O30)="","—",INDEX(LdgNoteB,$O30)),"")) | N30: =IFERROR(MATCH($C$5&"|"&RIGHT("000000"&14,6),LdgRankKeyA,0),"") | O30: =IFERROR(MATCH($C$5&"|"&RIGHT("000000"&14,6),LdgRankKeyB,0),"")
A31: 15 | B31: =IF(AND($N31="",$O31=""),"",IF($N31<>"",INDEX(PCNormDate,$N31),INDEX(LdgDateB,$O31))) | C31: =IF($N31<>"",INDEX(PCOp,$N31),IF($O31<>"",IF(N(INDEX(TxnDepB,$O31))>0,"دریافت بانکی","پرداخت بانکی"),"")) | D31: =IF($N31<>"",IF(INDEX(PCDoc,$N31)="","—",INDEX(PCDoc,$N31)),IF($O31<>"",INDEX(LdgBankB,$O31),"")) | E31: =IF($N31<>"",IF(INDEX(PCCitrus,$N31)="","—",INDEX(PCCitrus,$N31)),"") | F31: =IF($N31<>"",IF(INDEX(PCScale,$N31)=0,"",INDEX(PCScale,$N31)),"") | G31: =IF($N31<>"",IF(INDEX(PCBaskets,$N31)=0,"",INDEX(PCBaskets,$N31)),"") | H31: =IF($N31<>"",IF(INDEX(PCNet,$N31)=0,"",INDEX(PCNet,$N31)),"") | I31: =IF($N31<>"",IF(INDEX(PCOp,$N31)="مرجوعی خرید","",IF(INDEX(PCAmount,$N31)<=0,"",INDEX(PCAmount,$N31))),IF($O31<>"",IF(INDEX(TxnDepB,$O31)=0,"",INDEX(TxnDepB,$O31)),"")) | J31: =IF($N31<>"",IF(INDEX(PCOp,$N31)="مرجوعی خرید",IF(INDEX(PCAmount,$N31)=0,"",-INDEX(PCAmount,$N31)),""),IF($O31<>"",IF(INDEX(TxnWitB,$O31)=0,"",INDEX(TxnWitB,$O31)),"")) | K31: =IF($B31="","",IF($K30="",$C$10,$K30)+IF($I31="",0,$I31)-IF($J31="",0,$J31)) | L31: =IF($N31<>"",IF(INDEX(PCNotes,$N31)="","—",INDEX(PCNotes,$N31)),IF($O31<>"",IF(INDEX(LdgNoteB,$O31)="","—",INDEX(LdgNoteB,$O31)),"")) | N31: =IFERROR(MATCH($C$5&"|"&RIGHT("000000"&15,6),LdgRankKeyA,0),"") | O31: =IFERROR(MATCH($C$5&"|"&RIGHT("000000"&15,6),LdgRankKeyB,0),"")
A32: 16 | B32: =IF(AND($N32="",$O32=""),"",IF($N32<>"",INDEX(PCNormDate,$N32),INDEX(LdgDateB,$O32))) | C32: =IF($N32<>"",INDEX(PCOp,$N32),IF($O32<>"",IF(N(INDEX(TxnDepB,$O32))>0,"دریافت بانکی","پرداخت بانکی"),"")) | D32: =IF($N32<>"",IF(INDEX(PCDoc,$N32)="","—",INDEX(PCDoc,$N32)),IF($O32<>"",INDEX(LdgBankB,$O32),"")) | E32: =IF($N32<>"",IF(INDEX(PCCitrus,$N32)="","—",INDEX(PCCitrus,$N32)),"") | F32: =IF($N32<>"",IF(INDEX(PCScale,$N32)=0,"",INDEX(PCScale,$N32)),"") | G32: =IF($N32<>"",IF(INDEX(PCBaskets,$N32)=0,"",INDEX(PCBaskets,$N32)),"") | H32: =IF($N32<>"",IF(INDEX(PCNet,$N32)=0,"",INDEX(PCNet,$N32)),"") | I32: =IF($N32<>"",IF(INDEX(PCOp,$N32)="مرجوعی خرید","",IF(INDEX(PCAmount,$N32)<=0,"",INDEX(PCAmount,$N32))),IF($O32<>"",IF(INDEX(TxnDepB,$O32)=0,"",INDEX(TxnDepB,$O32)),"")) | J32: =IF($N32<>"",IF(INDEX(PCOp,$N32)="مرجوعی خرید",IF(INDEX(PCAmount,$N32)=0,"",-INDEX(PCAmount,$N32)),""),IF($O32<>"",IF(INDEX(TxnWitB,$O32)=0,"",INDEX(TxnWitB,$O32)),"")) | K32: =IF($B32="","",IF($K31="",$C$10,$K31)+IF($I32="",0,$I32)-IF($J32="",0,$J32)) | L32: =IF($N32<>"",IF(INDEX(PCNotes,$N32)="","—",INDEX(PCNotes,$N32)),IF($O32<>"",IF(INDEX(LdgNoteB,$O32)="","—",INDEX(LdgNoteB,$O32)),"")) | N32: =IFERROR(MATCH($C$5&"|"&RIGHT("000000"&16,6),LdgRankKeyA,0),"") | O32: =IFERROR(MATCH($C$5&"|"&RIGHT("000000"&16,6),LdgRankKeyB,0),"")
A33: 17 | B33: =IF(AND($N33="",$O33=""),"",IF($N33<>"",INDEX(PCNormDate,$N33),INDEX(LdgDateB,$O33))) | C33: =IF($N33<>"",INDEX(PCOp,$N33),IF($O33<>"",IF(N(INDEX(TxnDepB,$O33))>0,"دریافت بانکی","پرداخت بانکی"),"")) | D33: =IF($N33<>"",IF(INDEX(PCDoc,$N33)="","—",INDEX(PCDoc,$N33)),IF($O33<>"",INDEX(LdgBankB,$O33),"")) | E33: =IF($N33<>"",IF(INDEX(PCCitrus,$N33)="","—",INDEX(PCCitrus,$N33)),"") | F33: =IF($N33<>"",IF(INDEX(PCScale,$N33)=0,"",INDEX(PCScale,$N33)),"") | G33: =IF($N33<>"",IF(INDEX(PCBaskets,$N33)=0,"",INDEX(PCBaskets,$N33)),"") | H33: =IF($N33<>"",IF(INDEX(PCNet,$N33)=0,"",INDEX(PCNet,$N33)),"") | I33: =IF($N33<>"",IF(INDEX(PCOp,$N33)="مرجوعی خرید","",IF(INDEX(PCAmount,$N33)<=0,"",INDEX(PCAmount,$N33))),IF($O33<>"",IF(INDEX(TxnDepB,$O33)=0,"",INDEX(TxnDepB,$O33)),"")) | J33: =IF($N33<>"",IF(INDEX(PCOp,$N33)="مرجوعی خرید",IF(INDEX(PCAmount,$N33)=0,"",-INDEX(PCAmount,$N33)),""),IF($O33<>"",IF(INDEX(TxnWitB,$O33)=0,"",INDEX(TxnWitB,$O33)),"")) | K33: =IF($B33="","",IF($K32="",$C$10,$K32)+IF($I33="",0,$I33)-IF($J33="",0,$J33)) | L33: =IF($N33<>"",IF(INDEX(PCNotes,$N33)="","—",INDEX(PCNotes,$N33)),IF($O33<>"",IF(INDEX(LdgNoteB,$O33)="","—",INDEX(LdgNoteB,$O33)),"")) | N33: =IFERROR(MATCH($C$5&"|"&RIGHT("000000"&17,6),LdgRankKeyA,0),"") | O33: =IFERROR(MATCH($C$5&"|"&RIGHT("000000"&17,6),LdgRankKeyB,0),"")
A34: 18 | B34: =IF(AND($N34="",$O34=""),"",IF($N34<>"",INDEX(PCNormDate,$N34),INDEX(LdgDateB,$O34))) | C34: =IF($N34<>"",INDEX(PCOp,$N34),IF($O34<>"",IF(N(INDEX(TxnDepB,$O34))>0,"دریافت بانکی","پرداخت بانکی"),"")) | D34: =IF($N34<>"",IF(INDEX(PCDoc,$N34)="","—",INDEX(PCDoc,$N34)),IF($O34<>"",INDEX(LdgBankB,$O34),"")) | E34: =IF($N34<>"",IF(INDEX(PCCitrus,$N34)="","—",INDEX(PCCitrus,$N34)),"") | F34: =IF($N34<>"",IF(INDEX(PCScale,$N34)=0,"",INDEX(PCScale,$N34)),"") | G34: =IF($N34<>"",IF(INDEX(PCBaskets,$N34)=0,"",INDEX(PCBaskets,$N34)),"") | H34: =IF($N34<>"",IF(INDEX(PCNet,$N34)=0,"",INDEX(PCNet,$N34)),"") | I34: =IF($N34<>"",IF(INDEX(PCOp,$N34)="مرجوعی خرید","",IF(INDEX(PCAmount,$N34)<=0,"",INDEX(PCAmount,$N34))),IF($O34<>"",IF(INDEX(TxnDepB,$O34)=0,"",INDEX(TxnDepB,$O34)),"")) | J34: =IF($N34<>"",IF(INDEX(PCOp,$N34)="مرجوعی خرید",IF(INDEX(PCAmount,$N34)=0,"",-INDEX(PCAmount,$N34)),""),IF($O34<>"",IF(INDEX(TxnWitB,$O34)=0,"",INDEX(TxnWitB,$O34)),"")) | K34: =IF($B34="","",IF($K33="",$C$10,$K33)+IF($I34="",0,$I34)-IF($J34="",0,$J34)) | L34: =IF($N34<>"",IF(INDEX(PCNotes,$N34)="","—",INDEX(PCNotes,$N34)),IF($O34<>"",IF(INDEX(LdgNoteB,$O34)="","—",INDEX(LdgNoteB,$O34)),"")) | N34: =IFERROR(MATCH($C$5&"|"&RIGHT("000000"&18,6),LdgRankKeyA,0),"") | O34: =IFERROR(MATCH($C$5&"|"&RIGHT("000000"&18,6),LdgRankKeyB,0),"")
A35: 19 | B35: =IF(AND($N35="",$O35=""),"",IF($N35<>"",INDEX(PCNormDate,$N35),INDEX(LdgDateB,$O35))) | C35: =IF($N35<>"",INDEX(PCOp,$N35),IF($O35<>"",IF(N(INDEX(TxnDepB,$O35))>0,"دریافت بانکی","پرداخت بانکی"),"")) | D35: =IF($N35<>"",IF(INDEX(PCDoc,$N35)="","—",INDEX(PCDoc,$N35)),IF($O35<>"",INDEX(LdgBankB,$O35),"")) | E35: =IF($N35<>"",IF(INDEX(PCCitrus,$N35)="","—",INDEX(PCCitrus,$N35)),"") | F35: =IF($N35<>"",IF(INDEX(PCScale,$N35)=0,"",INDEX(PCScale,$N35)),"") | G35: =IF($N35<>"",IF(INDEX(PCBaskets,$N35)=0,"",INDEX(PCBaskets,$N35)),"") | H35: =IF($N35<>"",IF(INDEX(PCNet,$N35)=0,"",INDEX(PCNet,$N35)),"") | I35: =IF($N35<>"",IF(INDEX(PCOp,$N35)="مرجوعی خرید","",IF(INDEX(PCAmount,$N35)<=0,"",INDEX(PCAmount,$N35))),IF($O35<>"",IF(INDEX(TxnDepB,$O35)=0,"",INDEX(TxnDepB,$O35)),"")) | J35: =IF($N35<>"",IF(INDEX(PCOp,$N35)="مرجوعی خرید",IF(INDEX(PCAmount,$N35)=0,"",-INDEX(PCAmount,$N35)),""),IF($O35<>"",IF(INDEX(TxnWitB,$O35)=0,"",INDEX(TxnWitB,$O35)),"")) | K35: =IF($B35="","",IF($K34="",$C$10,$K34)+IF($I35="",0,$I35)-IF($J35="",0,$J35)) | L35: =IF($N35<>"",IF(INDEX(PCNotes,$N35)="","—",INDEX(PCNotes,$N35)),IF($O35<>"",IF(INDEX(LdgNoteB,$O35)="","—",INDEX(LdgNoteB,$O35)),"")) | N35: =IFERROR(MATCH($C$5&"|"&RIGHT("000000"&19,6),LdgRankKeyA,0),"") | O35: =IFERROR(MATCH($C$5&"|"&RIGHT("000000"&19,6),LdgRankKeyB,0),"")
A36: 20 | B36: =IF(AND($N36="",$O36=""),"",IF($N36<>"",INDEX(PCNormDate,$N36),INDEX(LdgDateB,$O36))) | C36: =IF($N36<>"",INDEX(PCOp,$N36),IF($O36<>"",IF(N(INDEX(TxnDepB,$O36))>0,"دریافت بانکی","پرداخت بانکی"),"")) | D36: =IF($N36<>"",IF(INDEX(PCDoc,$N36)="","—",INDEX(PCDoc,$N36)),IF($O36<>"",INDEX(LdgBankB,$O36),"")) | E36: =IF($N36<>"",IF(INDEX(PCCitrus,$N36)="","—",INDEX(PCCitrus,$N36)),"") | F36: =IF($N36<>"",IF(INDEX(PCScale,$N36)=0,"",INDEX(PCScale,$N36)),"") | G36: =IF($N36<>"",IF(INDEX(PCBaskets,$N36)=0,"",INDEX(PCBaskets,$N36)),"") | H36: =IF($N36<>"",IF(INDEX(PCNet,$N36)=0,"",INDEX(PCNet,$N36)),"") | I36: =IF($N36<>"",IF(INDEX(PCOp,$N36)="مرجوعی خرید","",IF(INDEX(PCAmount,$N36)<=0,"",INDEX(PCAmount,$N36))),IF($O36<>"",IF(INDEX(TxnDepB,$O36)=0,"",INDEX(TxnDepB,$O36)),"")) | J36: =IF($N36<>"",IF(INDEX(PCOp,$N36)="مرجوعی خرید",IF(INDEX(PCAmount,$N36)=0,"",-INDEX(PCAmount,$N36)),""),IF($O36<>"",IF(INDEX(TxnWitB,$O36)=0,"",INDEX(TxnWitB,$O36)),"")) | K36: =IF($B36="","",IF($K35="",$C$10,$K35)+IF($I36="",0,$I36)-IF($J36="",0,$J36)) | L36: =IF($N36<>"",IF(INDEX(PCNotes,$N36)="","—",INDEX(PCNotes,$N36)),IF($O36<>"",IF(INDEX(LdgNoteB,$O36)="","—",INDEX(LdgNoteB,$O36)),"")) | N36: =IFERROR(MATCH($C$5&"|"&RIGHT("000000"&20,6),LdgRankKeyA,0),"") | O36: =IFERROR(MATCH($C$5&"|"&RIGHT("000000"&20,6),LdgRankKeyB,0),"")
A37: 21 | B37: =IF(AND($N37="",$O37=""),"",IF($N37<>"",INDEX(PCNormDate,$N37),INDEX(LdgDateB,$O37))) | C37: =IF($N37<>"",INDEX(PCOp,$N37),IF($O37<>"",IF(N(INDEX(TxnDepB,$O37))>0,"دریافت بانکی","پرداخت بانکی"),"")) | D37: =IF($N37<>"",IF(INDEX(PCDoc,$N37)="","—",INDEX(PCDoc,$N37)),IF($O37<>"",INDEX(LdgBankB,$O37),"")) | E37: =IF($N37<>"",IF(INDEX(PCCitrus,$N37)="","—",INDEX(PCCitrus,$N37)),"") | F37: =IF($N37<>"",IF(INDEX(PCScale,$N37)=0,"",INDEX(PCScale,$N37)),"") | G37: =IF($N37<>"",IF(INDEX(PCBaskets,$N37)=0,"",INDEX(PCBaskets,$N37)),"") | H37: =IF($N37<>"",IF(INDEX(PCNet,$N37)=0,"",INDEX(PCNet,$N37)),"") | I37: =IF($N37<>"",IF(INDEX(PCOp,$N37)="مرجوعی خرید","",IF(INDEX(PCAmount,$N37)<=0,"",INDEX(PCAmount,$N37))),IF($O37<>"",IF(INDEX(TxnDepB,$O37)=0,"",INDEX(TxnDepB,$O37)),"")) | J37: =IF($N37<>"",IF(INDEX(PCOp,$N37)="مرجوعی خرید",IF(INDEX(PCAmount,$N37)=0,"",-INDEX(PCAmount,$N37)),""),IF($O37<>"",IF(INDEX(TxnWitB,$O37)=0,"",INDEX(TxnWitB,$O37)),"")) | K37: =IF($B37="","",IF($K36="",$C$10,$K36)+IF($I37="",0,$I37)-IF($J37="",0,$J37)) | L37: =IF($N37<>"",IF(INDEX(PCNotes,$N37)="","—",INDEX(PCNotes,$N37)),IF($O37<>"",IF(INDEX(LdgNoteB,$O37)="","—",INDEX(LdgNoteB,$O37)),"")) | N37: =IFERROR(MATCH($C$5&"|"&RIGHT("000000"&21,6),LdgRankKeyA,0),"") | O37: =IFERROR(MATCH($C$5&"|"&RIGHT("000000"&21,6),LdgRankKeyB,0),"")
A38: 22 | B38: =IF(AND($N38="",$O38=""),"",IF($N38<>"",INDEX(PCNormDate,$N38),INDEX(LdgDateB,$O38))) | C38: =IF($N38<>"",INDEX(PCOp,$N38),IF($O38<>"",IF(N(INDEX(TxnDepB,$O38))>0,"دریافت بانکی","پرداخت بانکی"),"")) | D38: =IF($N38<>"",IF(INDEX(PCDoc,$N38)="","—",INDEX(PCDoc,$N38)),IF($O38<>"",INDEX(LdgBankB,$O38),"")) | E38: =IF($N38<>"",IF(INDEX(PCCitrus,$N38)="","—",INDEX(PCCitrus,$N38)),"") | F38: =IF($N38<>"",IF(INDEX(PCScale,$N38)=0,"",INDEX(PCScale,$N38)),"") | G38: =IF($N38<>"",IF(INDEX(PCBaskets,$N38)=0,"",INDEX(PCBaskets,$N38)),"") | H38: =IF($N38<>"",IF(INDEX(PCNet,$N38)=0,"",INDEX(PCNet,$N38)),"") | I38: =IF($N38<>"",IF(INDEX(PCOp,$N38)="مرجوعی خرید","",IF(INDEX(PCAmount,$N38)<=0,"",INDEX(PCAmount,$N38))),IF($O38<>"",IF(INDEX(TxnDepB,$O38)=0,"",INDEX(TxnDepB,$O38)),"")) | J38: =IF($N38<>"",IF(INDEX(PCOp,$N38)="مرجوعی خرید",IF(INDEX(PCAmount,$N38)=0,"",-INDEX(PCAmount,$N38)),""),IF($O38<>"",IF(INDEX(TxnWitB,$O38)=0,"",INDEX(TxnWitB,$O38)),"")) | K38: =IF($B38="","",IF($K37="",$C$10,$K37)+IF($I38="",0,$I38)-IF($J38="",0,$J38)) | L38: =IF($N38<>"",IF(INDEX(PCNotes,$N38)="","—",INDEX(PCNotes,$N38)),IF($O38<>"",IF(INDEX(LdgNoteB,$O38)="","—",INDEX(LdgNoteB,$O38)),"")) | N38: =IFERROR(MATCH($C$5&"|"&RIGHT("000000"&22,6),LdgRankKeyA,0),"") | O38: =IFERROR(MATCH($C$5&"|"&RIGHT("000000"&22,6),LdgRankKeyB,0),"")
A39: 23 | B39: =IF(AND($N39="",$O39=""),"",IF($N39<>"",INDEX(PCNormDate,$N39),INDEX(LdgDateB,$O39))) | C39: =IF($N39<>"",INDEX(PCOp,$N39),IF($O39<>"",IF(N(INDEX(TxnDepB,$O39))>0,"دریافت بانکی","پرداخت بانکی"),"")) | D39: =IF($N39<>"",IF(INDEX(PCDoc,$N39)="","—",INDEX(PCDoc,$N39)),IF($O39<>"",INDEX(LdgBankB,$O39),"")) | E39: =IF($N39<>"",IF(INDEX(PCCitrus,$N39)="","—",INDEX(PCCitrus,$N39)),"") | F39: =IF($N39<>"",IF(INDEX(PCScale,$N39)=0,"",INDEX(PCScale,$N39)),"") | G39: =IF($N39<>"",IF(INDEX(PCBaskets,$N39)=0,"",INDEX(PCBaskets,$N39)),"") | H39: =IF($N39<>"",IF(INDEX(PCNet,$N39)=0,"",INDEX(PCNet,$N39)),"") | I39: =IF($N39<>"",IF(INDEX(PCOp,$N39)="مرجوعی خرید","",IF(INDEX(PCAmount,$N39)<=0,"",INDEX(PCAmount,$N39))),IF($O39<>"",IF(INDEX(TxnDepB,$O39)=0,"",INDEX(TxnDepB,$O39)),"")) | J39: =IF($N39<>"",IF(INDEX(PCOp,$N39)="مرجوعی خرید",IF(INDEX(PCAmount,$N39)=0,"",-INDEX(PCAmount,$N39)),""),IF($O39<>"",IF(INDEX(TxnWitB,$O39)=0,"",INDEX(TxnWitB,$O39)),"")) | K39: =IF($B39="","",IF($K38="",$C$10,$K38)+IF($I39="",0,$I39)-IF($J39="",0,$J39)) | L39: =IF($N39<>"",IF(INDEX(PCNotes,$N39)="","—",INDEX(PCNotes,$N39)),IF($O39<>"",IF(INDEX(LdgNoteB,$O39)="","—",INDEX(LdgNoteB,$O39)),"")) | N39: =IFERROR(MATCH($C$5&"|"&RIGHT("000000"&23,6),LdgRankKeyA,0),"") | O39: =IFERROR(MATCH($C$5&"|"&RIGHT("000000"&23,6),LdgRankKeyB,0),"")
A40: 24 | B40: =IF(AND($N40="",$O40=""),"",IF($N40<>"",INDEX(PCNormDate,$N40),INDEX(LdgDateB,$O40))) | C40: =IF($N40<>"",INDEX(PCOp,$N40),IF($O40<>"",IF(N(INDEX(TxnDepB,$O40))>0,"دریافت بانکی","پرداخت بانکی"),"")) | D40: =IF($N40<>"",IF(INDEX(PCDoc,$N40)="","—",INDEX(PCDoc,$N40)),IF($O40<>"",INDEX(LdgBankB,$O40),"")) | E40: =IF($N40<>"",IF(INDEX(PCCitrus,$N40)="","—",INDEX(PCCitrus,$N40)),"") | F40: =IF($N40<>"",IF(INDEX(PCScale,$N40)=0,"",INDEX(PCScale,$N40)),"") | G40: =IF($N40<>"",IF(INDEX(PCBaskets,$N40)=0,"",INDEX(PCBaskets,$N40)),"") | H40: =IF($N40<>"",IF(INDEX(PCNet,$N40)=0,"",INDEX(PCNet,$N40)),"") | I40: =IF($N40<>"",IF(INDEX(PCOp,$N40)="مرجوعی خرید","",IF(INDEX(PCAmount,$N40)<=0,"",INDEX(PCAmount,$N40))),IF($O40<>"",IF(INDEX(TxnDepB,$O40)=0,"",INDEX(TxnDepB,$O40)),"")) | J40: =IF($N40<>"",IF(INDEX(PCOp,$N40)="مرجوعی خرید",IF(INDEX(PCAmount,$N40)=0,"",-INDEX(PCAmount,$N40)),""),IF($O40<>"",IF(INDEX(TxnWitB,$O40)=0,"",INDEX(TxnWitB,$O40)),"")) | K40: =IF($B40="","",IF($K39="",$C$10,$K39)+IF($I40="",0,$I40)-IF($J40="",0,$J40)) | L40: =IF($N40<>"",IF(INDEX(PCNotes,$N40)="","—",INDEX(PCNotes,$N40)),IF($O40<>"",IF(INDEX(LdgNoteB,$O40)="","—",INDEX(LdgNoteB,$O40)),"")) | N40: =IFERROR(MATCH($C$5&"|"&RIGHT("000000"&24,6),LdgRankKeyA,0),"") | O40: =IFERROR(MATCH($C$5&"|"&RIGHT("000000"&24,6),LdgRankKeyB,0),"")
A41: 25 | B41: =IF(AND($N41="",$O41=""),"",IF($N41<>"",INDEX(PCNormDate,$N41),INDEX(LdgDateB,$O41))) | C41: =IF($N41<>"",INDEX(PCOp,$N41),IF($O41<>"",IF(N(INDEX(TxnDepB,$O41))>0,"دریافت بانکی","پرداخت بانکی"),"")) | D41: =IF($N41<>"",IF(INDEX(PCDoc,$N41)="","—",INDEX(PCDoc,$N41)),IF($O41<>"",INDEX(LdgBankB,$O41),"")) | E41: =IF($N41<>"",IF(INDEX(PCCitrus,$N41)="","—",INDEX(PCCitrus,$N41)),"") | F41: =IF($N41<>"",IF(INDEX(PCScale,$N41)=0,"",INDEX(PCScale,$N41)),"") | G41: =IF($N41<>"",IF(INDEX(PCBaskets,$N41)=0,"",INDEX(PCBaskets,$N41)),"") | H41: =IF($N41<>"",IF(INDEX(PCNet,$N41)=0,"",INDEX(PCNet,$N41)),"") | I41: =IF($N41<>"",IF(INDEX(PCOp,$N41)="مرجوعی خرید","",IF(INDEX(PCAmount,$N41)<=0,"",INDEX(PCAmount,$N41))),IF($O41<>"",IF(INDEX(TxnDepB,$O41)=0,"",INDEX(TxnDepB,$O41)),"")) | J41: =IF($N41<>"",IF(INDEX(PCOp,$N41)="مرجوعی خرید",IF(INDEX(PCAmount,$N41)=0,"",-INDEX(PCAmount,$N41)),""),IF($O41<>"",IF(INDEX(TxnWitB,$O41)=0,"",INDEX(TxnWitB,$O41)),"")) | K41: =IF($B41="","",IF($K40="",$C$10,$K40)+IF($I41="",0,$I41)-IF($J41="",0,$J41)) | L41: =IF($N41<>"",IF(INDEX(PCNotes,$N41)="","—",INDEX(PCNotes,$N41)),IF($O41<>"",IF(INDEX(LdgNoteB,$O41)="","—",INDEX(LdgNoteB,$O41)),"")) | N41: =IFERROR(MATCH($C$5&"|"&RIGHT("000000"&25,6),LdgRankKeyA,0),"") | O41: =IFERROR(MATCH($C$5&"|"&RIGHT("000000"&25,6),LdgRankKeyB,0),"")
...

Sheet Summary
A1: =IF(Sync!$S$6="","مازندشت",Sync!$S$6)&" — "&IF(Sync!$S$9="","سورتینگ و بسته‌بندی مرکبات",Sync!$S$9)
A2: =IF(Sync!$S$7="","باغدشت، بخش مرکزی، شهرستان قائم‌شهر، استان مازندران، ایران",Sync!$S$7)&" | MAZANDASHT · CITRUS SORTING & PACKING"
A3: خلاصه خرید مرکبات به تفکیک حساب — از دفتر باسکول (گروه اصلی: خرید)
A4: ="پارامترها: وزن هر سبد = "&IFERROR(VLOOKUP("P01",ParamTbl,3,0),1.5)&" کیلوگرم | درصد افت (فقط گروه خرید) = "&IFERROR(VLOOKUP("P02",ParamTbl,3,0),1)&"٪ — تعریف و تغییر در INFO ← شیت Params"
A5: تعداد حساب‌های فعال | D5: جمع کل باسکول (kg) | G5: جمع کل سبد | J5: جمع کل خالص (kg)
A6: =NAcctAll | D6: =F570 | G6: =G570 | J6: =H570
A8: ردیف | B8: کد حساب | C8: نام صاحب حساب | D8: نوع حساب | E8: تعداد ورودی | F8: جمع باسکول (kg) | G8: جمع سبد | H8: وزن خالص (kg) | I8: گروه حسابداری | J8: گروه حسابرسی | K8: سهم از خالص
A9: No. | B9: Code | C9: Account Holder | D9: Type | E9: Entries | F9: Scale Total | G9: Baskets Total | H9: Net Weight | I9: Acct Group | J9: Audit Group | K9: Share
A10: =IF(ROW()-9>NAcctAll,"",ROW()-9) | B10: =IF($A10="","",IF($A10<=NAcctAll,INDEX(PkAcctAll,$A10),"")) | C10: =IF($B10="","",IFERROR(IF(VLOOKUP($B10,AcctTbl,4,0)="","(بدون نام)",VLOOKUP($B10,AcctTbl,4,0)),"—")) | D10: =IF($B10="","",IFERROR(IF(VLOOKUP($B10,AcctTbl,3,0)="",IF(VLOOKUP($B10,AcctTbl,2,0)="","—",VLOOKUP($B10,AcctTbl,2,0)),VLOOKUP($B10,AcctTbl,3,0)),"—")) | E10: =IF($B10="","",COUNTIFS(CalcParty,$B10,CalcGroup,"خرید")) | F10: =IF($B10="","",SUMIFS(CalcScale,CalcParty,$B10,CalcGroup,"خرید")) | G10: =IF($B10="","",SUMIFS(CalcBaskets,CalcParty,$B10,CalcGroup,"خرید")) | H10: =IF($B10="","",SUMIFS(CalcNet,CalcParty,$B10,CalcGroup,"خرید")) | I10: =IF($B10="","",IFERROR(IF(VLOOKUP($B10,AcctTbl,5,0)="","—",VLOOKUP($B10,AcctTbl,5,0)),"—")) | J10: =IF($B10="","",IFERROR(IF(VLOOKUP($B10,AcctTbl,6,0)="","—",VLOOKUP($B10,AcctTbl,6,0)),"—")) | K10: =IF(OR($B10="",$H$570=0),"",$H10/$H$570)
A11: =IF(ROW()-9>NAcctAll,"",ROW()-9) | B11: =IF($A11="","",IF($A11<=NAcctAll,INDEX(PkAcctAll,$A11),"")) | C11: =IF($B11="","",IFERROR(IF(VLOOKUP($B11,AcctTbl,4,0)="","(بدون نام)",VLOOKUP($B11,AcctTbl,4,0)),"—")) | D11: =IF($B11="","",IFERROR(IF(VLOOKUP($B11,AcctTbl,3,0)="",IF(VLOOKUP($B11,AcctTbl,2,0)="","—",VLOOKUP($B11,AcctTbl,2,0)),VLOOKUP($B11,AcctTbl,3,0)),"—")) | E11: =IF($B11="","",COUNTIFS(CalcParty,$B11,CalcGroup,"خرید")) | F11: =IF($B11="","",SUMIFS(CalcScale,CalcParty,$B11,CalcGroup,"خرید")) | G11: =IF($B11="","",SUMIFS(CalcBaskets,CalcParty,$B11,CalcGroup,"خرید")) | H11: =IF($B11="","",SUMIFS(CalcNet,CalcParty,$B11,CalcGroup,"خرید")) | I11: =IF($B11="","",IFERROR(IF(VLOOKUP($B11,AcctTbl,5,0)="","—",VLOOKUP($B11,AcctTbl,5,0)),"—")) | J11: =IF($B11="","",IFERROR(IF(VLOOKUP($B11,AcctTbl,6,0)="","—",VLOOKUP($B11,AcctTbl,6,0)),"—")) | K11: =IF(OR($B11="",$H$570=0),"",$H11/$H$570)
A12: =IF(ROW()-9>NAcctAll,"",ROW()-9) | B12: =IF($A12="","",IF($A12<=NAcctAll,INDEX(PkAcctAll,$A12),"")) | C12: =IF($B12="","",IFERROR(IF(VLOOKUP($B12,AcctTbl,4,0)="","(بدون نام)",VLOOKUP($B12,AcctTbl,4,0)),"—")) | D12: =IF($B12="","",IFERROR(IF(VLOOKUP($B12,AcctTbl,3,0)="",IF(VLOOKUP($B12,AcctTbl,2,0)="","—",VLOOKUP($B12,AcctTbl,2,0)),VLOOKUP($B12,AcctTbl,3,0)),"—")) | E12: =IF($B12="","",COUNTIFS(CalcParty,$B12,CalcGroup,"خرید")) | F12: =IF($B12="","",SUMIFS(CalcScale,CalcParty,$B12,CalcGroup,"خرید")) | G12: =IF($B12="","",SUMIFS(CalcBaskets,CalcParty,$B12,CalcGroup,"خرید")) | H12: =IF($B12="","",SUMIFS(CalcNet,CalcParty,$B12,CalcGroup,"خرید")) | I12: =IF($B12="","",IFERROR(IF(VLOOKUP($B12,AcctTbl,5,0)="","—",VLOOKUP($B12,AcctTbl,5,0)),"—")) | J12: =IF($B12="","",IFERROR(IF(VLOOKUP($B12,AcctTbl,6,0)="","—",VLOOKUP($B12,AcctTbl,6,0)),"—")) | K12: =IF(OR($B12="",$H$570=0),"",$H12/$H$570)
A13: =IF(ROW()-9>NAcctAll,"",ROW()-9) | B13: =IF($A13="","",IF($A13<=NAcctAll,INDEX(PkAcctAll,$A13),"")) | C13: =IF($B13="","",IFERROR(IF(VLOOKUP($B13,AcctTbl,4,0)="","(بدون نام)",VLOOKUP($B13,AcctTbl,4,0)),"—")) | D13: =IF($B13="","",IFERROR(IF(VLOOKUP($B13,AcctTbl,3,0)="",IF(VLOOKUP($B13,AcctTbl,2,0)="","—",VLOOKUP($B13,AcctTbl,2,0)),VLOOKUP($B13,AcctTbl,3,0)),"—")) | E13: =IF($B13="","",COUNTIFS(CalcParty,$B13,CalcGroup,"خرید")) | F13: =IF($B13="","",SUMIFS(CalcScale,CalcParty,$B13,CalcGroup,"خرید")) | G13: =IF($B13="","",SUMIFS(CalcBaskets,CalcParty,$B13,CalcGroup,"خرید")) | H13: =IF($B13="","",SUMIFS(CalcNet,CalcParty,$B13,CalcGroup,"خرید")) | I13: =IF($B13="","",IFERROR(IF(VLOOKUP($B13,AcctTbl,5,0)="","—",VLOOKUP($B13,AcctTbl,5,0)),"—")) | J13: =IF($B13="","",IFERROR(IF(VLOOKUP($B13,AcctTbl,6,0)="","—",VLOOKUP($B13,AcctTbl,6,0)),"—")) | K13: =IF(OR($B13="",$H$570=0),"",$H13/$H$570)
A14: =IF(ROW()-9>NAcctAll,"",ROW()-9) | B14: =IF($A14="","",IF($A14<=NAcctAll,INDEX(PkAcctAll,$A14),"")) | C14: =IF($B14="","",IFERROR(IF(VLOOKUP($B14,AcctTbl,4,0)="","(بدون نام)",VLOOKUP($B14,AcctTbl,4,0)),"—")) | D14: =IF($B14="","",IFERROR(IF(VLOOKUP($B14,AcctTbl,3,0)="",IF(VLOOKUP($B14,AcctTbl,2,0)="","—",VLOOKUP($B14,AcctTbl,2,0)),VLOOKUP($B14,AcctTbl,3,0)),"—")) | E14: =IF($B14="","",COUNTIFS(CalcParty,$B14,CalcGroup,"خرید")) | F14: =IF($B14="","",SUMIFS(CalcScale,CalcParty,$B14,CalcGroup,"خرید")) | G14: =IF($B14="","",SUMIFS(CalcBaskets,CalcParty,$B14,CalcGroup,"خرید")) | H14: =IF($B14="","",SUMIFS(CalcNet,CalcParty,$B14,CalcGroup,"خرید")) | I14: =IF($B14="","",IFERROR(IF(VLOOKUP($B14,AcctTbl,5,0)="","—",VLOOKUP($B14,AcctTbl,5,0)),"—")) | J14: =IF($B14="","",IFERROR(IF(VLOOKUP($B14,AcctTbl,6,0)="","—",VLOOKUP($B14,AcctTbl,6,0)),"—")) | K14: =IF(OR($B14="",$H$570=0),"",$H14/$H$570)
A15: =IF(ROW()-9>NAcctAll,"",ROW()-9) | B15: =IF($A15="","",IF($A15<=NAcctAll,INDEX(PkAcctAll,$A15),"")) | C15: =IF($B15="","",IFERROR(IF(VLOOKUP($B15,AcctTbl,4,0)="","(بدون نام)",VLOOKUP($B15,AcctTbl,4,0)),"—")) | D15: =IF($B15="","",IFERROR(IF(VLOOKUP($B15,AcctTbl,3,0)="",IF(VLOOKUP($B15,AcctTbl,2,0)="","—",VLOOKUP($B15,AcctTbl,2,0)),VLOOKUP($B15,AcctTbl,3,0)),"—")) | E15: =IF($B15="","",COUNTIFS(CalcParty,$B15,CalcGroup,"خرید")) | F15: =IF($B15="","",SUMIFS(CalcScale,CalcParty,$B15,CalcGroup,"خرید")) | G15: =IF($B15="","",SUMIFS(CalcBaskets,CalcParty,$B15,CalcGroup,"خرید")) | H15: =IF($B15="","",SUMIFS(CalcNet,CalcParty,$B15,CalcGroup,"خرید")) | I15: =IF($B15="","",IFERROR(IF(VLOOKUP($B15,AcctTbl,5,0)="","—",VLOOKUP($B15,AcctTbl,5,0)),"—")) | J15: =IF($B15="","",IFERROR(IF(VLOOKUP($B15,AcctTbl,6,0)="","—",VLOOKUP($B15,AcctTbl,6,0)),"—")) | K15: =IF(OR($B15="",$H$570=0),"",$H15/$H$570)
A16: =IF(ROW()-9>NAcctAll,"",ROW()-9) | B16: =IF($A16="","",IF($A16<=NAcctAll,INDEX(PkAcctAll,$A16),"")) | C16: =IF($B16="","",IFERROR(IF(VLOOKUP($B16,AcctTbl,4,0)="","(بدون نام)",VLOOKUP($B16,AcctTbl,4,0)),"—")) | D16: =IF($B16="","",IFERROR(IF(VLOOKUP($B16,AcctTbl,3,0)="",IF(VLOOKUP($B16,AcctTbl,2,0)="","—",VLOOKUP($B16,AcctTbl,2,0)),VLOOKUP($B16,AcctTbl,3,0)),"—")) | E16: =IF($B16="","",COUNTIFS(CalcParty,$B16,CalcGroup,"خرید")) | F16: =IF($B16="","",SUMIFS(CalcScale,CalcParty,$B16,CalcGroup,"خرید")) | G16: =IF($B16="","",SUMIFS(CalcBaskets,CalcParty,$B16,CalcGroup,"خرید")) | H16: =IF($B16="","",SUMIFS(CalcNet,CalcParty,$B16,CalcGroup,"خرید")) | I16: =IF($B16="","",IFERROR(IF(VLOOKUP($B16,AcctTbl,5,0)="","—",VLOOKUP($B16,AcctTbl,5,0)),"—")) | J16: =IF($B16="","",IFERROR(IF(VLOOKUP($B16,AcctTbl,6,0)="","—",VLOOKUP($B16,AcctTbl,6,0)),"—")) | K16: =IF(OR($B16="",$H$570=0),"",$H16/$H$570)
A17: =IF(ROW()-9>NAcctAll,"",ROW()-9) | B17: =IF($A17="","",IF($A17<=NAcctAll,INDEX(PkAcctAll,$A17),"")) | C17: =IF($B17="","",IFERROR(IF(VLOOKUP($B17,AcctTbl,4,0)="","(بدون نام)",VLOOKUP($B17,AcctTbl,4,0)),"—")) | D17: =IF($B17="","",IFERROR(IF(VLOOKUP($B17,AcctTbl,3,0)="",IF(VLOOKUP($B17,AcctTbl,2,0)="","—",VLOOKUP($B17,AcctTbl,2,0)),VLOOKUP($B17,AcctTbl,3,0)),"—")) | E17: =IF($B17="","",COUNTIFS(CalcParty,$B17,CalcGroup,"خرید")) | F17: =IF($B17="","",SUMIFS(CalcScale,CalcParty,$B17,CalcGroup,"خرید")) | G17: =IF($B17="","",SUMIFS(CalcBaskets,CalcParty,$B17,CalcGroup,"خرید")) | H17: =IF($B17="","",SUMIFS(CalcNet,CalcParty,$B17,CalcGroup,"خرید")) | I17: =IF($B17="","",IFERROR(IF(VLOOKUP($B17,AcctTbl,5,0)="","—",VLOOKUP($B17,AcctTbl,5,0)),"—")) | J17: =IF($B17="","",IFERROR(IF(VLOOKUP($B17,AcctTbl,6,0)="","—",VLOOKUP($B17,AcctTbl,6,0)),"—")) | K17: =IF(OR($B17="",$H$570=0),"",$H17/$H$570)
A18: =IF(ROW()-9>NAcctAll,"",ROW()-9) | B18: =IF($A18="","",IF($A18<=NAcctAll,INDEX(PkAcctAll,$A18),"")) | C18: =IF($B18="","",IFERROR(IF(VLOOKUP($B18,AcctTbl,4,0)="","(بدون نام)",VLOOKUP($B18,AcctTbl,4,0)),"—")) | D18: =IF($B18="","",IFERROR(IF(VLOOKUP($B18,AcctTbl,3,0)="",IF(VLOOKUP($B18,AcctTbl,2,0)="","—",VLOOKUP($B18,AcctTbl,2,0)),VLOOKUP($B18,AcctTbl,3,0)),"—")) | E18: =IF($B18="","",COUNTIFS(CalcParty,$B18,CalcGroup,"خرید")) | F18: =IF($B18="","",SUMIFS(CalcScale,CalcParty,$B18,CalcGroup,"خرید")) | G18: =IF($B18="","",SUMIFS(CalcBaskets,CalcParty,$B18,CalcGroup,"خرید")) | H18: =IF($B18="","",SUMIFS(CalcNet,CalcParty,$B18,CalcGroup,"خرید")) | I18: =IF($B18="","",IFERROR(IF(VLOOKUP($B18,AcctTbl,5,0)="","—",VLOOKUP($B18,AcctTbl,5,0)),"—")) | J18: =IF($B18="","",IFERROR(IF(VLOOKUP($B18,AcctTbl,6,0)="","—",VLOOKUP($B18,AcctTbl,6,0)),"—")) | K18: =IF(OR($B18="",$H$570=0),"",$H18/$H$570)
A19: =IF(ROW()-9>NAcctAll,"",ROW()-9) | B19: =IF($A19="","",IF($A19<=NAcctAll,INDEX(PkAcctAll,$A19),"")) | C19: =IF($B19="","",IFERROR(IF(VLOOKUP($B19,AcctTbl,4,0)="","(بدون نام)",VLOOKUP($B19,AcctTbl,4,0)),"—")) | D19: =IF($B19="","",IFERROR(IF(VLOOKUP($B19,AcctTbl,3,0)="",IF(VLOOKUP($B19,AcctTbl,2,0)="","—",VLOOKUP($B19,AcctTbl,2,0)),VLOOKUP($B19,AcctTbl,3,0)),"—")) | E19: =IF($B19="","",COUNTIFS(CalcParty,$B19,CalcGroup,"خرید")) | F19: =IF($B19="","",SUMIFS(CalcScale,CalcParty,$B19,CalcGroup,"خرید")) | G19: =IF($B19="","",SUMIFS(CalcBaskets,CalcParty,$B19,CalcGroup,"خرید")) | H19: =IF($B19="","",SUMIFS(CalcNet,CalcParty,$B19,CalcGroup,"خرید")) | I19: =IF($B19="","",IFERROR(IF(VLOOKUP($B19,AcctTbl,5,0)="","—",VLOOKUP($B19,AcctTbl,5,0)),"—")) | J19: =IF($B19="","",IFERROR(IF(VLOOKUP($B19,AcctTbl,6,0)="","—",VLOOKUP($B19,AcctTbl,6,0)),"—")) | K19: =IF(OR($B19="",$H$570=0),"",$H19/$H$570)
A20: =IF(ROW()-9>NAcctAll,"",ROW()-9) | B20: =IF($A20="","",IF($A20<=NAcctAll,INDEX(PkAcctAll,$A20),"")) | C20: =IF($B20="","",IFERROR(IF(VLOOKUP($B20,AcctTbl,4,0)="","(بدون نام)",VLOOKUP($B20,AcctTbl,4,0)),"—")) | D20: =IF($B20="","",IFERROR(IF(VLOOKUP($B20,AcctTbl,3,0)="",IF(VLOOKUP($B20,AcctTbl,2,0)="","—",VLOOKUP($B20,AcctTbl,2,0)),VLOOKUP($B20,AcctTbl,3,0)),"—")) | E20: =IF($B20="","",COUNTIFS(CalcParty,$B20,CalcGroup,"خرید")) | F20: =IF($B20="","",SUMIFS(CalcScale,CalcParty,$B20,CalcGroup,"خرید")) | G20: =IF($B20="","",SUMIFS(CalcBaskets,CalcParty,$B20,CalcGroup,"خرید")) | H20: =IF($B20="","",SUMIFS(CalcNet,CalcParty,$B20,CalcGroup,"خرید")) | I20: =IF($B20="","",IFERROR(IF(VLOOKUP($B20,AcctTbl,5,0)="","—",VLOOKUP($B20,AcctTbl,5,0)),"—")) | J20: =IF($B20="","",IFERROR(IF(VLOOKUP($B20,AcctTbl,6,0)="","—",VLOOKUP($B20,AcctTbl,6,0)),"—")) | K20: =IF(OR($B20="",$H$570=0),"",$H20/$H$570)
A21: =IF(ROW()-9>NAcctAll,"",ROW()-9) | B21: =IF($A21="","",IF($A21<=NAcctAll,INDEX(PkAcctAll,$A21),"")) | C21: =IF($B21="","",IFERROR(IF(VLOOKUP($B21,AcctTbl,4,0)="","(بدون نام)",VLOOKUP($B21,AcctTbl,4,0)),"—")) | D21: =IF($B21="","",IFERROR(IF(VLOOKUP($B21,AcctTbl,3,0)="",IF(VLOOKUP($B21,AcctTbl,2,0)="","—",VLOOKUP($B21,AcctTbl,2,0)),VLOOKUP($B21,AcctTbl,3,0)),"—")) | E21: =IF($B21="","",COUNTIFS(CalcParty,$B21,CalcGroup,"خرید")) | F21: =IF($B21="","",SUMIFS(CalcScale,CalcParty,$B21,CalcGroup,"خرید")) | G21: =IF($B21="","",SUMIFS(CalcBaskets,CalcParty,$B21,CalcGroup,"خرید")) | H21: =IF($B21="","",SUMIFS(CalcNet,CalcParty,$B21,CalcGroup,"خرید")) | I21: =IF($B21="","",IFERROR(IF(VLOOKUP($B21,AcctTbl,5,0)="","—",VLOOKUP($B21,AcctTbl,5,0)),"—")) | J21: =IF($B21="","",IFERROR(IF(VLOOKUP($B21,AcctTbl,6,0)="","—",VLOOKUP($B21,AcctTbl,6,0)),"—")) | K21: =IF(OR($B21="",$H$570=0),"",$H21/$H$570)
... A569: =IF(ROW()-9>NAcctAll,"",ROW()-9) | B569: =IF($A569="","",IF($A569<=NAcctAll,INDEX(PkAcctAll,$A569),"")) | C569: =IF($B569="","",IFERROR(IF(VLOOKUP($B569,AcctTbl,4,0)="","(بدون نام)",VLOOKUP($B569,AcctTbl,4,0)),"—")) | D569: =IF($B569="","",IFERROR(IF(VLOOKUP($B569,AcctTbl,3,0)="",IF(VLOOKUP($B569,AcctTbl,2,0)="","—",VLOOKUP($B569,AcctTbl,2,0)),VLOOKUP($B569,AcctTbl,3,0)),"—")) | E569: =IF($B569="","",COUNTIFS(CalcParty,$B569,CalcGroup,"خرید")) | F569: =IF($B569="","",SUMIFS(CalcScale,CalcParty,$B569,CalcGroup,"خرید")) | G569: =IF($B569="","",SUMIFS(CalcBaskets,CalcParty,$B569,CalcGroup,"خرید")) | H569: =IF($B569="","",SUMIFS(CalcNet,CalcParty,$B569,CalcGroup,"خرید")) | I569: =IF($B569="","",IFERROR(IF(VLOOKUP($B569,AcctTbl,5,0)="","—",VLOOKUP($B569,AcctTbl,5,0)),"—")) | J569: =IF($B569="","",IFERROR(IF(VLOOKUP($B569,AcctTbl,6,0)="","—",VLOOKUP($B569,AcctTbl,6,0)),"—")) | K569: =IF(OR($B569="",$H$570=0),"",$H569/$H$570)
A570: جمع کل | E570: =SUM(E10:E569) | F570: =SUM(F10:F569) | G570: =SUM(G10:G569) | H570: =SUM(H10:H569)

Sheet Sync
A1: مازندشت — سورتینگ و بسته‌بندی مرکبات
A2: باغدشت، بخش مرکزی، شهرستان قائم‌شهر، استان مازندران، ایران | MAZANDASHT · CITRUS SORTING & PACKING
A3: برگه فنی — آینه‌ی فایل مادر (INFO)، دفتر باسکول (Baskol) و فایل واریز/برداشت (Transactions) برای گزارش خرید. فرمول‌ها را تغییر ندهید. اگر همه سلول‌ها خالی شدند یعنی لینک به‌روز نشده: Data ← Edit Links ← Update Values.
A5: Accounts · Code | B5: · Nature | C5: · Subgroup | D5: · Name | E5: · Acct Group | F5: · Audit Group | H5: Ops · Code | I5: · Title | J5: · Direction | K5: · Group | M5: Lists · Citrus Types | O5: Params · Code | P5: · Name | Q5: · Value | S5: Company | U5: Baskol · Date | V5: · Time | W5: · Doc | X5: · Op | Y5: · Party | Z5: · Sub | AA5: · Citrus | AB5: · Scale | AC5: · Baskets | AD5: · Amount | AE5: · Notes | AG5: Txn Entry · C | AH5: Txn Entry · D | AI5: Txn Entry · E | AJ5: Txn Entry · G | AK5: Txn Entry · K | AL5: Txn Entry · L | AM5: Txn Entry · M | AN5: Txn Entry · N | AO5: Txn Entry · R | AQ5: flg | AR5: cum·N | AS5: packed·Acct
A6: =IF([1]Accounts!$D$7="","",[1]Accounts!$A$7) | B6: =IF([1]Accounts!$D$7="","",[1]Accounts!$B$7) | C6: =IF([1]Accounts!$D$7="","",[1]Accounts!$C$7) | D6: =IF([1]Accounts!$D$7="","",[1]Accounts!$D$7) | E6: =IF([1]Accounts!$D$7="","",[1]Accounts!$J$7) | F6: =IF([1]Accounts!$D$7="","",[1]Accounts!$K$7) | H6: =IF([1]Ops!$B$7="","",[1]Ops!$A$7) | I6: =IF([1]Ops!$B$7="","",[1]Ops!$B$7) | J6: =IF([1]Ops!$B$7="","",[1]Ops!$C$7) | K6: =IF([1]Ops!$B$7="","",[1]Ops!$D$7) | M6: =IF([1]Lists!$C$7="","",[1]Lists!$C$7) | O6: =IF([1]Params!$A$7="","",[1]Params!$A$7) | P6: =IF([1]Params!$B$7="","",[1]Params!$B$7) | Q6: =[1]Params!$C$7 | S6: =IF([1]Company!$C$5="","",[1]Company!$C$5) | U6: =IF([2]Baskol!$B$9="","",[2]Baskol!$B$9) | V6: =IF([2]Baskol!$C$9="","",[2]Baskol!$C$9) | W6: =IF([2]Baskol!$D$9="","",[2]Baskol!$D$9) | X6: =IF([2]Baskol!$E$9="","",[2]Baskol!$E$9) | Y6: =IF([2]Baskol!$G$9="","",[2]Baskol!$G$9) | Z6: =IF([2]Baskol!$I$9="","",[2]Baskol!$I$9) | AA6: =IF([2]Baskol!$J$9="","",[2]Baskol!$J$9) | AB6: =IF([2]Baskol!$K$9="","",[2]Baskol!$K$9) | AC6: =IF([2]Baskol!$L$9="","",[2]Baskol!$L$9) | AD6: =IF([2]Baskol!$N$9="","",[2]Baskol!$N$9) | AE6: =IF([2]Baskol!$O$9="","",[2]Baskol!$O$9) | AG6: =IF([3]Entry!$C$9="","",[3]Entry!$C$9) | AH6: =IF([3]Entry!$D$9="","",[3]Entry!$D$9) | AI6: =IF([3]Entry!$E$9="","",[3]Entry!$E$9) | AJ6: =IF([3]Entry!$G$9="","",[3]Entry!$G$9) | AK6: =IF([3]Entry!$K$9="","",[3]Entry!$K$9) | AL6: =IF([3]Entry!$L$9="","",[3]Entry!$L$9) | AM6: =IF([3]Entry!$M$9="","",[3]Entry!$M$9) | AN6: =IF([3]Entry!$N$9="","",[3]Entry!$N$9) | AO6: =IF([3]Entry!$R$9="","",[3]Entry!$R$9) | AQ6: =IF(AND($D6<>"",$A6<>""),1,0) | AR6: =SUM($AQ$6:$AQ6) | AS6: =IFERROR(INDEX($A$6:$A$565,MATCH(ROW()-5,$AR$6:$AR$565,0)),"")
A7: =IF([1]Accounts!$D$8="","",[1]Accounts!$A$8) | B7: =IF([1]Accounts!$D$8="","",[1]Accounts!$B$8) | C7: =IF([1]Accounts!$D$8="","",[1]Accounts!$C$8) | D7: =IF([1]Accounts!$D$8="","",[1]Accounts!$D$8) | E7: =IF([1]Accounts!$D$8="","",[1]Accounts!$J$8) | F7: =IF([1]Accounts!$D$8="","",[1]Accounts!$K$8) | H7: =IF([1]Ops!$B$8="","",[1]Ops!$A$8) | I7: =IF([1]Ops!$B$8="","",[1]Ops!$B$8) | J7: =IF([1]Ops!$B$8="","",[1]Ops!$C$8) | K7: =IF([1]Ops!$B$8="","",[1]Ops!$D$8) | M7: =IF([1]Lists!$C$8="","",[1]Lists!$C$8) | O7: =IF([1]Params!$A$8="","",[1]Params!$A$8) | P7: =IF([1]Params!$B$8="","",[1]Params!$B$8) | Q7: =[1]Params!$C$8 | S7: =IF([1]Company!$C$8="","",[1]Company!$C$8) | U7: =IF([2]Baskol!$B$10="","",[2]Baskol!$B$10) | V7: =IF([2]Baskol!$C$10="","",[2]Baskol!$C$10) | W7: =IF([2]Baskol!$D$10="","",[2]Baskol!$D$10) | X7: =IF([2]Baskol!$E$10="","",[2]Baskol!$E$10) | Y7: =IF([2]Baskol!$G$10="","",[2]Baskol!$G$10) | Z7: =IF([2]Baskol!$I$10="","",[2]Baskol!$I$10) | AA7: =IF([2]Baskol!$J$10="","",[2]Baskol!$J$10) | AB7: =IF([2]Baskol!$K$10="","",[2]Baskol!$K$10) | AC7: =IF([2]Baskol!$L$10="","",[2]Baskol!$L$10) | AD7: =IF([2]Baskol!$N$10="","",[2]Baskol!$N$10) | AE7: =IF([2]Baskol!$O$10="","",[2]Baskol!$O$10) | AG7: =IF([3]Entry!$C$10="","",[3]Entry!$C$10) | AH7: =IF([3]Entry!$D$10="","",[3]Entry!$D$10) | AI7: =IF([3]Entry!$E$10="","",[3]Entry!$E$10) | AJ7: =IF([3]Entry!$G$10="","",[3]Entry!$G$10) | AK7: =IF([3]Entry!$K$10="","",[3]Entry!$K$10) | AL7: =IF([3]Entry!$L$10="","",[3]Entry!$L$10) | AM7: =IF([3]Entry!$M$10="","",[3]Entry!$M$10) | AN7: =IF([3]Entry!$N$10="","",[3]Entry!$N$10) | AO7: =IF([3]Entry!$R$10="","",[3]Entry!$R$10) | AQ7: =IF(AND($D7<>"",$A7<>""),1,0) | AR7: =SUM($AQ$6:$AQ7) | AS7: =IFERROR(INDEX($A$6:$A$565,MATCH(ROW()-5,$AR$6:$AR$565,0)),"")
A8: =IF([1]Accounts!$D$9="","",[1]Accounts!$A$9) | B8: =IF([1]Accounts!$D$9="","",[1]Accounts!$B$9) | C8: =IF([1]Accounts!$D$9="","",[1]Accounts!$C$9) | D8: =IF([1]Accounts!$D$9="","",[1]Accounts!$D$9) | E8: =IF([1]Accounts!$D$9="","",[1]Accounts!$J$9) | F8: =IF([1]Accounts!$D$9="","",[1]Accounts!$K$9) | H8: =IF([1]Ops!$B$9="","",[1]Ops!$A$9) | I8: =IF([1]Ops!$B$9="","",[1]Ops!$B$9) | J8: =IF([1]Ops!$B$9="","",[1]Ops!$C$9) | K8: =IF([1]Ops!$B$9="","",[1]Ops!$D$9) | M8: =IF([1]Lists!$C$9="","",[1]Lists!$C$9) | O8: =IF([1]Params!$A$9="","",[1]Params!$A$9) | P8: =IF([1]Params!$B$9="","",[1]Params!$B$9) | Q8: =[1]Params!$C$9 | S8: =IF([1]Company!$C$9="","",[1]Company!$C$9) | U8: =IF([2]Baskol!$B$11="","",[2]Baskol!$B$11) | V8: =IF([2]Baskol!$C$11="","",[2]Baskol!$C$11) | W8: =IF([2]Baskol!$D$11="","",[2]Baskol!$D$11) | X8: =IF([2]Baskol!$E$11="","",[2]Baskol!$E$11) | Y8: =IF([2]Baskol!$G$11="","",[2]Baskol!$G$11) | Z8: =IF([2]Baskol!$I$11="","",[2]Baskol!$I$11) | AA8: =IF([2]Baskol!$J$11="","",[2]Baskol!$J$11) | AB8: =IF([2]Baskol!$K$11="","",[2]Baskol!$K$11) | AC8: =IF([2]Baskol!$L$11="","",[2]Baskol!$L$11) | AD8: =IF([2]Baskol!$N$11="","",[2]Baskol!$N$11) | AE8: =IF([2]Baskol!$O$11="","",[2]Baskol!$O$11) | AG8: =IF([3]Entry!$C$11="","",[3]Entry!$C$11) | AH8: =IF([3]Entry!$D$11="","",[3]Entry!$D$11) | AI8: =IF([3]Entry!$E$11="","",[3]Entry!$E$11) | AJ8: =IF([3]Entry!$G$11="","",[3]Entry!$G$11) | AK8: =IF([3]Entry!$K$11="","",[3]Entry!$K$11) | AL8: =IF([3]Entry!$L$11="","",[3]Entry!$L$11) | AM8: =IF([3]Entry!$M$11="","",[3]Entry!$M$11) | AN8: =IF([3]Entry!$N$11="","",[3]Entry!$N$11) | AO8: =IF([3]Entry!$R$11="","",[3]Entry!$R$11) | AQ8: =IF(AND($D8<>"",$A8<>""),1,0) | AR8: =SUM($AQ$6:$AQ8) | AS8: =IFERROR(INDEX($A$6:$A$565,MATCH(ROW()-5,$AR$6:$AR$565,0)),"")
A9: =IF([1]Accounts!$D$10="","",[1]Accounts!$A$10) | B9: =IF([1]Accounts!$D$10="","",[1]Accounts!$B$10) | C9: =IF([1]Accounts!$D$10="","",[1]Accounts!$C$10) | D9: =IF([1]Accounts!$D$10="","",[1]Accounts!$D$10) | E9: =IF([1]Accounts!$D$10="","",[1]Accounts!$J$10) | F9: =IF([1]Accounts!$D$10="","",[1]Accounts!$K$10) | H9: =IF([1]Ops!$B$10="","",[1]Ops!$A$10) | I9: =IF([1]Ops!$B$10="","",[1]Ops!$B$10) | J9: =IF([1]Ops!$B$10="","",[1]Ops!$C$10) | K9: =IF([1]Ops!$B$10="","",[1]Ops!$D$10) | M9: =IF([1]Lists!$C$10="","",[1]Lists!$C$10) | O9: =IF([1]Params!$A$10="","",[1]Params!$A$10) | P9: =IF([1]Params!$B$10="","",[1]Params!$B$10) | Q9: =[1]Params!$C$10 | S9: =IF([1]Company!$C$7="","",[1]Company!$C$7) | U9: =IF([2]Baskol!$B$12="","",[2]Baskol!$B$12) | V9: =IF([2]Baskol!$C$12="","",[2]Baskol!$C$12) | W9: =IF([2]Baskol!$D$12="","",[2]Baskol!$D$12) | X9: =IF([2]Baskol!$E$12="","",[2]Baskol!$E$12) | Y9: =IF([2]Baskol!$G$12="","",[2]Baskol!$G$12) | Z9: =IF([2]Baskol!$I$12="","",[2]Baskol!$I$12) | AA9: =IF([2]Baskol!$J$12="","",[2]Baskol!$J$12) | AB9: =IF([2]Baskol!$K$12="","",[2]Baskol!$K$12) | AC9: =IF([2]Baskol!$L$12="","",[2]Baskol!$L$12) | AD9: =IF([2]Baskol!$N$12="","",[2]Baskol!$N$12) | AE9: =IF([2]Baskol!$O$12="","",[2]Baskol!$O$12) | AG9: =IF([3]Entry!$C$12="","",[3]Entry!$C$12) | AH9: =IF([3]Entry!$D$12="","",[3]Entry!$D$12) | AI9: =IF([3]Entry!$E$12="","",[3]Entry!$E$12) | AJ9: =IF([3]Entry!$G$12="","",[3]Entry!$G$12) | AK9: =IF([3]Entry!$K$12="","",[3]Entry!$K$12) | AL9: =IF([3]Entry!$L$12="","",[3]Entry!$L$12) | AM9: =IF([3]Entry!$M$12="","",[3]Entry!$M$12) | AN9: =IF([3]Entry!$N$12="","",[3]Entry!$N$12) | AO9: =IF([3]Entry!$R$12="","",[3]Entry!$R$12) | AQ9: =IF(AND($D9<>"",$A9<>""),1,0) | AR9: =SUM($AQ$6:$AQ9) | AS9: =IFERROR(INDEX($A$6:$A$565,MATCH(ROW()-5,$AR$6:$AR$565,0)),"")
A10: =IF([1]Accounts!$D$11="","",[1]Accounts!$A$11) | B10: =IF([1]Accounts!$D$11="","",[1]Accounts!$B$11) | C10: =IF([1]Accounts!$D$11="","",[1]Accounts!$C$11) | D10: =IF([1]Accounts!$D$11="","",[1]Accounts!$D$11) | E10: =IF([1]Accounts!$D$11="","",[1]Accounts!$J$11) | F10: =IF([1]Accounts!$D$11="","",[1]Accounts!$K$11) | H10: =IF([1]Ops!$B$11="","",[1]Ops!$A$11) | I10: =IF([1]Ops!$B$11="","",[1]Ops!$B$11) | J10: =IF([1]Ops!$B$11="","",[1]Ops!$C$11) | K10: =IF([1]Ops!$B$11="","",[1]Ops!$D$11) | M10: =IF([1]Lists!$C$11="","",[1]Lists!$C$11) | O10: =IF([1]Params!$A$11="","",[1]Params!$A$11) | P10: =IF([1]Params!$B$11="","",[1]Params!$B$11) | Q10: =[1]Params!$C$11 | U10: =IF([2]Baskol!$B$13="","",[2]Baskol!$B$13) | V10: =IF([2]Baskol!$C$13="","",[2]Baskol!$C$13) | W10: =IF([2]Baskol!$D$13="","",[2]Baskol!$D$13) | X10: =IF([2]Baskol!$E$13="","",[2]Baskol!$E$13) | Y10: =IF([2]Baskol!$G$13="","",[2]Baskol!$G$13) | Z10: =IF([2]Baskol!$I$13="","",[2]Baskol!$I$13) | AA10: =IF([2]Baskol!$J$13="","",[2]Baskol!$J$13) | AB10: =IF([2]Baskol!$K$13="","",[2]Baskol!$K$13) | AC10: =IF([2]Baskol!$L$13="","",[2]Baskol!$L$13) | AD10: =IF([2]Baskol!$N$13="","",[2]Baskol!$N$13) | AE10: =IF([2]Baskol!$O$13="","",[2]Baskol!$O$13) | AG10: =IF([3]Entry!$C$13="","",[3]Entry!$C$13) | AH10: =IF([3]Entry!$D$13="","",[3]Entry!$D$13) | AI10: =IF([3]Entry!$E$13="","",[3]Entry!$E$13) | AJ10: =IF([3]Entry!$G$13="","",[3]Entry!$G$13) | AK10: =IF([3]Entry!$K$13="","",[3]Entry!$K$13) | AL10: =IF([3]Entry!$L$13="","",[3]Entry!$L$13) | AM10: =IF([3]Entry!$M$13="","",[3]Entry!$M$13) | AN10: =IF([3]Entry!$N$13="","",[3]Entry!$N$13) | AO10: =IF([3]Entry!$R$13="","",[3]Entry!$R$13) | AQ10: =IF(AND($D10<>"",$A10<>""),1,0) | AR10: =SUM($AQ$6:$AQ10) | AS10: =IFERROR(INDEX($A$6:$A$565,MATCH(ROW()-5,$AR$6:$AR$565,0)),"")
