Workbook
Name AcctTbl: Sync!$A$6:$G$565
Name AcctCodes: Sync!$A$6:$A$565
Name SellerPhone: Sync!$E$6:$E$565
Name SellerMobile: Sync!$F$6:$F$565
Name SellerAddr: Sync!$G$6:$G$565
Name OpTbl: Sync!$J$6:$L$25
Name ParamTbl: Sync!$N$6:$P$17
Name LdgSellerA: Ledger!$A$6:$A$2005
Name LdgKeyA: Ledger!$B$6:$B$2005
Name LdgRankKeyA: Ledger!$D$6:$D$2005
Name LdgSellerB: Ledger!$F$6:$F$2005
Name LdgKeyB: Ledger!$K$6:$K$2005
Name LdgRankKeyB: Ledger!$M$6:$M$2005
Name LdgDateB: Ledger!$J$6:$J$2005
Name LdgDepB: Sync!$AK$6:$AK$2005
Name LdgWitB: Sync!$AL$6:$AL$2005
Name LdgBankB: Sync!$AG$6:$AG$2005
Name LdgNoteB: Sync!$AM$6:$AM$2005
Name SCNormDate: Calc!$E$10:$E$2009
Name SCYM: Calc!$F$10:$F$2009
Name SCSeller: Calc!$G$10:$G$2009
Name SCOp: Calc!$H$10:$H$2009
Name SCSub: Calc!$I$10:$I$2009
Name SCCitrus: Calc!$J$10:$J$2009
Name SCNet: Calc!$M$10:$M$2009
Name SCAmount: Calc!$N$10:$N$2009
Name SCDoc: Calc!$O$10:$O$2009
Name SCNotes: Calc!$P$10:$P$2009
Name SCTime: Calc!$Q$10:$Q$2009

Sheet Report
A1: =IF(Sync!$N$6="","مازندشت",Sync!$N$6)&" — "&IF(Sync!$N$9="","سورتینگ و بسته‌بندی مرکبات",Sync!$N$9)
A2: =IF(Sync!$N$7="","باغدشت، بخش مرکزی، شهرستان قائم‌شهر، استان مازندران، ایران",Sync!$N$7)&" | MAZANDASHT · CITRUS SORTING & PACKING"
A3: ="صورت حساب — "&IFERROR(IF(VLOOKUP($C$5,AcctTbl,4,0)="","(بدون عنوان)",VLOOKUP($C$5,AcctTbl,4,0)),"کد را وارد کنید")
A5: کد حساب (ورود دستی): | C5: SL001 | E5: کد را از فایل INFO (شیت Accounts) وارد کنید — همه‌چیز این شیت خودکار به‌روز می‌شود. برای حساب دیگر، همین شیت را کپی و کد را عوض کنید.
A6: نام صاحب حساب: | C6: =IFERROR(IF(VLOOKUP($C$5,AcctTbl,4,0)="","(بدون عنوان)",VLOOKUP($C$5,AcctTbl,4,0)),"—")
A7: نوع حساب: | C7: =IFERROR(IF(VLOOKUP($C$5,AcctTbl,3,0)="",IF(VLOOKUP($C$5,AcctTbl,2,0)="","—",VLOOKUP($C$5,AcctTbl,2,0)),VLOOKUP($C$5,AcctTbl,3,0)),"—")
A8: تلفن / همراه: | C8: =IFERROR(IF(AND(INDEX(SellerPhone,MATCH($C$5,AcctCodes,0))="",INDEX(SellerMobile,MATCH($C$5,AcctCodes,0))=""),"—",TRIM(INDEX(SellerPhone,MATCH($C$5,AcctCodes,0))&" / "&INDEX(SellerMobile,MATCH($C$5,AcctCodes,0)))),"—")
A9: نشانی: | C9: =IFERROR(IF(INDEX(SellerAddr,MATCH($C$5,AcctCodes,0))="","—",INDEX(SellerAddr,MATCH($C$5,AcctCodes,0))),"—")
A10: مانده اولیه حساب (دستی): | C10: 0 | E10: اگر حساب از قبل مانده دارد اینجا بنویسید (مثبت = بدهکار) — در مانده‌ها اثر می‌گذارد.
A11: جمع بدهکار (ریال) | C11: جمع بستانکار (ریال) | E11: مانده نهایی حساب | G11: ماهیت حساب
A12: =SUM($G$17:$G$2016) | C12: =SUM($H$17:$H$2016) | E12: =IFERROR(LOOKUP(9.99E+307,$I$17:$I$2016),$C$10) | G12: =IF($E$12>0,"▲ بدهکار — به ما بدهکار است",IF($E$12<0,"▼ بستانکار — ما بدهکاریم","= تسویه شده"))
A13: تعداد توزین فروش | C13: تعداد پرداخت بانکی | E13: جمع وزن خالص فروش (kg) | G13: آخرین تراکنش
A14: =COUNTIF($C$17:$C$2016,"فروش")+COUNTIF($C$17:$C$2016,"مرجوعی فروش") | C14: =COUNTIF($C$17:$C$2016,"پرداخت بانکی") | E14: =SUMIF($C$17:$C$2016,"فروش",$F$17:$F$2016)-SUMIF($C$17:$C$2016,"مرجوعی فروش",$F$17:$F$2016) | G14: =IF(COUNT($I$17:$I$2016)=0,"—",INDEX($B$17:$B$2016,COUNT($I$17:$I$2016)))
A15: ردیف | B15: تاریخ | C15: نوع عملیات | D15: مرجع | E15: توضیحات | F15: وزن خالص (kg) | G15: بدهکار (ریال) | H15: بستانکار (ریال) | I15: مانده (ریال)
A16: No. | B16: Date | C16: Type | D16: Ref | E16: Description | F16: Net Weight | G16: Debit | H16: Credit | I16: Balance
A17: 1 | B17: =IF(AND($L17="",$M17=""),"",IF($L17<>"",INDEX(SCNormDate,$L17),INDEX(LdgDateB,$M17))) | C17: =IF($L17<>"",INDEX(SCOp,$L17),IF($M17<>"","پرداخت بانکی","")) | D17: =IF($L17<>"",IF(INDEX(SCDoc,$L17)="","—",INDEX(SCDoc,$L17)),IF($M17<>"",INDEX(LdgBankB,$M17),"")) | E17: =IF($L17<>"",IF(INDEX(SCCitrus,$L17)&INDEX(SCNotes,$L17)="","",IF(INDEX(SCCitrus,$L17)="","",INDEX(SCCitrus,$L17))&IF(INDEX(SCNotes,$L17)="",""," — "&INDEX(SCNotes,$L17))),IF($M17<>"",IF(INDEX(LdgNoteB,$M17)="","—",INDEX(LdgNoteB,$M17)),"")) | F17: =IF($L17<>"",IF(INDEX(SCNet,$L17)=0,"",INDEX(SCNet,$L17)),"") | G17: =IF($L17<>"",IF(INDEX(SCOp,$L17)="مرجوعی فروش","",IF(INDEX(SCAmount,$L17)<=0,"",INDEX(SCAmount,$L17))),IF($M17<>"",IF(INDEX(LdgWitB,$M17)=0,"",INDEX(LdgWitB,$M17)),"")) | H17: =IF($L17<>"",IF(INDEX(SCOp,$L17)="مرجوعی فروش",IF(INDEX(SCAmount,$L17)=0,"",-INDEX(SCAmount,$L17)),""),IF($M17<>"",IF(INDEX(LdgDepB,$M17)=0,"",INDEX(LdgDepB,$M17)),"")) | I17: =IF($B17="","",$C$10+IF($G17="",0,$G17)-IF($H17="",0,$H17)) | L17: =IFERROR(MATCH($C$5&"|"&RIGHT("000000"&1,6),LdgRankKeyA,0),"") | M17: =IFERROR(MATCH($C$5&"|"&RIGHT("000000"&1,6),LdgRankKeyB,0),"")
A18: 2 | B18: =IF(AND($L18="",$M18=""),"",IF($L18<>"",INDEX(SCNormDate,$L18),INDEX(LdgDateB,$M18))) | C18: =IF($L18<>"",INDEX(SCOp,$L18),IF($M18<>"","پرداخت بانکی","")) | D18: =IF($L18<>"",IF(INDEX(SCDoc,$L18)="","—",INDEX(SCDoc,$L18)),IF($M18<>"",INDEX(LdgBankB,$M18),"")) | E18: =IF($L18<>"",IF(INDEX(SCCitrus,$L18)&INDEX(SCNotes,$L18)="","",IF(INDEX(SCCitrus,$L18)="","",INDEX(SCCitrus,$L18))&IF(INDEX(SCNotes,$L18)="",""," — "&INDEX(SCNotes,$L18))),IF($M18<>"",IF(INDEX(LdgNoteB,$M18)="","—",INDEX(LdgNoteB,$M18)),"")) | F18: =IF($L18<>"",IF(INDEX(SCNet,$L18)=0,"",INDEX(SCNet,$L18)),"") | G18: =IF($L18<>"",IF(INDEX(SCOp,$L18)="مرجوعی فروش","",IF(INDEX(SCAmount,$L18)<=0,"",INDEX(SCAmount,$L18))),IF($M18<>"",IF(INDEX(LdgWitB,$M18)=0,"",INDEX(LdgWitB,$M18)),"")) | H18: =IF($L18<>"",IF(INDEX(SCOp,$L18)="مرجوعی فروش",IF(INDEX(SCAmount,$L18)=0,"",-INDEX(SCAmount,$L18)),""),IF($M18<>"",IF(INDEX(LdgDepB,$M18)=0,"",INDEX(LdgDepB,$M18)),"")) | I18: =IF($B18="","",IF($I17="",$C$10,$I17)+IF($G18="",0,$G18)-IF($H18="",0,$H18)) | L18: =IFERROR(MATCH($C$5&"|"&RIGHT("000000"&2,6),LdgRankKeyA,0),"") | M18: =IFERROR(MATCH($C$5&"|"&RIGHT("000000"&2,6),LdgRankKeyB,0),"")
A19: 3 | B19: =IF(AND($L19="",$M19=""),"",IF($L19<>"",INDEX(SCNormDate,$L19),INDEX(LdgDateB,$M19))) | C19: =IF($L19<>"",INDEX(SCOp,$L19),IF($M19<>"","پرداخت بانکی","")) | D19: =IF($L19<>"",IF(INDEX(SCDoc,$L19)="","—",INDEX(SCDoc,$L19)),IF($M19<>"",INDEX(LdgBankB,$M19),"")) | E19: =IF($L19<>"",IF(INDEX(SCCitrus,$L19)&INDEX(SCNotes,$L19)="","",IF(INDEX(SCCitrus,$L19)="","",INDEX(SCCitrus,$L19))&IF(INDEX(SCNotes,$L19)="",""," — "&INDEX(SCNotes,$L19))),IF($M19<>"",IF(INDEX(LdgNoteB,$M19)="","—",INDEX(LdgNoteB,$M19)),"")) | F19: =IF($L19<>"",IF(INDEX(SCNet,$L19)=0,"",INDEX(SCNet,$L19)),"") | G19: =IF($L19<>"",IF(INDEX(SCOp,$L19)="مرجوعی فروش","",IF(INDEX(SCAmount,$L19)<=0,"",INDEX(SCAmount,$L19))),IF($M19<>"",IF(INDEX(LdgWitB,$M19)=0,"",INDEX(LdgWitB,$M19)),"")) | H19: =IF($L19<>"",IF(INDEX(SCOp,$L19)="مرجوعی فروش",IF(INDEX(SCAmount,$L19)=0,"",-INDEX(SCAmount,$L19)),""),IF($M19<>"",IF(INDEX(LdgDepB,$M19)=0,"",INDEX(LdgDepB,$M19)),"")) | I19: =IF($B19="","",IF($I18="",$C$10,$I18)+IF($G19="",0,$G19)-IF($H19="",0,$H19)) | L19: =IFERROR(MATCH($C$5&"|"&RIGHT("000000"&3,6),LdgRankKeyA,0),"") | M19: =IFERROR(MATCH($C$5&"|"&RIGHT("000000"&3,6),LdgRankKeyB,0),"")
A20: 4 | B20: =IF(AND($L20="",$M20=""),"",IF($L20<>"",INDEX(SCNormDate,$L20),INDEX(LdgDateB,$M20))) | C20: =IF($L20<>"",INDEX(SCOp,$L20),IF($M20<>"","پرداخت بانکی","")) | D20: =IF($L20<>"",IF(INDEX(SCDoc,$L20)="","—",INDEX(SCDoc,$L20)),IF($M20<>"",INDEX(LdgBankB,$M20),"")) | E20: =IF($L20<>"",IF(INDEX(SCCitrus,$L20)&INDEX(SCNotes,$L20)="","",IF(INDEX(SCCitrus,$L20)="","",INDEX(SCCitrus,$L20))&IF(INDEX(SCNotes,$L20)="",""," — "&INDEX(SCNotes,$L20))),IF($M20<>"",IF(INDEX(LdgNoteB,$M20)="","—",INDEX(LdgNoteB,$M20)),"")) | F20: =IF($L20<>"",IF(INDEX(SCNet,$L20)=0,"",INDEX(SCNet,$L20)),"") | G20: =IF($L20<>"",IF(INDEX(SCOp,$L20)="مرجوعی فروش","",IF(INDEX(SCAmount,$L20)<=0,"",INDEX(SCAmount,$L20))),IF($M20<>"",IF(INDEX(LdgWitB,$M20)=0,"",INDEX(LdgWitB,$M20)),"")) | H20: =IF($L20<>"",IF(INDEX(SCOp,$L20)="مرجوعی فروش",IF(INDEX(SCAmount,$L20)=0,"",-INDEX(SCAmount,$L20)),""),IF($M20<>"",IF(INDEX(LdgDepB,$M20)=0,"",INDEX(LdgDepB,$M20)),"")) | I20: =IF($B20="","",IF($I19="",$C$10,$I19)+IF($G20="",0,$G20)-IF($H20="",0,$H20)) | L20: =IFERROR(MATCH($C$5&"|"&RIGHT("000000"&4,6),LdgRankKeyA,0),"") | M20: =IFERROR(MATCH($C$5&"|"&RIGHT("000000"&4,6),LdgRankKeyB,0),"")
A21: 5 | B21: =IF(AND($L21="",$M21=""),"",IF($L21<>"",INDEX(SCNormDate,$L21),INDEX(LdgDateB,$M21))) | C21: =IF($L21<>"",INDEX(SCOp,$L21),IF($M21<>"","پرداخت بانکی","")) | D21: =IF($L21<>"",IF(INDEX(SCDoc,$L21)="","—",INDEX(SCDoc,$L21)),IF($M21<>"",INDEX(LdgBankB,$M21),"")) | E21: =IF($L21<>"",IF(INDEX(SCCitrus,$L21)&INDEX(SCNotes,$L21)="","",IF(INDEX(SCCitrus,$L21)="","",INDEX(SCCitrus,$L21))&IF(INDEX(SCNotes,$L21)="",""," — "&INDEX(SCNotes,$L21))),IF($M21<>"",IF(INDEX(LdgNoteB,$M21)="","—",INDEX(LdgNoteB,$M21)),"")) | F21: =IF($L21<>"",IF(INDEX(SCNet,$L21)=0,"",INDEX(SCNet,$L21)),"") | G21: =IF($L21<>"",IF(INDEX(SCOp,$L21)="مرجوعی فروش","",IF(INDEX(SCAmount,$L21)<=0,"",INDEX(SCAmount,$L21))),IF($M21<>"",IF(INDEX(LdgWitB,$M21)=0,"",INDEX(LdgWitB,$M21)),"")) | H21: =IF($L21<>"",IF(INDEX(SCOp,$L21)="مرجوعی فروش",IF(INDEX(SCAmount,$L21)=0,"",-INDEX(SCAmount,$L21)),""),IF($M21<>"",IF(INDEX(LdgDepB,$M21)=0,"",INDEX(LdgDepB,$M21)),"")) | I21: =IF($B21="","",IF($I20="",$C$10,$I20)+IF($G21="",0,$G21)-IF($H21="",0,$H21)) | L21: =IFERROR(MATCH($C$5&"|"&RIGHT("000000"&5,6),LdgRankKeyA,0),"") | M21: =IFERROR(MATCH($C$5&"|"&RIGHT("000000"&5,6),LdgRankKeyB,0),"")
A22: 6 | B22: =IF(AND($L22="",$M22=""),"",IF($L22<>"",INDEX(SCNormDate,$L22),INDEX(LdgDateB,$M22))) | C22: =IF($L22<>"",INDEX(SCOp,$L22),IF($M22<>"","پرداخت بانکی","")) | D22: =IF($L22<>"",IF(INDEX(SCDoc,$L22)="","—",INDEX(SCDoc,$L22)),IF($M22<>"",INDEX(LdgBankB,$M22),"")) | E22: =IF($L22<>"",IF(INDEX(SCCitrus,$L22)&INDEX(SCNotes,$L22)="","",IF(INDEX(SCCitrus,$L22)="","",INDEX(SCCitrus,$L22))&IF(INDEX(SCNotes,$L22)="",""," — "&INDEX(SCNotes,$L22))),IF($M22<>"",IF(INDEX(LdgNoteB,$M22)="","—",INDEX(LdgNoteB,$M22)),"")) | F22: =IF($L22<>"",IF(INDEX(SCNet,$L22)=0,"",INDEX(SCNet,$L22)),"") | G22: =IF($L22<>"",IF(INDEX(SCOp,$L22)="مرجوعی فروش","",IF(INDEX(SCAmount,$L22)<=0,"",INDEX(SCAmount,$L22))),IF($M22<>"",IF(INDEX(LdgWitB,$M22)=0,"",INDEX(LdgWitB,$M22)),"")) | H22: =IF($L22<>"",IF(INDEX(SCOp,$L22)="مرجوعی فروش",IF(INDEX(SCAmount,$L22)=0,"",-INDEX(SCAmount,$L22)),""),IF($M22<>"",IF(INDEX(LdgDepB,$M22)=0,"",INDEX(LdgDepB,$M22)),"")) | I22: =IF($B22="","",IF($I21="",$C$10,$I21)+IF($G22="",0,$G22)-IF($H22="",0,$H22)) | L22: =IFERROR(MATCH($C$5&"|"&RIGHT("000000"&6,6),LdgRankKeyA,0),"") | M22: =IFERROR(MATCH($C$5&"|"&RIGHT("000000"&6,6),LdgRankKeyB,0),"")
A23: 7 | B23: =IF(AND($L23="",$M23=""),"",IF($L23<>"",INDEX(SCNormDate,$L23),INDEX(LdgDateB,$M23))) | C23: =IF($L23<>"",INDEX(SCOp,$L23),IF($M23<>"","پرداخت بانکی","")) | D23: =IF($L23<>"",IF(INDEX(SCDoc,$L23)="","—",INDEX(SCDoc,$L23)),IF($M23<>"",INDEX(LdgBankB,$M23),"")) | E23: =IF($L23<>"",IF(INDEX(SCCitrus,$L23)&INDEX(SCNotes,$L23)="","",IF(INDEX(SCCitrus,$L23)="","",INDEX(SCCitrus,$L23))&IF(INDEX(SCNotes,$L23)="",""," — "&INDEX(SCNotes,$L23))),IF($M23<>"",IF(INDEX(LdgNoteB,$M23)="","—",INDEX(LdgNoteB,$M23)),"")) | F23: =IF($L23<>"",IF(INDEX(SCNet,$L23)=0,"",INDEX(SCNet,$L23)),"") | G23: =IF($L23<>"",IF(INDEX(SCOp,$L23)="مرجوعی فروش","",IF(INDEX(SCAmount,$L23)<=0,"",INDEX(SCAmount,$L23))),IF($M23<>"",IF(INDEX(LdgWitB,$M23)=0,"",INDEX(LdgWitB,$M23)),"")) | H23: =IF($L23<>"",IF(INDEX(SCOp,$L23)="مرجوعی فروش",IF(INDEX(SCAmount,$L23)=0,"",-INDEX(SCAmount,$L23)),""),IF($M23<>"",IF(INDEX(LdgDepB,$M23)=0,"",INDEX(LdgDepB,$M23)),"")) | I23: =IF($B23="","",IF($I22="",$C$10,$I22)+IF($G23="",0,$G23)-IF($H23="",0,$H23)) | L23: =IFERROR(MATCH($C$5&"|"&RIGHT("000000"&7,6),LdgRankKeyA,0),"") | M23: =IFERROR(MATCH($C$5&"|"&RIGHT("000000"&7,6),LdgRankKeyB,0),"")
A24: 8 | B24: =IF(AND($L24="",$M24=""),"",IF($L24<>"",INDEX(SCNormDate,$L24),INDEX(LdgDateB,$M24))) | C24: =IF($L24<>"",INDEX(SCOp,$L24),IF($M24<>"","پرداخت بانکی","")) | D24: =IF($L24<>"",IF(INDEX(SCDoc,$L24)="","—",INDEX(SCDoc,$L24)),IF($M24<>"",INDEX(LdgBankB,$M24),"")) | E24: =IF($L24<>"",IF(INDEX(SCCitrus,$L24)&INDEX(SCNotes,$L24)="","",IF(INDEX(SCCitrus,$L24)="","",INDEX(SCCitrus,$L24))&IF(INDEX(SCNotes,$L24)="",""," — "&INDEX(SCNotes,$L24))),IF($M24<>"",IF(INDEX(LdgNoteB,$M24)="","—",INDEX(LdgNoteB,$M24)),"")) | F24: =IF($L24<>"",IF(INDEX(SCNet,$L24)=0,"",INDEX(SCNet,$L24)),"") | G24: =IF($L24<>"",IF(INDEX(SCOp,$L24)="مرجوعی فروش","",IF(INDEX(SCAmount,$L24)<=0,"",INDEX(SCAmount,$L24))),IF($M24<>"",IF(INDEX(LdgWitB,$M24)=0,"",INDEX(LdgWitB,$M24)),"")) | H24: =IF($L24<>"",IF(INDEX(SCOp,$L24)="مرجوعی فروش",IF(INDEX(SCAmount,$L24)=0,"",-INDEX(SCAmount,$L24)),""),IF($M24<>"",IF(INDEX(LdgDepB,$M24)=0,"",INDEX(LdgDepB,$M24)),"")) | I24: =IF($B24="","",IF($I23="",$C$10,$I23)+IF($G24="",0,$G24)-IF($H24="",0,$H24)) | L24: =IFERROR(MATCH($C$5&"|"&RIGHT("000000"&8,6),LdgRankKeyA,0),"") | M24: =IFERROR(MATCH($C$5&"|"&RIGHT("000000"&8,6),LdgRankKeyB,0),"")
A25: 9 | B25: =IF(AND($L25="",$M25=""),"",IF($L25<>"",INDEX(SCNormDate,$L25),INDEX(LdgDateB,$M25))) | C25: =IF($L25<>"",INDEX(SCOp,$L25),IF($M25<>"","پرداخت بانکی","")) | D25: =IF($L25<>"",IF(INDEX(SCDoc,$L25)="","—",INDEX(SCDoc,$L25)),IF($M25<>"",INDEX(LdgBankB,$M25),"")) | E25: =IF($L25<>"",IF(INDEX(SCCitrus,$L25)&INDEX(SCNotes,$L25)="","",IF(INDEX(SCCitrus,$L25)="","",INDEX(SCCitrus,$L25))&IF(INDEX(SCNotes,$L25)="",""," — "&INDEX(SCNotes,$L25))),IF($M25<>"",IF(INDEX(LdgNoteB,$M25)="","—",INDEX(LdgNoteB,$M25)),"")) | F25: =IF($L25<>"",IF(INDEX(SCNet,$L25)=0,"",INDEX(SCNet,$L25)),"") | G25: =IF($L25<>"",IF(INDEX(SCOp,$L25)="مرجوعی فروش","",IF(INDEX(SCAmount,$L25)<=0,"",INDEX(SCAmount,$L25))),IF($M25<>"",IF(INDEX(LdgWitB,$M25)=0,"",INDEX(LdgWitB,$M25)),"")) | H25: =IF($L25<>"",IF(INDEX(SCOp,$L25)="مرجوعی فروش",IF(INDEX(SCAmount,$L25)=0,"",-INDEX(SCAmount,$L25)),""),IF($M25<>"",IF(INDEX(LdgDepB,$M25)=0,"",INDEX(LdgDepB,$M25)),"")) | I25: =IF($B25="","",IF($I24="",$C$10,$I24)+IF($G25="",0,$G25)-IF($H25="",0,$H25)) | L25: =IFERROR(MATCH($C$5&"|"&RIGHT("000000"&9,6),LdgRankKeyA,0),"") | M25: =IFERROR(MATCH($C$5&"|"&RIGHT("000000"&9,6),LdgRankKeyB,0),"")
A26: 10 | B26: =IF(AND($L26="",$M26=""),"",IF($L26<>"",INDEX(SCNormDate,$L26),INDEX(LdgDateB,$M26))) | C26: =IF($L26<>"",INDEX(SCOp,$L26),IF($M26<>"","پرداخت بانکی","")) | D26: =IF($L26<>"",IF(INDEX(SCDoc,$L26)="","—",INDEX(SCDoc,$L26)),IF($M26<>"",INDEX(LdgBankB,$M26),"")) | E26: =IF($L26<>"",IF(INDEX(SCCitrus,$L26)&INDEX(SCNotes,$L26)="","",IF(INDEX(SCCitrus,$L26)="","",INDEX(SCCitrus,$L26))&IF(INDEX(SCNotes,$L26)="",""," — "&INDEX(SCNotes,$L26))),IF($M26<>"",IF(INDEX(LdgNoteB,$M26)="","—",INDEX(LdgNoteB,$M26)),"")) | F26: =IF($L26<>"",IF(INDEX(SCNet,$L26)=0,"",INDEX(SCNet,$L26)),"") | G26: =IF($L26<>"",IF(INDEX(SCOp,$L26)="مرجوعی فروش","",IF(INDEX(SCAmount,$L26)<=0,"",INDEX(SCAmount,$L26))),IF($M26<>"",IF(INDEX(LdgWitB,$M26)=0,"",INDEX(LdgWitB,$M26)),"")) | H26: =IF($L26<>"",IF(INDEX(SCOp,$L26)="مرجوعی فروش",IF(INDEX(SCAmount,$L26)=0,"",-INDEX(SCAmount,$L26)),""),IF($M26<>"",IF(INDEX(LdgDepB,$M26)=0,"",INDEX(LdgDepB,$M26)),"")) | I26: =IF($B26="","",IF($I25="",$C$10,$I25)+IF($G26="",0,$G26)-IF($H26="",0,$H26)) | L26: =IFERROR(MATCH($C$5&"|"&RIGHT("000000"&10,6),LdgRankKeyA,0),"") | M26: =IFERROR(MATCH($C$5&"|"&RIGHT("000000"&10,6),LdgRankKeyB,0),"")
A27: 11 | B27: =IF(AND($L27="",$M27=""),"",IF($L27<>"",INDEX(SCNormDate,$L27),INDEX(LdgDateB,$M27))) | C27: =IF($L27<>"",INDEX(SCOp,$L27),IF($M27<>"","پرداخت بانکی","")) | D27: =IF($L27<>"",IF(INDEX(SCDoc,$L27)="","—",INDEX(SCDoc,$L27)),IF($M27<>"",INDEX(LdgBankB,$M27),"")) | E27: =IF($L27<>"",IF(INDEX(SCCitrus,$L27)&INDEX(SCNotes,$L27)="","",IF(INDEX(SCCitrus,$L27)="","",INDEX(SCCitrus,$L27))&IF(INDEX(SCNotes,$L27)="",""," — "&INDEX(SCNotes,$L27))),IF($M27<>"",IF(INDEX(LdgNoteB,$M27)="","—",INDEX(LdgNoteB,$M27)),"")) | F27: =IF($L27<>"",IF(INDEX(SCNet,$L27)=0,"",INDEX(SCNet,$L27)),"") | G27: =IF($L27<>"",IF(INDEX(SCOp,$L27)="مرجوعی فروش","",IF(INDEX(SCAmount,$L27)<=0,"",INDEX(SCAmount,$L27))),IF($M27<>"",IF(INDEX(LdgWitB,$M27)=0,"",INDEX(LdgWitB,$M27)),"")) | H27: =IF($L27<>"",IF(INDEX(SCOp,$L27)="مرجوعی فروش",IF(INDEX(SCAmount,$L27)=0,"",-INDEX(SCAmount,$L27)),""),IF($M27<>"",IF(INDEX(LdgDepB,$M27)=0,"",INDEX(LdgDepB,$M27)),"")) | I27: =IF($B27="","",IF($I26="",$C$10,$I26)+IF($G27="",0,$G27)-IF($H27="",0,$H27)) | L27: =IFERROR(MATCH($C$5&"|"&RIGHT("000000"&11,6),LdgRankKeyA,0),"") | M27: =IFERROR(MATCH($C$5&"|"&RIGHT("000000"&11,6),LdgRankKeyB,0),"")
A28: 12 | B28: =IF(AND($L28="",$M28=""),"",IF($L28<>"",INDEX(SCNormDate,$L28),INDEX(LdgDateB,$M28))) | C28: =IF($L28<>"",INDEX(SCOp,$L28),IF($M28<>"","پرداخت بانکی","")) | D28: =IF($L28<>"",IF(INDEX(SCDoc,$L28)="","—",INDEX(SCDoc,$L28)),IF($M28<>"",INDEX(LdgBankB,$M28),"")) | E28: =IF($L28<>"",IF(INDEX(SCCitrus,$L28)&INDEX(SCNotes,$L28)="","",IF(INDEX(SCCitrus,$L28)="","",INDEX(SCCitrus,$L28))&IF(INDEX(SCNotes,$L28)="",""," — "&INDEX(SCNotes,$L28))),IF($M28<>"",IF(INDEX(LdgNoteB,$M28)="","—",INDEX(LdgNoteB,$M28)),"")) | F28: =IF($L28<>"",IF(INDEX(SCNet,$L28)=0,"",INDEX(SCNet,$L28)),"") | G28: =IF($L28<>"",IF(INDEX(SCOp,$L28)="مرجوعی فروش","",IF(INDEX(SCAmount,$L28)<=0,"",INDEX(SCAmount,$L28))),IF($M28<>"",IF(INDEX(LdgWitB,$M28)=0,"",INDEX(LdgWitB,$M28)),"")) | H28: =IF($L28<>"",IF(INDEX(SCOp,$L28)="مرجوعی فروش",IF(INDEX(SCAmount,$L28)=0,"",-INDEX(SCAmount,$L28)),""),IF($M28<>"",IF(INDEX(LdgDepB,$M28)=0,"",INDEX(LdgDepB,$M28)),"")) | I28: =IF($B28="","",IF($I27="",$C$10,$I27)+IF($G28="",0,$G28)-IF($H28="",0,$H28)) | L28: =IFERROR(MATCH($C$5&"|"&RIGHT("000000"&12,6),LdgRankKeyA,0),"") | M28: =IFERROR(MATCH($C$5&"|"&RIGHT("000000"&12,6),LdgRankKeyB,0),"")
A29: 13 | B29: =IF(AND($L29="",$M29=""),"",IF($L29<>"",INDEX(SCNormDate,$L29),INDEX(LdgDateB,$M29))) | C29: =IF($L29<>"",INDEX(SCOp,$L29),IF($M29<>"","پرداخت بانکی","")) | D29: =IF($L29<>"",IF(INDEX(SCDoc,$L29)="","—",INDEX(SCDoc,$L29)),IF($M29<>"",INDEX(LdgBankB,$M29),"")) | E29: =IF($L29<>"",IF(INDEX(SCCitrus,$L29)&INDEX(SCNotes,$L29)="","",IF(INDEX(SCCitrus,$L29)="","",INDEX(SCCitrus,$L29))&IF(INDEX(SCNotes,$L29)="",""," — "&INDEX(SCNotes,$L29))),IF($M29<>"",IF(INDEX(LdgNoteB,$M29)="","—",INDEX(LdgNoteB,$M29)),"")) | F29: =IF($L29<>"",IF(INDEX(SCNet,$L29)=0,"",INDEX(SCNet,$L29)),"") | G29: =IF($L29<>"",IF(INDEX(SCOp,$L29)="مرجوعی فروش","",IF(INDEX(SCAmount,$L29)<=0,"",INDEX(SCAmount,$L29))),IF($M29<>"",IF(INDEX(LdgWitB,$M29)=0,"",INDEX(LdgWitB,$M29)),"")) | H29: =IF($L29<>"",IF(INDEX(SCOp,$L29)="مرجوعی فروش",IF(INDEX(SCAmount,$L29)=0,"",-INDEX(SCAmount,$L29)),""),IF($M29<>"",IF(INDEX(LdgDepB,$M29)=0,"",INDEX(LdgDepB,$M29)),"")) | I29: =IF($B29="","",IF($I28="",$C$10,$I28)+IF($G29="",0,$G29)-IF($H29="",0,$H29)) | L29: =IFERROR(MATCH($C$5&"|"&RIGHT("000000"&13,6),LdgRankKeyA,0),"") | M29: =IFERROR(MATCH($C$5&"|"&RIGHT("000000"&13,6),LdgRankKeyB,0),"")
A30: 14 | B30: =IF(AND($L30="",$M30=""),"",IF($L30<>"",INDEX(SCNormDate,$L30),INDEX(LdgDateB,$M30))) | C30: =IF($L30<>"",INDEX(SCOp,$L30),IF($M30<>"","پرداخت بانکی","")) | D30: =IF($L30<>"",IF(INDEX(SCDoc,$L30)="","—",INDEX(SCDoc,$L30)),IF($M30<>"",INDEX(LdgBankB,$M30),"")) | E30: =IF($L30<>"",IF(INDEX(SCCitrus,$L30)&INDEX(SCNotes,$L30)="","",IF(INDEX(SCCitrus,$L30)="","",INDEX(SCCitrus,$L30))&IF(INDEX(SCNotes,$L30)="",""," — "&INDEX(SCNotes,$L30))),IF($M30<>"",IF(INDEX(LdgNoteB,$M30)="","—",INDEX(LdgNoteB,$M30)),"")) | F30: =IF($L30<>"",IF(INDEX(SCNet,$L30)=0,"",INDEX(SCNet,$L30)),"") | G30: =IF($L30<>"",IF(INDEX(SCOp,$L30)="مرجوعی فروش","",IF(INDEX(SCAmount,$L30)<=0,"",INDEX(SCAmount,$L30))),IF($M30<>"",IF(INDEX(LdgWitB,$M30)=0,"",INDEX(LdgWitB,$M30)),"")) | H30: =IF($L30<>"",IF(INDEX(SCOp,$L30)="مرجوعی فروش",IF(INDEX(SCAmount,$L30)=0,"",-INDEX(SCAmount,$L30)),""),IF($M30<>"",IF(INDEX(LdgDepB,$M30)=0,"",INDEX(LdgDepB,$M30)),"")) | I30: =IF($B30="","",IF($I29="",$C$10,$I29)+IF($G30="",0,$G30)-IF($H30="",0,$H30)) | L30: =IFERROR(MATCH($C$5&"|"&RIGHT("000000"&14,6),LdgRankKeyA,0),"") | M30: =IFERROR(MATCH($C$5&"|"&RIGHT("000000"&14,6),LdgRankKeyB,0),"")
A31: 15 | B31: =IF(AND($L31="",$M31=""),"",IF($L31<>"",INDEX(SCNormDate,$L31),INDEX(LdgDateB,$M31))) | C31: =IF($L31<>"",INDEX(SCOp,$L31),IF($M31<>"","پرداخت بانکی","")) | D31: =IF($L31<>"",IF(INDEX(SCDoc,$L31)="","—",INDEX(SCDoc,$L31)),IF($M31<>"",INDEX(LdgBankB,$M31),"")) | E31: =IF($L31<>"",IF(INDEX(SCCitrus,$L31)&INDEX(SCNotes,$L31)="","",IF(INDEX(SCCitrus,$L31)="","",INDEX(SCCitrus,$L31))&IF(INDEX(SCNotes,$L31)="",""," — "&INDEX(SCNotes,$L31))),IF($M31<>"",IF(INDEX(LdgNoteB,$M31)="","—",INDEX(LdgNoteB,$M31)),"")) | F31: =IF($L31<>"",IF(INDEX(SCNet,$L31)=0,"",INDEX(SCNet,$L31)),"") | G31: =IF($L31<>"",IF(INDEX(SCOp,$L31)="مرجوعی فروش","",IF(INDEX(SCAmount,$L31)<=0,"",INDEX(SCAmount,$L31))),IF($M31<>"",IF(INDEX(LdgWitB,$M31)=0,"",INDEX(LdgWitB,$M31)),"")) | H31: =IF($L31<>"",IF(INDEX(SCOp,$L31)="مرجوعی فروش",IF(INDEX(SCAmount,$L31)=0,"",-INDEX(SCAmount,$L31)),""),IF($M31<>"",IF(INDEX(LdgDepB,$M31)=0,"",INDEX(LdgDepB,$M31)),"")) | I31: =IF($B31="","",IF($I30="",$C$10,$I30)+IF($G31="",0,$G31)-IF($H31="",0,$H31)) | L31: =IFERROR(MATCH($C$5&"|"&RIGHT("000000"&15,6),LdgRankKeyA,0),"") | M31: =IFERROR(MATCH($C$5&"|"&RIGHT("000000"&15,6),LdgRankKeyB,0),"")
A32: 16 | B32: =IF(AND($L32="",$M32=""),"",IF($L32<>"",INDEX(SCNormDate,$L32),INDEX(LdgDateB,$M32))) | C32: =IF($L32<>"",INDEX(SCOp,$L32),IF($M32<>"","پرداخت بانکی","")) | D32: =IF($L32<>"",IF(INDEX(SCDoc,$L32)="","—",INDEX(SCDoc,$L32)),IF($M32<>"",INDEX(LdgBankB,$M32),"")) | E32: =IF($L32<>"",IF(INDEX(SCCitrus,$L32)&INDEX(SCNotes,$L32)="","",IF(INDEX(SCCitrus,$L32)="","",INDEX(SCCitrus,$L32))&IF(INDEX(SCNotes,$L32)="",""," — "&INDEX(SCNotes,$L32))),IF($M32<>"",IF(INDEX(LdgNoteB,$M32)="","—",INDEX(LdgNoteB,$M32)),"")) | F32: =IF($L32<>"",IF(INDEX(SCNet,$L32)=0,"",INDEX(SCNet,$L32)),"") | G32: =IF($L32<>"",IF(INDEX(SCOp,$L32)="مرجوعی فروش","",IF(INDEX(SCAmount,$L32)<=0,"",INDEX(SCAmount,$L32))),IF($M32<>"",IF(INDEX(LdgWitB,$M32)=0,"",INDEX(LdgWitB,$M32)),"")) | H32: =IF($L32<>"",IF(INDEX(SCOp,$L32)="مرجوعی فروش",IF(INDEX(SCAmount,$L32)=0,"",-INDEX(SCAmount,$L32)),""),IF($M32<>"",IF(INDEX(LdgDepB,$M32)=0,"",INDEX(LdgDepB,$M32)),"")) | I32: =IF($B32="","",IF($I31="",$C$10,$I31)+IF($G32="",0,$G32)-IF($H32="",0,$H32)) | L32: =IFERROR(MATCH($C$5&"|"&RIGHT("000000"&16,6),LdgRankKeyA,0),"") | M32: =IFERROR(MATCH($C$5&"|"&RIGHT("000000"&16,6),LdgRankKeyB,0),"")
A33: 17 | B33: =IF(AND($L33="",$M33=""),"",IF($L33<>"",INDEX(SCNormDate,$L33),INDEX(LdgDateB,$M33))) | C33: =IF($L33<>"",INDEX(SCOp,$L33),IF($M33<>"","پرداخت بانکی","")) | D33: =IF($L33<>"",IF(INDEX(SCDoc,$L33)="","—",INDEX(SCDoc,$L33)),IF($M33<>"",INDEX(LdgBankB,$M33),"")) | E33: =IF($L33<>"",IF(INDEX(SCCitrus,$L33)&INDEX(SCNotes,$L33)="","",IF(INDEX(SCCitrus,$L33)="","",INDEX(SCCitrus,$L33))&IF(INDEX(SCNotes,$L33)="",""," — "&INDEX(SCNotes,$L33))),IF($M33<>"",IF(INDEX(LdgNoteB,$M33)="","—",INDEX(LdgNoteB,$M33)),"")) | F33: =IF($L33<>"",IF(INDEX(SCNet,$L33)=0,"",INDEX(SCNet,$L33)),"") | G33: =IF($L33<>"",IF(INDEX(SCOp,$L33)="مرجوعی فروش","",IF(INDEX(SCAmount,$L33)<=0,"",INDEX(SCAmount,$L33))),IF($M33<>"",IF(INDEX(LdgWitB,$M33)=0,"",INDEX(LdgWitB,$M33)),"")) | H33: =IF($L33<>"",IF(INDEX(SCOp,$L33)="مرجوعی فروش",IF(INDEX(SCAmount,$L33)=0,"",-INDEX(SCAmount,$L33)),""),IF($M33<>"",IF(INDEX(LdgDepB,$M33)=0,"",INDEX(LdgDepB,$M33)),"")) | I33: =IF($B33="","",IF($I32="",$C$10,$I32)+IF($G33="",0,$G33)-IF($H33="",0,$H33)) | L33: =IFERROR(MATCH($C$5&"|"&RIGHT("000000"&17,6),LdgRankKeyA,0),"") | M33: =IFERROR(MATCH($C$5&"|"&RIGHT("000000"&17,6),LdgRankKeyB,0),"")
A34: 18 | B34: =IF(AND($L34="",$M34=""),"",IF($L34<>"",INDEX(SCNormDate,$L34),INDEX(LdgDateB,$M34))) | C34: =IF($L34<>"",INDEX(SCOp,$L34),IF($M34<>"","پرداخت بانکی","")) | D34: =IF($L34<>"",IF(INDEX(SCDoc,$L34)="","—",INDEX(SCDoc,$L34)),IF($M34<>"",INDEX(LdgBankB,$M34),"")) | E34: =IF($L34<>"",IF(INDEX(SCCitrus,$L34)&INDEX(SCNotes,$L34)="","",IF(INDEX(SCCitrus,$L34)="","",INDEX(SCCitrus,$L34))&IF(INDEX(SCNotes,$L34)="",""," — "&INDEX(SCNotes,$L34))),IF($M34<>"",IF(INDEX(LdgNoteB,$M34)="","—",INDEX(LdgNoteB,$M34)),"")) | F34: =IF($L34<>"",IF(INDEX(SCNet,$L34)=0,"",INDEX(SCNet,$L34)),"") | G34: =IF($L34<>"",IF(INDEX(SCOp,$L34)="مرجوعی فروش","",IF(INDEX(SCAmount,$L34)<=0,"",INDEX(SCAmount,$L34))),IF($M34<>"",IF(INDEX(LdgWitB,$M34)=0,"",INDEX(LdgWitB,$M34)),"")) | H34: =IF($L34<>"",IF(INDEX(SCOp,$L34)="مرجوعی فروش",IF(INDEX(SCAmount,$L34)=0,"",-INDEX(SCAmount,$L34)),""),IF($M34<>"",IF(INDEX(LdgDepB,$M34)=0,"",INDEX(LdgDepB,$M34)),"")) | I34: =IF($B34="","",IF($I33="",$C$10,$I33)+IF($G34="",0,$G34)-IF($H34="",0,$H34)) | L34: =IFERROR(MATCH($C$5&"|"&RIGHT("000000"&18,6),LdgRankKeyA,0),"") | M34: =IFERROR(MATCH($C$5&"|"&RIGHT("000000"&18,6),LdgRankKeyB,0),"")
A35: 19 | B35: =IF(AND($L35="",$M35=""),"",IF($L35<>"",INDEX(SCNormDate,$L35),INDEX(LdgDateB,$M35))) | C35: =IF($L35<>"",INDEX(SCOp,$L35),IF($M35<>"","پرداخت بانکی","")) | D35: =IF($L35<>"",IF(INDEX(SCDoc,$L35)="","—",INDEX(SCDoc,$L35)),IF($M35<>"",INDEX(LdgBankB,$M35),"")) | E35: =IF($L35<>"",IF(INDEX(SCCitrus,$L35)&INDEX(SCNotes,$L35)="","",IF(INDEX(SCCitrus,$L35)="","",INDEX(SCCitrus,$L35))&IF(INDEX(SCNotes,$L35)="",""," — "&INDEX(SCNotes,$L35))),IF($M35<>"",IF(INDEX(LdgNoteB,$M35)="","—",INDEX(LdgNoteB,$M35)),"")) | F35: =IF($L35<>"",IF(INDEX(SCNet,$L35)=0,"",INDEX(SCNet,$L35)),"") | G35: =IF($L35<>"",IF(INDEX(SCOp,$L35)="مرجوعی فروش","",IF(INDEX(SCAmount,$L35)<=0,"",INDEX(SCAmount,$L35))),IF($M35<>"",IF(INDEX(LdgWitB,$M35)=0,"",INDEX(LdgWitB,$M35)),"")) | H35: =IF($L35<>"",IF(INDEX(SCOp,$L35)="مرجوعی فروش",IF(INDEX(SCAmount,$L35)=0,"",-INDEX(SCAmount,$L35)),""),IF($M35<>"",IF(INDEX(LdgDepB,$M35)=0,"",INDEX(LdgDepB,$M35)),"")) | I35: =IF($B35="","",IF($I34="",$C$10,$I34)+IF($G35="",0,$G35)-IF($H35="",0,$H35)) | L35: =IFERROR(MATCH($C$5&"|"&RIGHT("000000"&19,6),LdgRankKeyA,0),"") | M35: =IFERROR(MATCH($C$5&"|"&RIGHT("000000"&19,6),LdgRankKeyB,0),"")
A36: 20 | B36: =IF(AND($L36="",$M36=""),"",IF($L36<>"",INDEX(SCNormDate,$L36),INDEX(LdgDateB,$M36))) | C36: =IF($L36<>"",INDEX(SCOp,$L36),IF($M36<>"","پرداخت بانکی","")) | D36: =IF($L36<>"",IF(INDEX(SCDoc,$L36)="","—",INDEX(SCDoc,$L36)),IF($M36<>"",INDEX(LdgBankB,$M36),"")) | E36: =IF($L36<>"",IF(INDEX(SCCitrus,$L36)&INDEX(SCNotes,$L36)="","",IF(INDEX(SCCitrus,$L36)="","",INDEX(SCCitrus,$L36))&IF(INDEX(SCNotes,$L36)="",""," — "&INDEX(SCNotes,$L36))),IF($M36<>"",IF(INDEX(LdgNoteB,$M36)="","—",INDEX(LdgNoteB,$M36)),"")) | F36: =IF($L36<>"",IF(INDEX(SCNet,$L36)=0,"",INDEX(SCNet,$L36)),"") | G36: =IF($L36<>"",IF(INDEX(SCOp,$L36)="مرجوعی فروش","",IF(INDEX(SCAmount,$L36)<=0,"",INDEX(SCAmount,$L36))),IF($M36<>"",IF(INDEX(LdgWitB,$M36)=0,"",INDEX(LdgWitB,$M36)),"")) | H36: =IF($L36<>"",IF(INDEX(SCOp,$L36)="مرجوعی فروش",IF(INDEX(SCAmount,$L36)=0,"",-INDEX(SCAmount,$L36)),""),IF($M36<>"",IF(INDEX(LdgDepB,$M36)=0,"",INDEX(LdgDepB,$M36)),"")) | I36: =IF($B36="","",IF($I35="",$C$10,$I35)+IF($G36="",0,$G36)-IF($H36="",0,$H36)) | L36: =IFERROR(MATCH($C$5&"|"&RIGHT("000000"&20,6),LdgRankKeyA,0),"") | M36: =IFERROR(MATCH($C$5&"|"&RIGHT("000000"&20,6),LdgRankKeyB,0),"")
A37: 21 | B37: =IF(AND($L37="",$M37=""),"",IF($L37<>"",INDEX(SCNormDate,$L37),INDEX(LdgDateB,$M37))) | C37: =IF($L37<>"",INDEX(SCOp,$L37),IF($M37<>"","پرداخت بانکی","")) | D37: =IF($L37<>"",IF(INDEX(SCDoc,$L37)="","—",INDEX(SCDoc,$L37)),IF($M37<>"",INDEX(LdgBankB,$M37),"")) | E37: =IF($L37<>"",IF(INDEX(SCCitrus,$L37)&INDEX(SCNotes,$L37)="","",IF(INDEX(SCCitrus,$L37)="","",INDEX(SCCitrus,$L37))&IF(INDEX(SCNotes,$L37)="",""," — "&INDEX(SCNotes,$L37))),IF($M37<>"",IF(INDEX(LdgNoteB,$M37)="","—",INDEX(LdgNoteB,$M37)),"")) | F37: =IF($L37<>"",IF(INDEX(SCNet,$L37)=0,"",INDEX(SCNet,$L37)),"") | G37: =IF($L37<>"",IF(INDEX(SCOp,$L37)="مرجوعی فروش","",IF(INDEX(SCAmount,$L37)<=0,"",INDEX(SCAmount,$L37))),IF($M37<>"",IF(INDEX(LdgWitB,$M37)=0,"",INDEX(LdgWitB,$M37)),"")) | H37: =IF($L37<>"",IF(INDEX(SCOp,$L37)="مرجوعی فروش",IF(INDEX(SCAmount,$L37)=0,"",-INDEX(SCAmount,$L37)),""),IF($M37<>"",IF(INDEX(LdgDepB,$M37)=0,"",INDEX(LdgDepB,$M37)),"")) | I37: =IF($B37="","",IF($I36="",$C$10,$I36)+IF($G37="",0,$G37)-IF($H37="",0,$H37)) | L37: =IFERROR(MATCH($C$5&"|"&RIGHT("000000"&21,6),LdgRankKeyA,0),"") | M37: =IFERROR(MATCH($C$5&"|"&RIGHT("000000"&21,6),LdgRankKeyB,0),"")
A38: 22 | B38: =IF(AND($L38="",$M38=""),"",IF($L38<>"",INDEX(SCNormDate,$L38),INDEX(LdgDateB,$M38))) | C38: =IF($L38<>"",INDEX(SCOp,$L38),IF($M38<>"","پرداخت بانکی","")) | D38: =IF($L38<>"",IF(INDEX(SCDoc,$L38)="","—",INDEX(SCDoc,$L38)),IF($M38<>"",INDEX(LdgBankB,$M38),"")) | E38: =IF($L38<>"",IF(INDEX(SCCitrus,$L38)&INDEX(SCNotes,$L38)="","",IF(INDEX(SCCitrus,$L38)="","",INDEX(SCCitrus,$L38))&IF(INDEX(SCNotes,$L38)="",""," — "&INDEX(SCNotes,$L38))),IF($M38<>"",IF(INDEX(LdgNoteB,$M38)="","—",INDEX(LdgNoteB,$M38)),"")) | F38: =IF($L38<>"",IF(INDEX(SCNet,$L38)=0,"",INDEX(SCNet,$L38)),"") | G38: =IF($L38<>"",IF(INDEX(SCOp,$L38)="مرجوعی فروش","",IF(INDEX(SCAmount,$L38)<=0,"",INDEX(SCAmount,$L38))),IF($M38<>"",IF(INDEX(LdgWitB,$M38)=0,"",INDEX(LdgWitB,$M38)),"")) | H38: =IF($L38<>"",IF(INDEX(SCOp,$L38)="مرجوعی فروش",IF(INDEX(SCAmount,$L38)=0,"",-INDEX(SCAmount,$L38)),""),IF($M38<>"",IF(INDEX(LdgDepB,$M38)=0,"",INDEX(LdgDepB,$M38)),"")) | I38: =IF($B38="","",IF($I37="",$C$10,$I37)+IF($G38="",0,$G38)-IF($H38="",0,$H38)) | L38: =IFERROR(MATCH($C$5&"|"&RIGHT("000000"&22,6),LdgRankKeyA,0),"") | M38: =IFERROR(MATCH($C$5&"|"&RIGHT("000000"&22,6),LdgRankKeyB,0),"")
A39: 23 | B39: =IF(AND($L39="",$M39=""),"",IF($L39<>"",INDEX(SCNormDate,$L39),INDEX(LdgDateB,$M39))) | C39: =IF($L39<>"",INDEX(SCOp,$L39),IF($M39<>"","پرداخت بانکی","")) | D39: =IF($L39<>"",IF(INDEX(SCDoc,$L39)="","—",INDEX(SCDoc,$L39)),IF($M39<>"",INDEX(LdgBankB,$M39),"")) | E39: =IF($L39<>"",IF(INDEX(SCCitrus,$L39)&INDEX(SCNotes,$L39)="","",IF(INDEX(SCCitrus,$L39)="","",INDEX(SCCitrus,$L39))&IF(INDEX(SCNotes,$L39)="",""," — "&INDEX(SCNotes,$L39))),IF($M39<>"",IF(INDEX(LdgNoteB,$M39)="","—",INDEX(LdgNoteB,$M39)),"")) | F39: =IF($L39<>"",IF(INDEX(SCNet,$L39)=0,"",INDEX(SCNet,$L39)),"") | G39: =IF($L39<>"",IF(INDEX(SCOp,$L39)="مرجوعی فروش","",IF(INDEX(SCAmount,$L39)<=0,"",INDEX(SCAmount,$L39))),IF($M39<>"",IF(INDEX(LdgWitB,$M39)=0,"",INDEX(LdgWitB,$M39)),"")) | H39: =IF($L39<>"",IF(INDEX(SCOp,$L39)="مرجوعی فروش",IF(INDEX(SCAmount,$L39)=0,"",-INDEX(SCAmount,$L39)),""),IF($M39<>"",IF(INDEX(LdgDepB,$M39)=0,"",INDEX(LdgDepB,$M39)),"")) | I39: =IF($B39="","",IF($I38="",$C$10,$I38)+IF($G39="",0,$G39)-IF($H39="",0,$H39)) | L39: =IFERROR(MATCH($C$5&"|"&RIGHT("000000"&23,6),LdgRankKeyA,0),"") | M39: =IFERROR(MATCH($C$5&"|"&RIGHT("000000"&23,6),LdgRankKeyB,0),"")
A40: 24 | B40: =IF(AND($L40="",$M40=""),"",IF($L40<>"",INDEX(SCNormDate,$L40),INDEX(LdgDateB,$M40))) | C40: =IF($L40<>"",INDEX(SCOp,$L40),IF($M40<>"","پرداخت بانکی","")) | D40: =IF($L40<>"",IF(INDEX(SCDoc,$L40)="","—",INDEX(SCDoc,$L40)),IF($M40<>"",INDEX(LdgBankB,$M40),"")) | E40: =IF($L40<>"",IF(INDEX(SCCitrus,$L40)&INDEX(SCNotes,$L40)="","",IF(INDEX(SCCitrus,$L40)="","",INDEX(SCCitrus,$L40))&IF(INDEX(SCNotes,$L40)="",""," — "&INDEX(SCNotes,$L40))),IF($M40<>"",IF(INDEX(LdgNoteB,$M40)="","—",INDEX(LdgNoteB,$M40)),"")) | F40: =IF($L40<>"",IF(INDEX(SCNet,$L40)=0,"",INDEX(SCNet,$L40)),"") | G40: =IF($L40<>"",IF(INDEX(SCOp,$L40)="مرجوعی فروش","",IF(INDEX(SCAmount,$L40)<=0,"",INDEX(SCAmount,$L40))),IF($M40<>"",IF(INDEX(LdgWitB,$M40)=0,"",INDEX(LdgWitB,$M40)),"")) | H40: =IF($L40<>"",IF(INDEX(SCOp,$L40)="مرجوعی فروش",IF(INDEX(SCAmount,$L40)=0,"",-INDEX(SCAmount,$L40)),""),IF($M40<>"",IF(INDEX(LdgDepB,$M40)=0,"",INDEX(LdgDepB,$M40)),"")) | I40: =IF($B40="","",IF($I39="",$C$10,$I39)+IF($G40="",0,$G40)-IF($H40="",0,$H40)) | L40: =IFERROR(MATCH($C$5&"|"&RIGHT("000000"&24,6),LdgRankKeyA,0),"") | M40: =IFERROR(MATCH($C$5&"|"&RIGHT("000000"&24,6),LdgRankKeyB,0),"")
A41: 25 | B41: =IF(AND($L41="",$M41=""),"",IF($L41<>"",INDEX(SCNormDate,$L41),INDEX(LdgDateB,$M41))) | C41: =IF($L41<>"",INDEX(SCOp,$L41),IF($M41<>"","پرداخت بانکی","")) | D41: =IF($L41<>"",IF(INDEX(SCDoc,$L41)="","—",INDEX(SCDoc,$L41)),IF($M41<>"",INDEX(LdgBankB,$M41),"")) | E41: =IF($L41<>"",IF(INDEX(SCCitrus,$L41)&INDEX(SCNotes,$L41)="","",IF(INDEX(SCCitrus,$L41)="","",INDEX(SCCitrus,$L41))&IF(INDEX(SCNotes,$L41)="",""," — "&INDEX(SCNotes,$L41))),IF($M41<>"",IF(INDEX(LdgNoteB,$M41)="","—",INDEX(LdgNoteB,$M41)),"")) | F41: =IF($L41<>"",IF(INDEX(SCNet,$L41)=0,"",INDEX(SCNet,$L41)),"") | G41: =IF($L41<>"",IF(INDEX(SCOp,$L41)="مرجوعی فروش","",IF(INDEX(SCAmount,$L41)<=0,"",INDEX(SCAmount,$L41))),IF($M41<>"",IF(INDEX(LdgWitB,$M41)=0,"",INDEX(LdgWitB,$M41)),"")) | H41: =IF($L41<>"",IF(INDEX(SCOp,$L41)="مرجوعی فروش",IF(INDEX(SCAmount,$L41)=0,"",-INDEX(SCAmount,$L41)),""),IF($M41<>"",IF(INDEX(LdgDepB,$M41)=0,"",INDEX(LdgDepB,$M41)),"")) | I41: =IF($B41="","",IF($I40="",$C$10,$I40)+IF($G41="",0,$G41)-IF($H41="",0,$H41)) | L41: =IFERROR(MATCH($C$5&"|"&RIGHT("000000"&25,6),LdgRankKeyA,0),"") | M41: =IFERROR(MATCH($C$5&"|"&RIGHT("000000"&25,6),LdgRankKeyB,0),"")
...

Sheet Sync
A1: مازندشت — سورتینگ و بسته‌بندی مرکبات
A2: باغدشت، بخش مرکزی، شهرستان قائم‌شهر، استان مازندران، ایران | MAZANDASHT · CITRUS SORTING & PACKING
A3: برگه فنی — آینه‌ی فایل مادر (INFO)، دفتر باسکول (Baskol) و فایل واریز/برداشت (Transactions) برای صورت‌حساب حساب‌ها. فرمول‌ها را تغییر ندهید. اگر همه سلول‌ها خالی شدند یعنی لینک به‌روز نشده: Data ← Edit Links ← Update Values.
A5: Accounts · Code | B5: · Nature | C5: · Subgroup | D5: · Name | E5: · Phone | F5: · Mobile | G5: · Address | I5: Ops · Code | J5: · Title | K5: · Direction | L5: · Group | N5: Params · Code | O5: · Name | P5: · Value | R5: Company | T5: Baskol · Date | U5: · Time | V5: · Doc | W5: · Op | X5: · Party | Y5: · Sub | Z5: · Citrus | AA5: · Scale | AB5: · Baskets | AC5: · Amount | AD5: · Notes | AE5: Txn Entry · C | AF5: Txn Entry · D | AG5: Txn Entry · E | AH5: Txn Entry · G | AI5: Txn Entry · K | AJ5: Txn Entry · L | AK5: Txn Entry · M | AL5: Txn Entry · N | AM5: Txn Entry · R
A6: =IF([1]Accounts!$D$7="","",[1]Accounts!$A$7) | B6: =IF([1]Accounts!$D$7="","",[1]Accounts!$B$7) | C6: =IF([1]Accounts!$D$7="","",[1]Accounts!$C$7) | D6: =IF([1]Accounts!$D$7="","",[1]Accounts!$D$7) | E6: =IF([1]Accounts!$D$7="","",[1]Accounts!$E$7) | F6: =IF([1]Accounts!$D$7="","",[1]Accounts!$F$7) | G6: =IF([1]Accounts!$D$7="","",[1]Accounts!$G$7) | I6: =IF([1]Ops!$B$7="","",[1]Ops!$A$7) | J6: =IF([1]Ops!$B$7="","",[1]Ops!$B$7) | K6: =IF([1]Ops!$B$7="","",[1]Ops!$C$7) | L6: =IF([1]Ops!$B$7="","",[1]Ops!$D$7) | N6: =IF([1]Params!$A$7="","",[1]Params!$A$7) | O6: =IF([1]Params!$B$7="","",[1]Params!$B$7) | P6: =[1]Params!$C$7 | R6: =IF([1]Company!$C$5="","",[1]Company!$C$5) | T6: =IF([2]Baskol!$B$9="","",[2]Baskol!$B$9) | U6: =IF([2]Baskol!$C$9="","",[2]Baskol!$C$9) | V6: =IF([2]Baskol!$D$9="","",[2]Baskol!$D$9) | W6: =IF([2]Baskol!$E$9="","",[2]Baskol!$E$9) | X6: =IF([2]Baskol!$G$9="","",[2]Baskol!$G$9) | Y6: =IF([2]Baskol!$I$9="","",[2]Baskol!$I$9) | Z6: =IF([2]Baskol!$J$9="","",[2]Baskol!$J$9) | AA6: =IF([2]Baskol!$K$9="","",[2]Baskol!$K$9) | AB6: =IF([2]Baskol!$L$9="","",[2]Baskol!$L$9) | AC6: =IF([2]Baskol!$N$9="","",[2]Baskol!$N$9) | AD6: =IF([2]Baskol!$O$9="","",[2]Baskol!$O$9) | AE6: =IF([3]Entry!$C$9="","",[3]Entry!$C$9) | AF6: =IF([3]Entry!$D$9="","",[3]Entry!$D$9) | AG6: =IF([3]Entry!$E$9="","",[3]Entry!$E$9) | AH6: =IF([3]Entry!$G$9="","",[3]Entry!$G$9) | AI6: =IF([3]Entry!$K$9="","",[3]Entry!$K$9) | AJ6: =IF([3]Entry!$L$9="","",[3]Entry!$L$9) | AK6: =IF([3]Entry!$M$9="","",[3]Entry!$M$9) | AL6: =IF([3]Entry!$N$9="","",[3]Entry!$N$9) | AM6: =IF([3]Entry!$R$9="","",[3]Entry!$R$9)
A7: =IF([1]Accounts!$D$8="","",[1]Accounts!$A$8) | B7: =IF([1]Accounts!$D$8="","",[1]Accounts!$B$8) | C7: =IF([1]Accounts!$D$8="","",[1]Accounts!$C$8) | D7: =IF([1]Accounts!$D$8="","",[1]Accounts!$D$8) | E7: =IF([1]Accounts!$D$8="","",[1]Accounts!$E$8) | F7: =IF([1]Accounts!$D$8="","",[1]Accounts!$F$8) | G7: =IF([1]Accounts!$D$8="","",[1]Accounts!$G$8) | I7: =IF([1]Ops!$B$8="","",[1]Ops!$A$8) | J7: =IF([1]Ops!$B$8="","",[1]Ops!$B$8) | K7: =IF([1]Ops!$B$8="","",[1]Ops!$C$8) | L7: =IF([1]Ops!$B$8="","",[1]Ops!$D$8) | N7: =IF([1]Params!$A$8="","",[1]Params!$A$8) | O7: =IF([1]Params!$B$8="","",[1]Params!$B$8) | P7: =[1]Params!$C$8 | R7: =IF([1]Company!$C$8="","",[1]Company!$C$8) | T7: =IF([2]Baskol!$B$10="","",[2]Baskol!$B$10) | U7: =IF([2]Baskol!$C$10="","",[2]Baskol!$C$10) | V7: =IF([2]Baskol!$D$10="","",[2]Baskol!$D$10) | W7: =IF([2]Baskol!$E$10="","",[2]Baskol!$E$10) | X7: =IF([2]Baskol!$G$10="","",[2]Baskol!$G$10) | Y7: =IF([2]Baskol!$I$10="","",[2]Baskol!$I$10) | Z7: =IF([2]Baskol!$J$10="","",[2]Baskol!$J$10) | AA7: =IF([2]Baskol!$K$10="","",[2]Baskol!$K$10) | AB7: =IF([2]Baskol!$L$10="","",[2]Baskol!$L$10) | AC7: =IF([2]Baskol!$N$10="","",[2]Baskol!$N$10) | AD7: =IF([2]Baskol!$O$10="","",[2]Baskol!$O$10) | AE7: =IF([3]Entry!$C$10="","",[3]Entry!$C$10) | AF7: =IF([3]Entry!$D$10="","",[3]Entry!$D$10) | AG7: =IF([3]Entry!$E$10="","",[3]Entry!$E$10) | AH7: =IF([3]Entry!$G$10="","",[3]Entry!$G$10) | AI7: =IF([3]Entry!$K$10="","",[3]Entry!$K$10) | AJ7: =IF([3]Entry!$L$10="","",[3]Entry!$L$10) | AK7: =IF([3]Entry!$M$10="","",[3]Entry!$M$10) | AL7: =IF([3]Entry!$N$10="","",[3]Entry!$N$10) | AM7: =IF([3]Entry!$R$10="","",[3]Entry!$R$10)
A8: =IF([1]Accounts!$D$9="","",[1]Accounts!$A$9) | B8: =IF([1]Accounts!$D$9="","",[1]Accounts!$B$9) | C8: =IF([1]Accounts!$D$9="","",[1]Accounts!$C$9) | D8: =IF([1]Accounts!$D$9="","",[1]Accounts!$D$9) | E8: =IF([1]Accounts!$D$9="","",[1]Accounts!$E$9) | F8: =IF([1]Accounts!$D$9="","",[1]Accounts!$F$9) | G8: =IF([1]Accounts!$D$9="","",[1]Accounts!$G$9) | I8: =IF([1]Ops!$B$9="","",[1]Ops!$A$9) | J8: =IF([1]Ops!$B$9="","",[1]Ops!$B$9) | K8: =IF([1]Ops!$B$9="","",[1]Ops!$C$9) | L8: =IF([1]Ops!$B$9="","",[1]Ops!$D$9) | N8: =IF([1]Params!$A$9="","",[1]Params!$A$9) | O8: =IF([1]Params!$B$9="","",[1]Params!$B$9) | P8: =[1]Params!$C$9 | R8: =IF([1]Company!$C$9="","",[1]Company!$C$9) | T8: =IF([2]Baskol!$B$11="","",[2]Baskol!$B$11) | U8: =IF([2]Baskol!$C$11="","",[2]Baskol!$C$11) | V8: =IF([2]Baskol!$D$11="","",[2]Baskol!$D$11) | W8: =IF([2]Baskol!$E$11="","",[2]Baskol!$E$11) | X8: =IF([2]Baskol!$G$11="","",[2]Baskol!$G$11) | Y8: =IF([2]Baskol!$I$11="","",[2]Baskol!$I$11) | Z8: =IF([2]Baskol!$J$11="","",[2]Baskol!$J$11) | AA8: =IF([2]Baskol!$K$11="","",[2]Baskol!$K$11) | AB8: =IF([2]Baskol!$L$11="","",[2]Baskol!$L$11) | AC8: =IF([2]Baskol!$N$11="","",[2]Baskol!$N$11) | AD8: =IF([2]Baskol!$O$11="","",[2]Baskol!$O$11) | AE8: =IF([3]Entry!$C$11="","",[3]Entry!$C$11) | AF8: =IF([3]Entry!$D$11="","",[3]Entry!$D$11) | AG8: =IF([3]Entry!$E$11="","",[3]Entry!$E$11) | AH8: =IF([3]Entry!$G$11="","",[3]Entry!$G$11) | AI8: =IF([3]Entry!$K$11="","",[3]Entry!$K$11) | AJ8: =IF([3]Entry!$L$11="","",[3]Entry!$L$11) | AK8: =IF([3]Entry!$M$11="","",[3]Entry!$M$11) | AL8: =IF([3]Entry!$N$11="","",[3]Entry!$N$11) | AM8: =IF([3]Entry!$R$11="","",[3]Entry!$R$11)
A9: =IF([1]Accounts!$D$10="","",[1]Accounts!$A$10) | B9: =IF([1]Accounts!$D$10="","",[1]Accounts!$B$10) | C9: =IF([1]Accounts!$D$10="","",[1]Accounts!$C$10) | D9: =IF([1]Accounts!$D$10="","",[1]Accounts!$D$10) | E9: =IF([1]Accounts!$D$10="","",[1]Accounts!$E$10) | F9: =IF([1]Accounts!$D$10="","",[1]Accounts!$F$10) | G9: =IF([1]Accounts!$D$10="","",[1]Accounts!$G$10) | I9: =IF([1]Ops!$B$10="","",[1]Ops!$A$10) | J9: =IF([1]Ops!$B$10="","",[1]Ops!$B$10) | K9: =IF([1]Ops!$B$10="","",[1]Ops!$C$10) | L9: =IF([1]Ops!$B$10="","",[1]Ops!$D$10) | N9: =IF([1]Params!$A$10="","",[1]Params!$A$10) | O9: =IF([1]Params!$B$10="","",[1]Params!$B$10) | P9: =[1]Params!$C$10 | R9: =IF([1]Company!$C$7="","",[1]Company!$C$7) | T9: =IF([2]Baskol!$B$12="","",[2]Baskol!$B$12) | U9: =IF([2]Baskol!$C$12="","",[2]Baskol!$C$12) | V9: =IF([2]Baskol!$D$12="","",[2]Baskol!$D$12) | W9: =IF([2]Baskol!$E$12="","",[2]Baskol!$E$12) | X9: =IF([2]Baskol!$G$12="","",[2]Baskol!$G$12) | Y9: =IF([2]Baskol!$I$12="","",[2]Baskol!$I$12) | Z9: =IF([2]Baskol!$J$12="","",[2]Baskol!$J$12) | AA9: =IF([2]Baskol!$K$12="","",[2]Baskol!$K$12) | AB9: =IF([2]Baskol!$L$12="","",[2]Baskol!$L$12) | AC9: =IF([2]Baskol!$N$12="","",[2]Baskol!$N$12) | AD9: =IF([2]Baskol!$O$12="","",[2]Baskol!$O$12) | AE9: =IF([3]Entry!$C$12="","",[3]Entry!$C$12) | AF9: =IF([3]Entry!$D$12="","",[3]Entry!$D$12) | AG9: =IF([3]Entry!$E$12="","",[3]Entry!$E$12) | AH9: =IF([3]Entry!$G$12="","",[3]Entry!$G$12) | AI9: =IF([3]Entry!$K$12="","",[3]Entry!$K$12) | AJ9: =IF([3]Entry!$L$12="","",[3]Entry!$L$12) | AK9: =IF([3]Entry!$M$12="","",[3]Entry!$M$12) | AL9: =IF([3]Entry!$N$12="","",[3]Entry!$N$12) | AM9: =IF([3]Entry!$R$12="","",[3]Entry!$R$12)
A10: =IF([1]Accounts!$D$11="","",[1]Accounts!$A$11) | B10: =IF([1]Accounts!$D$11="","",[1]Accounts!$B$11) | C10: =IF([1]Accounts!$D$11="","",[1]Accounts!$C$11) | D10: =IF([1]Accounts!$D$11="","",[1]Accounts!$D$11) | E10: =IF([1]Accounts!$D$11="","",[1]Accounts!$E$11) | F10: =IF([1]Accounts!$D$11="","",[1]Accounts!$F$11) | G10: =IF([1]Accounts!$D$11="","",[1]Accounts!$G$11) | I10: =IF([1]Ops!$B$11="","",[1]Ops!$A$11) | J10: =IF([1]Ops!$B$11="","",[1]Ops!$B$11) | K10: =IF([1]Ops!$B$11="","",[1]Ops!$C$11) | L10: =IF([1]Ops!$B$11="","",[1]Ops!$D$11) | N10: =IF([1]Params!$A$11="","",[1]Params!$A$11) | O10: =IF([1]Params!$B$11="","",[1]Params!$B$11) | P10: =[1]Params!$C$11 | T10: =IF([2]Baskol!$B$13="","",[2]Baskol!$B$13) | U10: =IF([2]Baskol!$C$13="","",[2]Baskol!$C$13) | V10: =IF([2]Baskol!$D$13="","",[2]Baskol!$D$13) | W10: =IF([2]Baskol!$E$13="","",[2]Baskol!$E$13) | X10: =IF([2]Baskol!$G$13="","",[2]Baskol!$G$13) | Y10: =IF([2]Baskol!$I$13="","",[2]Baskol!$I$13) | Z10: =IF([2]Baskol!$J$13="","",[2]Baskol!$J$13) | AA10: =IF([2]Baskol!$K$13="","",[2]Baskol!$K$13) | AB10: =IF([2]Baskol!$L$13="","",[2]Baskol!$L$13) | AC10: =IF([2]Baskol!$N$13="","",[2]Baskol!$N$13) | AD10: =IF([2]Baskol!$O$13="","",[2]Baskol!$O$13) | AE10: =IF([3]Entry!$C$13="","",[3]Entry!$C$13) | AF10: =IF([3]Entry!$D$13="","",[3]Entry!$D$13) | AG10: =IF([3]Entry!$E$13="","",[3]Entry!$E$13) | AH10: =IF([3]Entry!$G$13="","",[3]Entry!$G$13) | AI10: =IF([3]Entry!$K$13="","",[3]Entry!$K$13) | AJ10: =IF([3]Entry!$L$13="","",[3]Entry!$L$13) | AK10: =IF([3]Entry!$M$13="","",[3]Entry!$M$13) | AL10: =IF([3]Entry!$N$13="","",[3]Entry!$N$13) | AM10: =IF([3]Entry!$R$13="","",[3]Entry!$R$13)
A11: =IF([1]Accounts!$D$12="","",[1]Accounts!$A$12) | B11: =IF([1]Accounts!$D$12="","",[1]Accounts!$B$12) | C11: =IF([1]Accounts!$D$12="","",[1]Accounts!$C$12) | D11: =IF([1]Accounts!$D$12="","",[1]Accounts!$D$12) | E11: =IF([1]Accounts!$D$12="","",[1]Accounts!$E$12) | F11: =IF([1]Accounts!$D$12="","",[1]Accounts!$F$12) | G11: =IF([1]Accounts!$D$12="","",[1]Accounts!$G$12) | I11: =IF([1]Ops!$B$12="","",[1]Ops!$A$12) | J11: =IF([1]Ops!$B$12="","",[1]Ops!$B$12) | K11: =IF([1]Ops!$B$12="","",[1]Ops!$C$12) | L11: =IF([1]Ops!$B$12="","",[1]Ops!$D$12) | N11: =IF([1]Params!$A$12="","",[1]Params!$A$12) | O11: =IF([1]Params!$B$12="","",[1]Params!$B$12) | P11: =[1]Params!$C$12 | T11: =IF([2]Baskol!$B$14="","",[2]Baskol!$B$14) | U11: =IF([2]Baskol!$C$14="","",[2]Baskol!$C$14) | V11: =IF([2]Baskol!$D$14="","",[2]Baskol!$D$14) | W11: =IF([2]Baskol!$E$14="","",[2]Baskol!$E$14) | X11: =IF([2]Baskol!$G$14="","",[2]Baskol!$G$14) | Y11: =IF([2]Baskol!$I$14="","",[2]Baskol!$I$14) | Z11: =IF([2]Baskol!$J$14="","",[2]Baskol!$J$14) | AA11: =IF([2]Baskol!$K$14="","",[2]Baskol!$K$14) | AB11: =IF([2]Baskol!$L$14="","",[2]Baskol!$L$14) | AC11: =IF([2]Baskol!$N$14="","",[2]Baskol!$N$14) | AD11: =IF([2]Baskol!$O$14="","",[2]Baskol!$O$14) | AE11: =IF([3]Entry!$C$14="","",[3]Entry!$C$14) | AF11: =IF([3]Entry!$D$14="","",[3]Entry!$D$14) | AG11: =IF([3]Entry!$E$14="","",[3]Entry!$E$14) | AH11: =IF([3]Entry!$G$14="","",[3]Entry!$G$14) | AI11: =IF([3]Entry!$K$14="","",[3]Entry!$K$14) | AJ11: =IF([3]Entry!$L$14="","",[3]Entry!$L$14) | AK11: =IF([3]Entry!$M$14="","",[3]Entry!$M$14) | AL11: =IF([3]Entry!$N$14="","",[3]Entry!$N$14) | AM11: =IF([3]Entry!$R$14="","",[3]Entry!$R$14)
A12: =IF([1]Accounts!$D$13="","",[1]Accounts!$A$13) | B12: =IF([1]Accounts!$D$13="","",[1]Accounts!$B$13) | C12: =IF([1]Accounts!$D$13="","",[1]Accounts!$C$13) | D12: =IF([1]Accounts!$D$13="","",[1]Accounts!$D$13) | E12: =IF([1]Accounts!$D$13="","",[1]Accounts!$E$13) | F12: =IF([1]Accounts!$D$13="","",[1]Accounts!$F$13) | G12: =IF([1]Accounts!$D$13="","",[1]Accounts!$G$13) | I12: =IF([1]Ops!$B$13="","",[1]Ops!$A$13) | J12: =IF([1]Ops!$B$13="","",[1]Ops!$B$13) | K12: =IF([1]Ops!$B$13="","",[1]Ops!$C$13) | L12: =IF([1]Ops!$B$13="","",[1]Ops!$D$13) | N12: =IF([1]Params!$A$13="","",[1]Params!$A$13) | O12: =IF([1]Params!$B$13="","",[1]Params!$B$13) | P12: =[1]Params!$C$13 | T12: =IF([2]Baskol!$B$15="","",[2]Baskol!$B$15) | U12: =IF([2]Baskol!$C$15="","",[2]Baskol!$C$15) | V12: =IF([2]Baskol!$D$15="","",[2]Baskol!$D$15) | W12: =IF([2]Baskol!$E$15="","",[2]Baskol!$E$15) | X12: =IF([2]Baskol!$G$15="","",[2]Baskol!$G$15) | Y12: =IF([2]Baskol!$I$15="","",[2]Baskol!$I$15) | Z12: =IF([2]Baskol!$J$15="","",[2]Baskol!$J$15) | AA12: =IF([2]Baskol!$K$15="","",[2]Baskol!$K$15) | AB12: =IF([2]Baskol!$L$15="","",[2]Baskol!$L$15) | AC12: =IF([2]Baskol!$N$15="","",[2]Baskol!$N$15) | AD12: =IF([2]Baskol!$O$15="","",[2]Baskol!$O$15) | AE12: =IF([3]Entry!$C$15="","",[3]Entry!$C$15) | AF12: =IF([3]Entry!$D$15="","",[3]Entry!$D$15) | AG12: =IF([3]Entry!$E$15="","",[3]Entry!$E$15) | AH12: =IF([3]Entry!$G$15="","",[3]Entry!$G$15) | AI12: =IF([3]Entry!$K$15="","",[3]Entry!$K$15) | AJ12: =IF([3]Entry!$L$15="","",[3]Entry!$L$15) | AK12: =IF([3]Entry!$M$15="","",[3]Entry!$M$15) | AL12: =IF([3]Entry!$N$15="","",[3]Entry!$N$15) | AM12: =IF([3]Entry!$R$15="","",[3]Entry!$R$15)
A13: =IF([1]Accounts!$D$14="","",[1]Accounts!$A$14) | B13: =IF([1]Accounts!$D$14="","",[1]Accounts!$B$14) | C13: =IF([1]Accounts!$D$14="","",[1]Accounts!$C$14) | D13: =IF([1]Accounts!$D$14="","",[1]Accounts!$D$14) | E13: =IF([1]Accounts!$D$14="","",[1]Accounts!$E$14) | F13: =IF([1]Accounts!$D$14="","",[1]Accounts!$F$14) | G13: =IF([1]Accounts!$D$14="","",[1]Accounts!$G$14) | I13: =IF([1]Ops!$B$14="","",[1]Ops!$A$14) | J13: =IF([1]Ops!$B$14="","",[1]Ops!$B$14) | K13: =IF([1]Ops!$B$14="","",[1]Ops!$C$14) | L13: =IF([1]Ops!$B$14="","",[1]Ops!$D$14) | N13: =IF([1]Params!$A$14="","",[1]Params!$A$14) | O13: =IF([1]Params!$B$14="","",[1]Params!$B$14) | P13: =[1]Params!$C$14 | T13: =IF([2]Baskol!$B$16="","",[2]Baskol!$B$16) | U13: =IF([2]Baskol!$C$16="","",[2]Baskol!$C$16) | V13: =IF([2]Baskol!$D$16="","",[2]Baskol!$D$16) | W13: =IF([2]Baskol!$E$16="","",[2]Baskol!$E$16) | X13: =IF([2]Baskol!$G$16="","",[2]Baskol!$G$16) | Y13: =IF([2]Baskol!$I$16="","",[2]Baskol!$I$16) | Z13: =IF([2]Baskol!$J$16="","",[2]Baskol!$J$16) | AA13: =IF([2]Baskol!$K$16="","",[2]Baskol!$K$16) | AB13: =IF([2]Baskol!$L$16="","",[2]Baskol!$L$16) | AC13: =IF([2]Baskol!$N$16="","",[2]Baskol!$N$16) | AD13: =IF([2]Baskol!$O$16="","",[2]Baskol!$O$16) | AE13: =IF([3]Entry!$C$16="","",[3]Entry!$C$16) | AF13: =IF([3]Entry!$D$16="","",[3]Entry!$D$16) | AG13: =IF([3]Entry!$E$16="","",[3]Entry!$E$16) | AH13: =IF([3]Entry!$G$16="","",[3]Entry!$G$16) | AI13: =IF([3]Entry!$K$16="","",[3]Entry!$K$16) | AJ13: =IF([3]Entry!$L$16="","",[3]Entry!$L$16) | AK13: =IF([3]Entry!$M$16="","",[3]Entry!$M$16) | AL13: =IF([3]Entry!$N$16="","",[3]Entry!$N$16) | AM13: =IF([3]Entry!$R$16="","",[3]Entry!$R$16)
A14: =IF([1]Accounts!$D$15="","",[1]Accounts!$A$15) | B14: =IF([1]Accounts!$D$15="","",[1]Accounts!$B$15) | C14: =IF([1]Accounts!$D$15="","",[1]Accounts!$C$15) | D14: =IF([1]Accounts!$D$15="","",[1]Accounts!$D$15) | E14: =IF([1]Accounts!$D$15="","",[1]Accounts!$E$15) | F14: =IF([1]Accounts!$D$15="","",[1]Accounts!$F$15) | G14: =IF([1]Accounts!$D$15="","",[1]Accounts!$G$15) | I14: =IF([1]Ops!$B$15="","",[1]Ops!$A$15) | J14: =IF([1]Ops!$B$15="","",[1]Ops!$B$15) | K14: =IF([1]Ops!$B$15="","",[1]Ops!$C$15) | L14: =IF([1]Ops!$B$15="","",[1]Ops!$D$15) | N14: =IF([1]Params!$A$15="","",[1]Params!$A$15) | O14: =IF([1]Params!$B$15="","",[1]Params!$B$15) | P14: =[1]Params!$C$15 | T14: =IF([2]Baskol!$B$17="","",[2]Baskol!$B$17) | U14: =IF([2]Baskol!$C$17="","",[2]Baskol!$C$17) | V14: =IF([2]Baskol!$D$17="","",[2]Baskol!$D$17) | W14: =IF([2]Baskol!$E$17="","",[2]Baskol!$E$17) | X14: =IF([2]Baskol!$G$17="","",[2]Baskol!$G$17) | Y14: =IF([2]Baskol!$I$17="","",[2]Baskol!$I$17) | Z14: =IF([2]Baskol!$J$17="","",[2]Baskol!$J$17) | AA14: =IF([2]Baskol!$K$17="","",[2]Baskol!$K$17) | AB14: =IF([2]Baskol!$L$17="","",[2]Baskol!$L$17) | AC14: =IF([2]Baskol!$N$17="","",[2]Baskol!$N$17) | AD14: =IF([2]Baskol!$O$17="","",[2]Baskol!$O$17) | AE14: =IF([3]Entry!$C$17="","",[3]Entry!$C$17) | AF14: =IF([3]Entry!$D$17="","",[3]Entry!$D$17) | AG14: =IF([3]Entry!$E$17="","",[3]Entry!$E$17) | AH14: =IF([3]Entry!$G$17="","",[3]Entry!$G$17) | AI14: =IF([3]Entry!$K$17="","",[3]Entry!$K$17) | AJ14: =IF([3]Entry!$L$17="","",[3]Entry!$L$17) | AK14: =IF([3]Entry!$M$17="","",[3]Entry!$M$17) | AL14: =IF([3]Entry!$N$17="","",[3]Entry!$N$17) | AM14: =IF([3]Entry!$R$17="","",[3]Entry!$R$17)
A15: =IF([1]Accounts!$D$16="","",[1]Accounts!$A$16) | B15: =IF([1]Accounts!$D$16="","",[1]Accounts!$B$16) | C15: =IF([1]Accounts!$D$16="","",[1]Accounts!$C$16) | D15: =IF([1]Accounts!$D$16="","",[1]Accounts!$D$16) | E15: =IF([1]Accounts!$D$16="","",[1]Accounts!$E$16) | F15: =IF([1]Accounts!$D$16="","",[1]Accounts!$F$16) | G15: =IF([1]Accounts!$D$16="","",[1]Accounts!$G$16) | I15: =IF([1]Ops!$B$16="","",[1]Ops!$A$16) | J15: =IF([1]Ops!$B$16="","",[1]Ops!$B$16) | K15: =IF([1]Ops!$B$16="","",[1]Ops!$C$16) | L15: =IF([1]Ops!$B$16="","",[1]Ops!$D$16) | N15: =IF([1]Params!$A$16="","",[1]Params!$A$16) | O15: =IF([1]Params!$B$16="","",[1]Params!$B$16) | P15: =[1]Params!$C$16 | T15: =IF([2]Baskol!$B$18="","",[2]Baskol!$B$18) | U15: =IF([2]Baskol!$C$18="","",[2]Baskol!$C$18) | V15: =IF([2]Baskol!$D$18="","",[2]Baskol!$D$18) | W15: =IF([2]Baskol!$E$18="","",[2]Baskol!$E$18) | X15: =IF([2]Baskol!$G$18="","",[2]Baskol!$G$18) | Y15: =IF([2]Baskol!$I$18="","",[2]Baskol!$I$18) | Z15: =IF([2]Baskol!$J$18="","",[2]Baskol!$J$18) | AA15: =IF([2]Baskol!$K$18="","",[2]Baskol!$K$18) | AB15: =IF([2]Baskol!$L$18="","",[2]Baskol!$L$18) | AC15: =IF([2]Baskol!$N$18="","",[2]Baskol!$N$18) | AD15: =IF([2]Baskol!$O$18="","",[2]Baskol!$O$18) | AE15: =IF([3]Entry!$C$18="","",[3]Entry!$C$18) | AF15: =IF([3]Entry!$D$18="","",[3]Entry!$D$18) | AG15: =IF([3]Entry!$E$18="","",[3]Entry!$E$18) | AH15: =IF([3]Entry!$G$18="","",[3]Entry!$G$18) | AI15: =IF([3]Entry!$K$18="","",[3]Entry!$K$18) | AJ15: =IF([3]Entry!$L$18="","",[3]Entry!$L$18) | AK15: =IF([3]Entry!$M$18="","",[3]Entry!$M$18) | AL15: =IF([3]Entry!$N$18="","",[3]Entry!$N$18) | AM15: =IF([3]Entry!$R$18="","",[3]Entry!$R$18)
A16: =IF([1]Accounts!$D$17="","",[1]Accounts!$A$17) | B16: =IF([1]Accounts!$D$17="","",[1]Accounts!$B$17) | C16: =IF([1]Accounts!$D$17="","",[1]Accounts!$C$17) | D16: =IF([1]Accounts!$D$17="","",[1]Accounts!$D$17) | E16: =IF([1]Accounts!$D$17="","",[1]Accounts!$E$17) | F16: =IF([1]Accounts!$D$17="","",[1]Accounts!$F$17) | G16: =IF([1]Accounts!$D$17="","",[1]Accounts!$G$17) | I16: =IF([1]Ops!$B$17="","",[1]Ops!$A$17) | J16: =IF([1]Ops!$B$17="","",[1]Ops!$B$17) | K16: =IF([1]Ops!$B$17="","",[1]Ops!$C$17) | L16: =IF([1]Ops!$B$17="","",[1]Ops!$D$17) | N16: =IF([1]Params!$A$17="","",[1]Params!$A$17) | O16: =IF([1]Params!$B$17="","",[1]Params!$B$17) | P16: =[1]Params!$C$17 | T16: =IF([2]Baskol!$B$19="","",[2]Baskol!$B$19) | U16: =IF([2]Baskol!$C$19="","",[2]Baskol!$C$19) | V16: =IF([2]Baskol!$D$19="","",[2]Baskol!$D$19) | W16: =IF([2]Baskol!$E$19="","",[2]Baskol!$E$19) | X16: =IF([2]Baskol!$G$19="","",[2]Baskol!$G$19) | Y16: =IF([2]Baskol!$I$19="","",[2]Baskol!$I$19) | Z16: =IF([2]Baskol!$J$19="","",[2]Baskol!$J$19) | AA16: =IF([2]Baskol!$K$19="","",[2]Baskol!$K$19) | AB16: =IF([2]Baskol!$L$19="","",[2]Baskol!$L$19) | AC16: =IF([2]Baskol!$N$19="","",[2]Baskol!$N$19) | AD16: =IF([2]Baskol!$O$19="","",[2]Baskol!$O$19) | AE16: =IF([3]Entry!$C$19="","",[3]Entry!$C$19) | AF16: =IF([3]Entry!$D$19="","",[3]Entry!$D$19) | AG16: =IF([3]Entry!$E$19="","",[3]Entry!$E$19) | AH16: =IF([3]Entry!$G$19="","",[3]Entry!$G$19) | AI16: =IF([3]Entry!$K$19="","",[3]Entry!$K$19) | AJ16: =IF([3]Entry!$L$19="","",[3]Entry!$L$19) | AK16: =IF([3]Entry!$M$19="","",[3]Entry!$M$19) | AL16: =IF([3]Entry!$N$19="","",[3]Entry!$N$19) | AM16: =IF([3]Entry!$R$19="","",[3]Entry!$R$19)
A17: =IF([1]Accounts!$D$18="","",[1]Accounts!$A$18) | B17: =IF([1]Accounts!$D$18="","",[1]Accounts!$B$18) | C17: =IF([1]Accounts!$D$18="","",[1]Accounts!$C$18) | D17: =IF([1]Accounts!$D$18="","",[1]Accounts!$D$18) | E17: =IF([1]Accounts!$D$18="","",[1]Accounts!$E$18) | F17: =IF([1]Accounts!$D$18="","",[1]Accounts!$F$18) | G17: =IF([1]Accounts!$D$18="","",[1]Accounts!$G$18) | I17: =IF([1]Ops!$B$18="","",[1]Ops!$A$18) | J17: =IF([1]Ops!$B$18="","",[1]Ops!$B$18) | K17: =IF([1]Ops!$B$18="","",[1]Ops!$C$18) | L17: =IF([1]Ops!$B$18="","",[1]Ops!$D$18) | N17: =IF([1]Params!$A$18="","",[1]Params!$A$18) | O17: =IF([1]Params!$B$18="","",[1]Params!$B$18) | P17: =[1]Params!$C$18 | T17: =IF([2]Baskol!$B$20="","",[2]Baskol!$B$20) | U17: =IF([2]Baskol!$C$20="","",[2]Baskol!$C$20) | V17: =IF([2]Baskol!$D$20="","",[2]Baskol!$D$20) | W17: =IF([2]Baskol!$E$20="","",[2]Baskol!$E$20) | X17: =IF([2]Baskol!$G$20="","",[2]Baskol!$G$20) | Y17: =IF([2]Baskol!$I$20="","",[2]Baskol!$I$20) | Z17: =IF([2]Baskol!$J$20="","",[2]Baskol!$J$20) | AA17: =IF([2]Baskol!$K$20="","",[2]Baskol!$K$20) | AB17: =IF([2]Baskol!$L$20="","",[2]Baskol!$L$20) | AC17: =IF([2]Baskol!$N$20="","",[2]Baskol!$N$20) | AD17: =IF([2]Baskol!$O$20="","",[2]Baskol!$O$20) | AE17: =IF([3]Entry!$C$20="","",[3]Entry!$C$20) | AF17: =IF([3]Entry!$D$20="","",[3]Entry!$D$20) | AG17: =IF([3]Entry!$E$20="","",[3]Entry!$E$20) | AH17: =IF([3]Entry!$G$20="","",[3]Entry!$G$20) | AI17: =IF([3]Entry!$K$20="","",[3]Entry!$K$20) | AJ17: =IF([3]Entry!$L$20="","",[3]Entry!$L$20) | AK17: =IF([3]Entry!$M$20="","",[3]Entry!$M$20) | AL17: =IF([3]Entry!$N$20="","",[3]Entry!$N$20) | AM17: =IF([3]Entry!$R$20="","",[3]Entry!$R$20)
A18: =IF([1]Accounts!$D$19="","",[1]Accounts!$A$19) | B18: =IF([1]Accounts!$D$19="","",[1]Accounts!$B$19) | C18: =IF([1]Accounts!$D$19="","",[1]Accounts!$C$19) | D18: =IF([1]Accounts!$D$19="","",[1]Accounts!$D$19) | E18: =IF([1]Accounts!$D$19="","",[1]Accounts!$E$19) | F18: =IF([1]Accounts!$D$19="","",[1]Accounts!$F$19) | G18: =IF([1]Accounts!$D$19="","",[1]Accounts!$G$19) | I18: =IF([1]Ops!$B$19="","",[1]Ops!$A$19) | J18: =IF([1]Ops!$B$19="","",[1]Ops!$B$19) | K18: =IF([1]Ops!$B$19="","",[1]Ops!$C$19) | L18: =IF([1]Ops!$B$19="","",[1]Ops!$D$19) | T18: =IF([2]Baskol!$B$21="","",[2]Baskol!$B$21) | U18: =IF([2]Baskol!$C$21="","",[2]Baskol!$C$21) | V18: =IF([2]Baskol!$D$21="","",[2]Baskol!$D$21) | W18: =IF([2]Baskol!$E$21="","",[2]Baskol!$E$21) | X18: =IF([2]Baskol!$G$21="","",[2]Baskol!$G$21) | Y18: =IF([2]Baskol!$I$21="","",[2]Baskol!$I$21) | Z18: =IF([2]Baskol!$J$21="","",[2]Baskol!$J$21) | AA18: =IF([2]Baskol!$K$21="","",[2]Baskol!$K$21) | AB18: =IF([2]Baskol!$L$21="","",[2]Baskol!$L$21) | AC18: =IF([2]Baskol!$N$21="","",[2]Baskol!$N$21) | AD18: =IF([2]Baskol!$O$21="","",[2]Baskol!$O$21) | AE18: =IF([3]Entry!$C$21="","",[3]Entry!$C$21) | AF18: =IF([3]Entry!$D$21="","",[3]Entry!$D$21) | AG18: =IF([3]Entry!$E$21="","",[3]Entry!$E$21) | AH18: =IF([3]Entry!$G$21="","",[3]Entry!$G$21) | AI18: =IF([3]Entry!$K$21="","",[3]Entry!$K$21) | AJ18: =IF([3]Entry!$L$21="","",[3]Entry!$L$21) | AK18: =IF([3]Entry!$M$21="","",[3]Entry!$M$21) | AL18: =IF([3]Entry!$N$21="","",[3]Entry!$N$21) | AM18: =IF([3]Entry!$R$21="","",[3]Entry!$R$21)
A19: =IF([1]Accounts!$D$20="","",[1]Accounts!$A$20) | B19: =IF([1]Accounts!$D$20="","",[1]Accounts!$B$20) | C19: =IF([1]Accounts!$D$20="","",[1]Accounts!$C$20) | D19: =IF([1]Accounts!$D$20="","",[1]Accounts!$D$20) | E19: =IF([1]Accounts!$D$20="","",[1]Accounts!$E$20) | F19: =IF([1]Accounts!$D$20="","",[1]Accounts!$F$20) | G19: =IF([1]Accounts!$D$20="","",[1]Accounts!$G$20) | I19: =IF([1]Ops!$B$20="","",[1]Ops!$A$20) | J19: =IF([1]Ops!$B$20="","",[1]Ops!$B$20) | K19: =IF([1]Ops!$B$20="","",[1]Ops!$C$20) | L19: =IF([1]Ops!$B$20="","",[1]Ops!$D$20) | T19: =IF([2]Baskol!$B$22="","",[2]Baskol!$B$22) | U19: =IF([2]Baskol!$C$22="","",[2]Baskol!$C$22) | V19: =IF([2]Baskol!$D$22="","",[2]Baskol!$D$22) | W19: =IF([2]Baskol!$E$22="","",[2]Baskol!$E$22) | X19: =IF([2]Baskol!$G$22="","",[2]Baskol!$G$22) | Y19: =IF([2]Baskol!$I$22="","",[2]Baskol!$I$22) | Z19: =IF([2]Baskol!$J$22="","",[2]Baskol!$J$22) | AA19: =IF([2]Baskol!$K$22="","",[2]Baskol!$K$22) | AB19: =IF([2]Baskol!$L$22="","",[2]Baskol!$L$22) | AC19: =IF([2]Baskol!$N$22="","",[2]Baskol!$N$22) | AD19: =IF([2]Baskol!$O$22="","",[2]Baskol!$O$22) | AE19: =IF([3]Entry!$C$22="","",[3]Entry!$C$22) | AF19: =IF([3]Entry!$D$22="","",[3]Entry!$D$22) | AG19: =IF([3]Entry!$E$22="","",[3]Entry!$E$22) | AH19: =IF([3]Entry!$G$22="","",[3]Entry!$G$22) | AI19: =IF([3]Entry!$K$22="","",[3]Entry!$K$22) | AJ19: =IF([3]Entry!$L$22="","",[3]Entry!$L$22) | AK19: =IF([3]Entry!$M$22="","",[3]Entry!$M$22) | AL19: =IF([3]Entry!$N$22="","",[3]Entry!$N$22) | AM19: =IF([3]Entry!$R$22="","",[3]Entry!$R$22)
A20: =IF([1]Accounts!$D$21="","",[1]Accounts!$A$21) | B20: =IF([1]Accounts!$D$21="","",[1]Accounts!$B$21) | C20: =IF([1]Accounts!$D$21="","",[1]Accounts!$C$21) | D20: =IF([1]Accounts!$D$21="","",[1]Accounts!$D$21) | E20: =IF([1]Accounts!$D$21="","",[1]Accounts!$E$21) | F20: =IF([1]Accounts!$D$21="","",[1]Accounts!$F$21) | G20: =IF([1]Accounts!$D$21="","",[1]Accounts!$G$21) | I20: =IF([1]Ops!$B$21="","",[1]Ops!$A$21) | J20: =IF([1]Ops!$B$21="","",[1]Ops!$B$21) | K20: =IF([1]Ops!$B$21="","",[1]Ops!$C$21) | L20: =IF([1]Ops!$B$21="","",[1]Ops!$D$21) | T20: =IF([2]Baskol!$B$23="","",[2]Baskol!$B$23) | U20: =IF([2]Baskol!$C$23="","",[2]Baskol!$C$23) | V20: =IF([2]Baskol!$D$23="","",[2]Baskol!$D$23) | W20: =IF([2]Baskol!$E$23="","",[2]Baskol!$E$23) | X20: =IF([2]Baskol!$G$23="","",[2]Baskol!$G$23) | Y20: =IF([2]Baskol!$I$23="","",[2]Baskol!$I$23) | Z20: =IF([2]Baskol!$J$23="","",[2]Baskol!$J$23) | AA20: =IF([2]Baskol!$K$23="","",[2]Baskol!$K$23) | AB20: =IF([2]Baskol!$L$23="","",[2]Baskol!$L$23) | AC20: =IF([2]Baskol!$N$23="","",[2]Baskol!$N$23) | AD20: =IF([2]Baskol!$O$23="","",[2]Baskol!$O$23) | AE20: =IF([3]Entry!$C$23="","",[3]Entry!$C$23) | AF20: =IF([3]Entry!$D$23="","",[3]Entry!$D$23) | AG20: =IF([3]Entry!$E$23="","",[3]Entry!$E$23) | AH20: =IF([3]Entry!$G$23="","",[3]Entry!$G$23) | AI20: =IF([3]Entry!$K$23="","",[3]Entry!$K$23) | AJ20: =IF([3]Entry!$L$23="","",[3]Entry!$L$23) | AK20: =IF([3]Entry!$M$23="","",[3]Entry!$M$23) | AL20: =IF([3]Entry!$N$23="","",[3]Entry!$N$23) | AM20: =IF([3]Entry!$R$23="","",[3]Entry!$R$23)
A21: =IF([1]Accounts!$D$22="","",[1]Accounts!$A$22) | B21: =IF([1]Accounts!$D$22="","",[1]Accounts!$B$22) | C21: =IF([1]Accounts!$D$22="","",[1]Accounts!$C$22) | D21: =IF([1]Accounts!$D$22="","",[1]Accounts!$D$22) | E21: =IF([1]Accounts!$D$22="","",[1]Accounts!$E$22) | F21: =IF([1]Accounts!$D$22="","",[1]Accounts!$F$22) | G21: =IF([1]Accounts!$D$22="","",[1]Accounts!$G$22) | I21: =IF([1]Ops!$B$22="","",[1]Ops!$A$22) | J21: =IF([1]Ops!$B$22="","",[1]Ops!$B$22) | K21: =IF([1]Ops!$B$22="","",[1]Ops!$C$22) | L21: =IF([1]Ops!$B$22="","",[1]Ops!$D$22) | T21: =IF([2]Baskol!$B$24="","",[2]Baskol!$B$24) | U21: =IF([2]Baskol!$C$24="","",[2]Baskol!$C$24) | V21: =IF([2]Baskol!$D$24="","",[2]Baskol!$D$24) | W21: =IF([2]Baskol!$E$24="","",[2]Baskol!$E$24) | X21: =IF([2]Baskol!$G$24="","",[2]Baskol!$G$24) | Y21: =IF([2]Baskol!$I$24="","",[2]Baskol!$I$24) | Z21: =IF([2]Baskol!$J$24="","",[2]Baskol!$J$24) | AA21: =IF([2]Baskol!$K$24="","",[2]Baskol!$K$24) | AB21: =IF([2]Baskol!$L$24="","",[2]Baskol!$L$24) | AC21: =IF([2]Baskol!$N$24="","",[2]Baskol!$N$24) | AD21: =IF([2]Baskol!$O$24="","",[2]Baskol!$O$24) | AE21: =IF([3]Entry!$C$24="","",[3]Entry!$C$24) | AF21: =IF([3]Entry!$D$24="","",[3]Entry!$D$24) | AG21: =IF([3]Entry!$E$24="","",[3]Entry!$E$24) | AH21: =IF([3]Entry!$G$24="","",[3]Entry!$G$24) | AI21: =IF([3]Entry!$K$24="","",[3]Entry!$K$24) | AJ21: =IF([3]Entry!$L$24="","",[3]Entry!$L$24) | AK21: =IF([3]Entry!$M$24="","",[3]Entry!$M$24) | AL21: =IF([3]Entry!$N$24="","",[3]Entry!$N$24) | AM21: =IF([3]Entry!$R$24="","",[3]Entry!$R$24)
